Workbook

Sheet ダッシュボード
A1: OLD ORDER 原宿店 売上管理ダッシュボード 2026年4月〜2027年3月
A2: 各月シートの入力欄を埋めると、ここに自動集計されます。単位：円
A4: 年間予算 | C4: 当期実績(YTD) | E4: 年間予算進捗 | G4: 経過月 達成率 | I4: 残り必要額
A5: =IF('設定'!$B$5=0,SUM(B8:B19),'設定'!$B$5) -> 225809762 | C5: =SUM(C8:C19) -> 63872132 | E5: =IFERROR(C5/A5,0) -> 0.28285815 | G5: =IFERROR(SUMIFS($C$8:$C$19,$C$8:$C$19,">0",$B$8:$B$19,">0")/SUMIFS($B$8:$B$19,$C$8:$C$19,">0",$B$8:$B$19,">0"),0) -> 0.5076882 | I5: =A5-C5 -> 161937630
A7: 月 | B7: 月間予算 | C7: 当月実績 | D7: 達成率 | E7: 予実差 | F7: 前年実績 | G7: 前年比 | H7: 購入人数 | I7: 来客数 | J7: 決定率 | K7: 客単価 | L7: 累計予算 | M7: 累計実績 | N7: 累計達成率
A8: 2026年4月 | B8: ='2026年04月'!$A$4 -> 9820292 | C8: ='2026年04月'!$C$4 -> 9864675 | D8: =IF(C8=0,"",IFERROR(C8/B8,"")) -> 1.0045195 | E8: =C8-B8 -> 44383 | F8: =IF('設定'!C8="","",'設定'!C8) | G8: =IF(OR(F8="",C8=0),"",IFERROR(C8/F8,"")) | H8: ='2026年04月'!$M$38 -> 425 | I8: ='2026年04月'!$O$38 -> 1489 | J8: =IFERROR(H8/I8,0) -> 0.28542646 | K8: =IFERROR(C8/H8,0) -> 23211 | L8: =IF(C8=0,"",SUM($B$8:B8)) -> 9820292 | M8: =IF(C8=0,"",SUM($C$8:C8)) -> 9864675 | N8: =IF(M8="","",IFERROR(M8/L8,0)) -> 1.0045195
A9: 2026年5月 | B9: ='2026年05月'!$A$4 -> 12329470 | C9: ='2026年05月'!$C$4 -> 12381052 | D9: =IF(C9=0,"",IFERROR(C9/B9,"")) -> 1.0041836 | E9: =C9-B9 -> 51582 | F9: =IF('設定'!C9="","",'設定'!C9) | G9: =IF(OR(F9="",C9=0),"",IFERROR(C9/F9,"")) | H9: ='2026年05月'!$M$39 -> 537 | I9: ='2026年05月'!$O$39 -> 1516 | J9: =IFERROR(H9/I9,0) -> 0.35422164 | K9: =IFERROR(C9/H9,0) -> 23055.963 | L9: =IF(C9=0,"",SUM($B$8:B9)) -> 22149762 | M9: =IF(C9=0,"",SUM($C$8:C9)) -> 22245727 | N9: =IF(M9="","",IFERROR(M9/L9,0)) -> 1.0043326
A10: 2026年6月 | B10: ='2026年06月'!$A$4 -> 17000000 | C10: ='2026年06月'!$C$4 -> 10446643 | D10: =IF(C10=0,"",IFERROR(C10/B10,"")) -> 0.61450841 | E10: =C10-B10 -> -6553357 | F10: =IF('設定'!C10="","",'設定'!C10) | G10: =IF(OR(F10="",C10=0),"",IFERROR(C10/F10,"")) | H10: ='2026年06月'!$M$38 -> 450 | I10: ='2026年06月'!$O$38 -> 1283 | J10: =IFERROR(H10/I10,0) -> 0.35074045 | K10: =IFERROR(C10/H10,0) -> 23214.762 | L10: =IF(C10=0,"",SUM($B$8:B10)) -> 39149762 | M10: =IF(C10=0,"",SUM($C$8:C10)) -> 32692370 | N10: =IF(M10="","",IFERROR(M10/L10,0)) -> 0.83505923
A11: 2026年7月 | B11: ='2026年07月'!$A$4 -> 20000000 | C11: ='2026年07月'!$C$4 -> 9690000 | D11: =IF(C11=0,"",IFERROR(C11/B11,"")) -> 0.4845 | E11: =C11-B11 -> -10310000 | F11: =IF('設定'!C11="","",'設定'!C11) | G11: =IF(OR(F11="",C11=0),"",IFERROR(C11/F11,"")) | H11: ='2026年07月'!$M$39 -> 426 | I11: ='2026年07月'!$O$39 -> 1165 | J11: =IFERROR(H11/I11,0) -> 0.36566524 | K11: =IFERROR(C11/H11,0) -> 22746.479 | L11: =IF(C11=0,"",SUM($B$8:B11)) -> 59149762 | M11: =IF(C11=0,"",SUM($C$8:C11)) -> 42382370 | N11: =IF(M11="","",IFERROR(M11/L11,0)) -> 0.71652647
A12: 2026年8月 | B12: ='2026年08月'!$A$4 -> 24660000 | C12: ='2026年08月'!$C$4 -> 8510877 | D12: =IF(C12=0,"",IFERROR(C12/B12,"")) -> 0.34512883 | E12: =C12-B12 -> -16149123 | F12: =IF('設定'!C12="","",'設定'!C12) | G12: =IF(OR(F12="",C12=0),"",IFERROR(C12/F12,"")) | H12: ='2026年08月'!$M$39 -> 386 | I12: ='2026年08月'!$O$39 -> 971 | J12: =IFERROR(H12/I12,0) -> 0.39752832 | K12: =IFERROR(C12/H12,0) -> 22048.904 | L12: =IF(C12=0,"",SUM($B$8:B12)) -> 83809762 | M12: =IF(C12=0,"",SUM($C$8:C12)) -> 50893247 | N12: =IF(M12="","",IFERROR(M12/L12,0)) -> 0.60724724
A13: 2026年9月 | B13: ='2026年09月'!$A$4 -> 23000000 | C13: ='2026年09月'!$C$4 -> 7801176 | D13: =IF(C13=0,"",IFERROR(C13/B13,"")) -> 0.33918157 | E13: =C13-B13 -> -15198824 | F13: =IF('設定'!C13="","",'設定'!C13) | G13: =IF(OR(F13="",C13=0),"",IFERROR(C13/F13,"")) | H13: ='2026年09月'!$M$38 -> 333 | I13: ='2026年09月'!$O$38 -> 851 | J13: =IFERROR(H13/I13,0) -> 0.39130435 | K13: =IFERROR(C13/H13,0) -> 23426.955 | L13: =IF(C13=0,"",SUM($B$8:B13)) -> 106809762 | M13: =IF(C13=0,"",SUM($C$8:C13)) -> 58694423 | N13: =IF(M13="","",IFERROR(M13/L13,0)) -> 0.54952302
A14: 2026年10月 | B14: ='2026年10月'!$A$4 -> 19000000 | C14: ='2026年10月'!$C$4 -> 5177709 | D14: =IF(C14=0,"",IFERROR(C14/B14,"")) -> 0.272511 | E14: =C14-B14 -> -13822291 | F14: =IF('設定'!C14="","",'設定'!C14) | G14: =IF(OR(F14="",C14=0),"",IFERROR(C14/F14,"")) | H14: ='2026年10月'!$M$39 -> 222 | I14: ='2026年10月'!$O$39 -> 600 | J14: =IFERROR(H14/I14,0) -> 0.37 | K14: =IFERROR(C14/H14,0) -> 23323.014 | L14: =IF(C14=0,"",SUM($B$8:B14)) -> 125809762 | M14: =IF(C14=0,"",SUM($C$8:C14)) -> 63872132 | N14: =IF(M14="","",IFERROR(M14/L14,0)) -> 0.5076882
A15: 2026年11月 | B15: ='2026年11月'!$A$4 -> 19000000 | C15: ='2026年11月'!$C$4 -> 0 | D15: =IF(C15=0,"",IFERROR(C15/B15,"")) | E15: =C15-B15 -> -19000000 | F15: =IF('設定'!C15="","",'設定'!C15) | G15: =IF(OR(F15="",C15=0),"",IFERROR(C15/F15,"")) | H15: ='2026年11月'!$M$38 -> 0 | I15: ='2026年11月'!$O$38 -> 0 | J15: =IFERROR(H15/I15,0) -> 0 | K15: =IFERROR(C15/H15,0) -> 0 | L15: =IF(C15=0,"",SUM($B$8:B15)) | M15: =IF(C15=0,"",SUM($C$8:C15)) | N15: =IF(M15="","",IFERROR(M15/L15,0))
A16: 2026年12月 | B16: ='2026年12月'!$A$4 -> 21000000 | C16: ='2026年12月'!$C$4 -> 0 | D16: =IF(C16=0,"",IFERROR(C16/B16,"")) | E16: =C16-B16 -> -21000000 | F16: =IF('設定'!C16="","",'設定'!C16) -> 4139160 | G16: =IF(OR(F16="",C16=0),"",IFERROR(C16/F16,"")) | H16: ='2026年12月'!$M$39 -> 0 | I16: ='2026年12月'!$O$39 -> 0 | J16: =IFERROR(H16/I16,0) -> 0 | K16: =IFERROR(C16/H16,0) -> 0 | L16: =IF(C16=0,"",SUM($B$8:B16)) | M16: =IF(C16=0,"",SUM($C$8:C16)) | N16: =IF(M16="","",IFERROR(M16/L16,0))
A17: 2027年1月 | B17: ='2027年01月'!$A$4 -> 25000000 | C17: ='2027年01月'!$C$4 -> 0 | D17: =IF(C17=0,"",IFERROR(C17/B17,"")) | E17: =C17-B17 -> -25000000 | F17: =IF('設定'!C17="","",'設定'!C17) -> 9650171 | G17: =IF(OR(F17="",C17=0),"",IFERROR(C17/F17,"")) | H17: ='2027年01月'!$M$39 -> 0 | I17: ='2027年01月'!$O$39 -> 0 | J17: =IFERROR(H17/I17,0) -> 0 | K17: =IFERROR(C17/H17,0) -> 0 | L17: =IF(C17=0,"",SUM($B$8:B17)) | M17: =IF(C17=0,"",SUM($C$8:C17)) | N17: =IF(M17="","",IFERROR(M17/L17,0))
A18: 2027年2月 | B18: ='2027年02月'!$A$4 -> 19000000 | C18: ='2027年02月'!$C$4 -> 0 | D18: =IF(C18=0,"",IFERROR(C18/B18,"")) | E18: =C18-B18 -> -19000000 | F18: =IF('設定'!C18="","",'設定'!C18) -> 7476182 | G18: =IF(OR(F18="",C18=0),"",IFERROR(C18/F18,"")) | H18: ='2027年02月'!$M$36 -> 0 | I18: ='2027年02月'!$O$36 -> 0 | J18: =IFERROR(H18/I18,0) -> 0 | K18: =IFERROR(C18/H18,0) -> 0 | L18: =IF(C18=0,"",SUM($B$8:B18)) | M18: =IF(C18=0,"",SUM($C$8:C18)) | N18: =IF(M18="","",IFERROR(M18/L18,0))
A19: 2027年3月 | B19: ='2027年03月'!$A$4 -> 16000000 | C19: ='2027年03月'!$C$4 -> 0 | D19: =IF(C19=0,"",IFERROR(C19/B19,"")) | E19: =C19-B19 -> -16000000 | F19: =IF('設定'!C19="","",'設定'!C19) -> 10101265 | G19: =IF(OR(F19="",C19=0),"",IFERROR(C19/F19,"")) | H19: ='2027年03月'!$M$39 -> 0 | I19: ='2027年03月'!$O$39 -> 0 | J19: =IFERROR(H19/I19,0) -> 0 | K19: =IFERROR(C19/H19,0) -> 0 | L19: =IF(C19=0,"",SUM($B$8:B19)) | M19: =IF(C19=0,"",SUM($C$8:C19)) | N19: =IF(M19="","",IFERROR(M19/L19,0))
A20: 合計 | B20: =SUM(B8:B19) -> 225809762 | C20: =SUM(C8:C19) -> 63872132 | D20: =IFERROR(C20/B20,0) -> 0.28285815 | E20: =SUM(E8:E19) -> -161937630 | F20: =SUM(F8:F19) -> 31366778 | G20: =IFERROR(C20/F20,0) -> 2.0362988 | H20: =SUM(H8:H19) -> 2779 | I20: =SUM(I8:I19) -> 7875 | J20: =IFERROR(H20/I20,0) -> 0.35288889 | K20: =IFERROR(C20/H20,0) -> 22983.855
A22: ※前年実績は「設定」シートの青字セルに入力。元データが無い月は空欄です。
A23: ※「経過月 達成率」は予算と実績の両方が入っている月だけで計算します。
A24: 【グラフ】

Sheet 2026年04月
A1: 2026年4月 原宿店 日別売上管理
A2: 青字＋薄黄色のセルが入力欄。白セルは数式なので触らないでください。単位：円
A3: 月間予算 | C3: 当月実績 | E3: 達成率 | G3: 営業日数(/30日) | I3: 残り必要額 | K3: 残り必要日商
A4: =IF('設定'!$B$8="",SUM(C8:C37),'設定'!$B$8) -> 9820292 | C4: =SUM(G8:G37) -> 9864675 | E4: =IFERROR(C4/A4,0) -> 1.0045195 | G4: =COUNTIF(G8:G37,">0") -> 30 | I4: =A4-C4 -> -44383 | K4: =IF((30-G4)>0,(A4-C4)/(30-G4),0) -> 0
A5: 日次予算合計 | C5: 着地見込 | E5: 決定率 | G5: 客単価 | I5: セット率 | K5: 試着率
A6: =SUM(C8:C37) -> 18500000 | C6: =IFERROR(C4/G4*30,0) -> 9864675 | E6: =IFERROR(M38/O38,0) -> 0.28542646 | G6: =IFERROR(G38/M38,0) -> 23211 | I6: =IFERROR(N38/M38,0) -> 1.0988235 | K6: =IFERROR(P38/O38,0) -> 0.48153123
A7: 日付 | B7: 曜 | C7: 日次予算 | D7: 累計予算 | E7: 現金 | F7: クレジット | G7: 実績合計 | H7: 累計実績 | I7: 日次達成 | J7: 累計達成 | K7: 累計予実差 | L7: ペース | M7: 購入人数 | N7: 販売点数 | O7: 来客数 | P7: 試着組数 | Q7: 試着個数 | R7: 決定率 | S7: 客単価 | T7: セット率 | U7: 試着率 | V7: クロス クーポン | W7: インスタ フォロワー | X7: 経費 | Y7: メモ | AA7: 曜日 | AB7: 平均日商 | AC7: 日数 | AD7: 決定率 | AE7: 客単価
A8: 46113 | B8: =MID("日月火水木金土",WEEKDAY(A8),1) -> 水 | C8: 500000 | D8: =SUM($C$8:C8) -> 500000 | E8: 63338 | F8: 43500 | G8: =IF(COUNT(E8:F8)=0,"",SUM(E8:F8)) -> 106838 | H8: =IF(G8="","",SUM($G$8:G8)) -> 106838 | I8: =IF(G8="","",IFERROR(G8/C8,"")) -> 0.213676 | J8: =IF(H8="","",IFERROR(H8/D8,"")) -> 0.213676 | K8: =IF(H8="","",IF(D8=0,"",H8-D8)) -> -393162 | L8: =IF(G8="","—",IF(D8=0,"予算未入力",IF(H8>=D8,"◎ ペース内","▲ 遅れ"))) -> ▲ 遅れ | M8: 5 | N8: 6 | O8: 31 | P8: 18 | R8: =IFERROR(M8/O8,"") -> 0.16129032 | S8: =IFERROR(G8/M8,"") -> 21367.6 | T8: =IFERROR(N8/M8,"") -> 1.2 | U8: =IFERROR(P8/O8,"") -> 0.58064516 | W8: 42670 | X8: 0 | AA8: 月 | AB8: =IFERROR(AVERAGEIFS($G$8:$G$37,$B$8:$B$37,AA8,$G$8:$G$37,">0"),0) -> 225772.5 | AC8: =COUNTIFS($B$8:$B$37,AA8,$G$8:$G$37,">0") -> 4 | AD8: =IFERROR(SUMIF($B$8:$B$37,AA8,$M$8:$M$37)/SUMIF($B$8:$B$37,AA8,$O$8:$O$37),0) -> 0.24074074 | AE8: =IFERROR(SUMIF($B$8:$B$37,AA8,$G$8:$G$37)/SUMIF($B$8:$B$37,AA8,$M$8:$M$37),0) -> 23156.154
A9: 46114 | B9: =MID("日月火水木金土",WEEKDAY(A9),1) -> 木 | C9: 500000 | D9: =SUM($C$8:C9) -> 1000000 | E9: 45700 | F9: 187810 | G9: =IF(COUNT(E9:F9)=0,"",SUM(E9:F9)) -> 233510 | H9: =IF(G9="","",SUM($G$8:G9)) -> 340348 | I9: =IF(G9="","",IFERROR(G9/C9,"")) -> 0.46702 | J9: =IF(H9="","",IFERROR(H9/D9,"")) -> 0.340348 | K9: =IF(H9="","",IF(D9=0,"",H9-D9)) -> -659652 | L9: =IF(G9="","—",IF(D9=0,"予算未入力",IF(H9>=D9,"◎ ペース内","▲ 遅れ"))) -> ▲ 遅れ | M9: 11 | N9: 13 | O9: 45 | P9: 18 | R9: =IFERROR(M9/O9,"") -> 0.24444444 | S9: =IFERROR(G9/M9,"") -> 21228.182 | T9: =IFERROR(N9/M9,"") -> 1.1818182 | U9: =IFERROR(P9/O9,"") -> 0.4 | W9: 42700 | X9: 0 | AA9: 火 | AB9: =IFERROR(AVERAGEIFS($G$8:$G$37,$B$8:$B$37,AA9,$G$8:$G$37,">0"),0) -> 284647.5 | AC9: =COUNTIFS($B$8:$B$37,AA9,$G$8:$G$37,">0") -> 4 | AD9: =IFERROR(SUMIF($B$8:$B$37,AA9,$M$8:$M$37)/SUMIF($B$8:$B$37,AA9,$O$8:$O$37),0) -> 0.26136364 | AE9: =IFERROR(SUMIF($B$8:$B$37,AA9,$G$8:$G$37)/SUMIF($B$8:$B$37,AA9,$M$8:$M$37),0) -> 24751.957
A10: 46115 | B10: =MID("日月火水木金土",WEEKDAY(A10),1) -> 金 | C10: 500000 | D10: =SUM($C$8:C10) -> 1500000 | E10: 115210 | F10: 385848 | G10: =IF(COUNT(E10:F10)=0,"",SUM(E10:F10)) -> 501058 | H10: =IF(G10="","",SUM($G$8:G10)) -> 841406 | I10: =IF(G10="","",IFERROR(G10/C10,"")) -> 1.002116 | J10: =IF(H10="","",IFERROR(H10/D10,"")) -> 0.56093733 | K10: =IF(H10="","",IF(D10=0,"",H10-D10)) -> -658594 | L10: =IF(G10="","—",IF(D10=0,"予算未入力",IF(H10>=D10,"◎ ペース内","▲ 遅れ"))) -> ▲ 遅れ | M10: 25 | N10: 25 | O10: 49 | P10: 25 | R10: =IFERROR(M10/O10,"") -> 0.51020408 | S10: =IFERROR(G10/M10,"") -> 20042.32 | T10: =IFERROR(N10/M10,"") -> 1 | U10: =IFERROR(P10/O10,"") -> 0.51020408 | W10: 42726 | X10: 0 | AA10: 水 | AB10: =IFERROR(AVERAGEIFS($G$8:$G$37,$B$8:$B$37,AA10,$G$8:$G$37,">0"),0) -> 352604.6 | AC10: =COUNTIFS($B$8:$B$37,AA10,$G$8:$G$37,">0") -> 5 | AD10: =IFERROR(SUMIF($B$8:$B$37,AA10,$M$8:$M$37)/SUMIF($B$8:$B$37,AA10,$O$8:$O$37),0) -> 0.30864198 | AE10: =IFERROR(SUMIF($B$8:$B$37,AA10,$G$8:$G$37)/SUMIF($B$8:$B$37,AA10,$M$8:$M$37),0) -> 23506.973
A11: 46116 | B11: =MID("日月火水木金土",WEEKDAY(A11),1) -> 土 | C11: 800000 | D11: =SUM($C$8:C11) -> 2300000 | E11: 143589 | F11: 252249 | G11: =IF(COUNT(E11:F11)=0,"",SUM(E11:F11)) -> 395838 | H11: =IF(G11="","",SUM($G$8:G11)) -> 1237244 | I11: =IF(G11="","",IFERROR(G11/C11,"")) -> 0.4947975 | J11: =IF(H11="","",IFERROR(H11/D11,"")) -> 0.53793217 | K11: =IF(H11="","",IF(D11=0,"",H11-D11)) -> -1062756 | L11: =IF(G11="","—",IF(D11=0,"予算未入力",IF(H11>=D11,"◎ ペース内","▲ 遅れ"))) -> ▲ 遅れ | M11: 18 | N11: 18 | O11: 65 | P11: 25 | R11: =IFERROR(M11/O11,"") -> 0.27692308 | S11: =IFERROR(G11/M11,"") -> 21991 | T11: =IFERROR(N11/M11,"") -> 1 | U11: =IFERROR(P11/O11,"") -> 0.38461538 | X11: 0 | AA11: 木 | AB11: =IFERROR(AVERAGEIFS($G$8:$G$37,$B$8:$B$37,AA11,$G$8:$G$37,">0"),0) -> 218086 | AC11: =COUNTIFS($B$8:$B$37,AA11,$G$8:$G$37,">0") -> 5 | AD11: =IFERROR(SUMIF($B$8:$B$37,AA11,$M$8:$M$37)/SUMIF($B$8:$B$37,AA11,$O$8:$O$37),0) -> 0.24242424 | AE11: =IFERROR(SUMIF($B$8:$B$37,AA11,$G$8:$G$37)/SUMIF($B$8:$B$37,AA11,$M$8:$M$37),0) -> 22717.292
A12: 46117 | B12: =MID("日月火水木金土",WEEKDAY(A12),1) -> 日 | C12: 800000 | D12: =SUM($C$8:C12) -> 3100000 | E12: 29970 | F12: 389469 | G12: =IF(COUNT(E12:F12)=0,"",SUM(E12:F12)) -> 419439 | H12: =IF(G12="","",SUM($G$8:G12)) -> 1656683 | I12: =IF(G12="","",IFERROR(G12/C12,"")) -> 0.52429875 | J12: =IF(H12="","",IFERROR(H12/D12,"")) -> 0.53441387 | K12: =IF(H12="","",IF(D12=0,"",H12-D12)) -> -1443317 | L12: =IF(G12="","—",IF(D12=0,"予算未入力",IF(H12>=D12,"◎ ペース内","▲ 遅れ"))) -> ▲ 遅れ | M12: 20 | N12: 21 | O12: 67 | P12: 37 | R12: =IFERROR(M12/O12,"") -> 0.29850746 | S12: =IFERROR(G12/M12,"") -> 20971.95 | T12: =IFERROR(N12/M12,"") -> 1.05 | U12: =IFERROR(P12/O12,"") -> 0.55223881 | X12: 0 | AA12: 金 | AB12: =IFERROR(AVERAGEIFS($G$8:$G$37,$B$8:$B$37,AA12,$G$8:$G$37,">0"),0) -> 376413.75 | AC12: =COUNTIFS($B$8:$B$37,AA12,$G$8:$G$37,">0") -> 4 | AD12: =IFERROR(SUMIF($B$8:$B$37,AA12,$M$8:$M$37)/SUMIF($B$8:$B$37,AA12,$O$8:$O$37),0) -> 0.32323232 | AE12: =IFERROR(SUMIF($B$8:$B$37,AA12,$G$8:$G$37)/SUMIF($B$8:$B$37,AA12,$M$8:$M$37),0) -> 23525.859
A13: 46118 | B13: =MID("日月火水木金土",WEEKDAY(A13),1) -> 月 | C13: 500000 | D13: =SUM($C$8:C13) -> 3600000 | E13: 72430 | F13: 154830 | G13: =IF(COUNT(E13:F13)=0,"",SUM(E13:F13)) -> 227260 | H13: =IF(G13="","",SUM($G$8:G13)) -> 1883943 | I13: =IF(G13="","",IFERROR(G13/C13,"")) -> 0.45452 | J13: =IF(H13="","",IFERROR(H13/D13,"")) -> 0.5233175 | K13: =IF(H13="","",IF(D13=0,"",H13-D13)) -> -1716057 | L13: =IF(G13="","—",IF(D13=0,"予算未入力",IF(H13>=D13,"◎ ペース内","▲ 遅れ"))) -> ▲ 遅れ | M13: 10 | N13: 10 | O13: 42 | P13: 13 | R13: =IFERROR(M13/O13,"") -> 0.23809524 | S13: =IFERROR(G13/M13,"") -> 22726 | T13: =IFERROR(N13/M13,"") -> 1 | U13: =IFERROR(P13/O13,"") -> 0.30952381 | X13: 0 | AA13: 土 | AB13: =IFERROR(AVERAGEIFS($G$8:$G$37,$B$8:$B$37,AA13,$G$8:$G$37,">0"),0) -> 387582 | AC13: =COUNTIFS($B$8:$B$37,AA13,$G$8:$G$37,">0") -> 4 | AD13: =IFERROR(SUMIF($B$8:$B$37,AA13,$M$8:$M$37)/SUMIF($B$8:$B$37,AA13,$O$8:$O$37),0) -> 0.2605364 | AE13: =IFERROR(SUMIF($B$8:$B$37,AA13,$G$8:$G$37)/SUMIF($B$8:$B$37,AA13,$M$8:$M$37),0) -> 22798.941
A14: 46119 | B14: =MID("日月火水木金土",WEEKDAY(A14),1) -> 火 | C14: 500000 | D14: =SUM($C$8:C14) -> 4100000 | E14: 63410 | F14: 241630 | G14: =IF(COUNT(E14:F14)=0,"",SUM(E14:F14)) -> 305040 | H14: =IF(G14="","",SUM($G$8:G14)) -> 2188983 | I14: =IF(G14="","",IFERROR(G14/C14,"")) -> 0.61008 | J14: =IF(H14="","",IFERROR(H14/D14,"")) -> 0.53389829 | K14: =IF(H14="","",IF(D14=0,"",H14-D14)) -> -1911017 | L14: =IF(G14="","—",IF(D14=0,"予算未入力",IF(H14>=D14,"◎ ペース内","▲ 遅れ"))) -> ▲ 遅れ | M14: 14 | N14: 14 | O14: 63 | P14: 33 | R14: =IFERROR(M14/O14,"") -> 0.22222222 | S14: =IFERROR(G14/M14,"") -> 21788.571 | T14: =IFERROR(N14/M14,"") -> 1 | U14: =IFERROR(P14/O14,"") -> 0.52380952 | W14: 42790 | X14: 0 | AA14: 日 | AB14: =IFERROR(AVERAGEIFS($G$8:$G$37,$B$8:$B$37,AA14,$G$8:$G$37,">0"),0) -> 478389.75 | AC14: =COUNTIFS($B$8:$B$37,AA14,$G$8:$G$37,">0") -> 4 | AD14: =IFERROR(SUMIF($B$8:$B$37,AA14,$M$8:$M$37)/SUMIF($B$8:$B$37,AA14,$O$8:$O$37),0) -> 0.33864542 | AE14: =IFERROR(SUMIF($B$8:$B$37,AA14,$G$8:$G$37)/SUMIF($B$8:$B$37,AA14,$M$8:$M$37),0) -> 22512.459
A15: 46120 | B15: =MID("日月火水木金土",WEEKDAY(A15),1) -> 水 | C15: 500000 | D15: =SUM($C$8:C15) -> 4600000 | E15: 110150 | F15: 194900 | G15: =IF(COUNT(E15:F15)=0,"",SUM(E15:F15)) -> 305050 | H15: =IF(G15="","",SUM($G$8:G15)) -> 2494033 | I15: =IF(G15="","",IFERROR(G15/C15,"")) -> 0.6101 | J15: =IF(H15="","",IFERROR(H15/D15,"")) -> 0.54218109 | K15: =IF(H15="","",IF(D15=0,"",H15-D15)) -> -2105967 | L15: =IF(G15="","—",IF(D15=0,"予算未入力",IF(H15>=D15,"◎ ペース内","▲ 遅れ"))) -> ▲ 遅れ | M15: 14 | N15: 16 | O15: 40 | P15: 24 | R15: =IFERROR(M15/O15,"") -> 0.35 | S15: =IFERROR(G15/M15,"") -> 21789.286 | T15: =IFERROR(N15/M15,"") -> 1.1428571 | U15: =IFERROR(P15/O15,"") -> 0.6 | X15: 0
A16: 46121 | B16: =MID("日月火水木金土",WEEKDAY(A16),1) -> 木 | C16: 500000 | D16: =SUM($C$8:C16) -> 5100000 | E16: 43220 | F16: 122250 | G16: =IF(COUNT(E16:F16)=0,"",SUM(E16:F16)) -> 165470 | H16: =IF(G16="","",SUM($G$8:G16)) -> 2659503 | I16: =IF(G16="","",IFERROR(G16/C16,"")) -> 0.33094 | J16: =IF(H16="","",IFERROR(H16/D16,"")) -> 0.52147118 | K16: =IF(H16="","",IF(D16=0,"",H16-D16)) -> -2440497 | L16: =IF(G16="","—",IF(D16=0,"予算未入力",IF(H16>=D16,"◎ ペース内","▲ 遅れ"))) -> ▲ 遅れ | M16: 7 | N16: 7 | O16: 33 | P16: 16 | R16: =IFERROR(M16/O16,"") -> 0.21212121 | S16: =IFERROR(G16/M16,"") -> 23638.571 | T16: =IFERROR(N16/M16,"") -> 1 | U16: =IFERROR(P16/O16,"") -> 0.48484848 | W16: 42835 | X16: 0 | AA16: ※実績入力後に曜日別の傾向が出ます
A17: 46122 | B17: =MID("日月火水木金土",WEEKDAY(A17),1) -> 金 | C17: 500000 | D17: =SUM($C$8:C17) -> 5600000 | E17: 48620 | F17: 220380 | G17: =IF(COUNT(E17:F17)=0,"",SUM(E17:F17)) -> 269000 | H17: =IF(G17="","",SUM($G$8:G17)) -> 2928503 | I17: =IF(G17="","",IFERROR(G17/C17,"")) -> 0.538 | J17: =IF(H17="","",IFERROR(H17/D17,"")) -> 0.52294696 | K17: =IF(H17="","",IF(D17=0,"",H17-D17)) -> -2671497 | L17: =IF(G17="","—",IF(D17=0,"予算未入力",IF(H17>=D17,"◎ ペース内","▲ 遅れ"))) -> ▲ 遅れ | M17: 10 | N17: 10 | O17: 48 | P17: 19 | R17: =IFERROR(M17/O17,"") -> 0.20833333 | S17: =IFERROR(G17/M17,"") -> 26900 | T17: =IFERROR(N17/M17,"") -> 1 | U17: =IFERROR(P17/O17,"") -> 0.39583333 | W17: 42878 | X17: 0
A18: 46123 | B18: =MID("日月火水木金土",WEEKDAY(A18),1) -> 土 | C18: 800000 | D18: =SUM($C$8:C18) -> 6400000 | E18: 93430 | F18: 160680 | G18: =IF(COUNT(E18:F18)=0,"",SUM(E18:F18)) -> 254110 | H18: =IF(G18="","",SUM($G$8:G18)) -> 3182613 | I18: =IF(G18="","",IFERROR(G18/C18,"")) -> 0.3176375 | J18: =IF(H18="","",IFERROR(H18/D18,"")) -> 0.49728328 | K18: =IF(H18="","",IF(D18=0,"",H18-D18)) -> -3217387 | L18: =IF(G18="","—",IF(D18=0,"予算未入力",IF(H18>=D18,"◎ ペース内","▲ 遅れ"))) -> ▲ 遅れ | M18: 11 | N18: 12 | O18: 60 | P18: 25 | R18: =IFERROR(M18/O18,"") -> 0.18333333 | S18: =IFERROR(G18/M18,"") -> 23100.909 | T18: =IFERROR(N18/M18,"") -> 1.0909091 | U18: =IFERROR(P18/O18,"") -> 0.41666667 | X18: 0 | AA18: ■ 週次サマリー（火曜〜翌月曜） | AH18: 第1火曜 | AI18: =$A$8+MOD(2-WEEKDAY($A$8,2)+7,7) -> 46119
A19: 46124 | B19: =MID("日月火水木金土",WEEKDAY(A19),1) -> 日 | C19: 800000 | D19: =SUM($C$8:C19) -> 7200000 | E19: 44043 | F19: 337467 | G19: =IF(COUNT(E19:F19)=0,"",SUM(E19:F19)) -> 381510 | H19: =IF(G19="","",SUM($G$8:G19)) -> 3564123 | I19: =IF(G19="","",IFERROR(G19/C19,"")) -> 0.4768875 | J19: =IF(H19="","",IFERROR(H19/D19,"")) -> 0.49501708 | K19: =IF(H19="","",IF(D19=0,"",H19-D19)) -> -3635877 | L19: =IF(G19="","—",IF(D19=0,"予算未入力",IF(H19>=D19,"◎ ペース内","▲ 遅れ"))) -> ▲ 遅れ | M19: 17 | N19: 17 | O19: 56 | P19: 34 | R19: =IFERROR(M19/O19,"") -> 0.30357143 | S19: =IFERROR(G19/M19,"") -> 22441.765 | T19: =IFERROR(N19/M19,"") -> 1 | U19: =IFERROR(P19/O19,"") -> 0.60714286 | W19: 42923 | X19: 0 | AA19: 週 | AB19: 期間 | AC19: 売上 | AD19: 決定率 | AE19: 客単価 | AF19: セット率 | AG19: 試着率
A20: 46125 | B20: =MID("日月火水木金土",WEEKDAY(A20),1) -> 月 | C20: 500000 | D20: =SUM($C$8:C20) -> 7700000 | E20: 43720 | F20: 138960 | G20: =IF(COUNT(E20:F20)=0,"",SUM(E20:F20)) -> 182680 | H20: =IF(G20="","",SUM($G$8:G20)) -> 3746803 | I20: =IF(G20="","",IFERROR(G20/C20,"")) -> 0.36536 | J20: =IF(H20="","",IFERROR(H20/D20,"")) -> 0.48659779 | K20: =IF(H20="","",IF(D20=0,"",H20-D20)) -> -3953197 | L20: =IF(G20="","—",IF(D20=0,"予算未入力",IF(H20>=D20,"◎ ペース内","▲ 遅れ"))) -> ▲ 遅れ | M20: 8 | N20: 8 | O20: 44 | P20: 15 | R20: =IFERROR(M20/O20,"") -> 0.18181818 | S20: =IFERROR(G20/M20,"") -> 22835 | T20: =IFERROR(N20/M20,"") -> 1 | U20: =IFERROR(P20/O20,"") -> 0.34090909 | X20: 0 | Y20: ※要確認：旧シートの売上合計と内訳が+4,900円ズレ。合計182,680円に合わせクレジットを134,060→138,960に調整 | AA20: 1 | AB20: =IF($AI$18+7*(1-1)>$A$37,"",TEXT($AI$18+7*(1-1),"m/d")&"-"&TEXT($AI$18+7*(1-1)+6,"m/d")) -> 4/7-4/13 | AC20: =IF($AB20="","",(SUMIFS($G$8:$G$37,$A$8:$A$37,">="&$AI$18+7*(1-1),$A$8:$A$37,"<="&$AI$18+7*(1-1)+6)+SUMIFS('2026年05月'!$G$8:$G$38,'2026年05月'!$A$8:$A$38,">="&$AI$18+7*(1-1),'2026年05月'!$A$8:$A$38,"<="&$AI$18+7*(1-1)+6))) -> 1862860 | AD20: =IF($AB20="","",IFERROR((SUMIFS($M$8:$M$37,$A$8:$A$37,">="&$AI$18+7*(1-1),$A$8:$A$37,"<="&$AI$18+7*(1-1)+6)+SUMIFS('2026年05月'!$M$8:$M$38,'2026年05月'!$A$8:$A$38,">="&$AI$18+7*(1-1),'2026年05月'!$A$8:$A$38,"<="&$AI$18+7*(1-1)+6))/(SUMIFS($O$8:$O$37,$A$8:$A$37,">="&$AI$18+7*(1-1),$A$8:$A$37,"<="&$AI$18+7*(1-1)+6)+SUMIFS('2026年05月'!$O$8:$O$38,'2026年05月'!$A$8:$A$38,">="&$AI$18+7*(1-1),'2026年05月'!$A$8:$A$38,"<="&$AI$18+7*(1-1)+6)),"")) -> 0.23546512 | AE20: =IF($AB20="","",IFERROR((SUMIFS($G$8:$G$37,$A$8:$A$37,">="&$AI$18+7*(1-1),$A$8:$A$37,"<="&$AI$18+7*(1-1)+6)+SUMIFS('2026年05月'!$G$8:$G$38,'2026年05月'!$A$8:$A$38,">="&$AI$18+7*(1-1),'2026年05月'!$A$8:$A$38,"<="&$AI$18+7*(1-1)+6))/(SUMIFS($M$8:$M$37,$A$8:$A$37,">="&$AI$18+7*(1-1),$A$8:$A$37,"<="&$AI$18+7*(1-1)+6)+SUMIFS('2026年05月'!$M$8:$M$38,'2026年05月'!$A$8:$A$38,">="&$AI$18+7*(1-1),'2026年05月'!$A$8:$A$38,"<="&$AI$18+7*(1-1)+6)),"")) -> 22998.272 | AF20: =IF($AB20="","",IFERROR((SUMIFS($N$8:$N$37,$A$8:$A$37,">="&$AI$18+7*(1-1),$A$8:$A$37,"<="&$AI$18+7*(1-1)+6)+SUMIFS('2026年05月'!$N$8:$N$38,'2026年05月'!$A$8:$A$38,">="&$AI$18+7*(1-1),'2026年05月'!$A$8:$A$38,"<="&$AI$18+7*(1-1)+6))/(SUMIFS($M$8:$M$37,$A$8:$A$37,">="&$AI$18+7*(1-1),$A$8:$A$37,"<="&$AI$18+7*(1-1)+6)+SUMIFS('2026年05月'!$M$8:$M$38,'2026年05月'!$A$8:$A$38,">="&$AI$18+7*(1-1),'2026年05月'!$A$8:$A$38,"<="&$AI$18+7*(1-1)+6)),"")) -> 1.037037 | AG20: =IF($AB20="","",IFERROR((SUMIFS($P$8:$P$37,$A$8:$A$37,">="&$AI$18+7*(1-1),$A$8:$A$37,"<="&$AI$18+7*(1-1)+6)+SUMIFS('2026年05月'!$P$8:$P$38,'2026年05月'!$A$8:$A$38,">="&$AI$18+7*(1-1),'2026年05月'!$A$8:$A$38,"<="&$AI$18+7*(1-1)+6))/(SUMIFS($O$8:$O$37,$A$8:$A$37,">="&$AI$18+7*(1-1),$A$8:$A$37,"<="&$AI$18+7*(1-1)+6)+SUMIFS('2026年05月'!$O$8:$O$38,'2026年05月'!$A$8:$A$38,">="&$AI$18+7*(1-1),'2026年05月'!$A$8:$A$38,"<="&$AI$18+7*(1-1)+6)),"")) -> 0.48255814
A21: 46126 | B21: =MID("日月火水木金土",WEEKDAY(A21),1) -> 火 | C21: 500000 | D21: =SUM($C$8:C21) -> 8200000 | E21: 43720 | F21: 350990 | G21: =IF(COUNT(E21:F21)=0,"",SUM(E21:F21)) -> 394710 | H21: =IF(G21="","",SUM($G$8:G21)) -> 4141513 | I21: =IF(G21="","",IFERROR(G21/C21,"")) -> 0.78942 | J21: =IF(H21="","",IFERROR(H21/D21,"")) -> 0.50506256 | K21: =IF(H21="","",IF(D21=0,"",H21-D21)) -> -4058487 | L21: =IF(G21="","—",IF(D21=0,"予算未入力",IF(H21>=D21,"◎ ペース内","▲ 遅れ"))) -> ▲ 遅れ | M21: 13 | N21: 18 | O21: 36 | P21: 12 | R21: =IFERROR(M21/O21,"") -> 0.36111111 | S21: =IFERROR(G21/M21,"") -> 30362.308 | T21: =IFERROR(N21/M21,"") -> 1.3846154 | U21: =IFERROR(P21/O21,"") -> 0.33333333 | W21: 43062 | X21: 0 | Y21: ※要確認：旧シートの売上合計と内訳が+44,110円ズレ。合計394,710円に合わせクレジットを306,880→350,990に調整 | AA21: 2 | AB21: =IF($AI$18+7*(2-1)>$A$37,"",TEXT($AI$18+7*(2-1),"m/d")&"-"&TEXT($AI$18+7*(2-1)+6,"m/d")) -> 4/14-4/20 | AC21: =IF($AB21="","",(SUMIFS($G$8:$G$37,$A$8:$A$37,">="&$AI$18+7*(2-1),$A$8:$A$37,"<="&$AI$18+7*(2-1)+6)+SUMIFS('2026年05月'!$G$8:$G$38,'2026年05月'!$A$8:$A$38,">="&$AI$18+7*(2-1),'2026年05月'!$A$8:$A$38,"<="&$AI$18+7*(2-1)+6))) -> 2595495 | AD21: =IF($AB21="","",IFERROR((SUMIFS($M$8:$M$37,$A$8:$A$37,">="&$AI$18+7*(2-1),$A$8:$A$37,"<="&$AI$18+7*(2-1)+6)+SUMIFS('2026年05月'!$M$8:$M$38,'2026年05月'!$A$8:$A$38,">="&$AI$18+7*(2-1),'2026年05月'!$A$8:$A$38,"<="&$AI$18+7*(2-1)+6))/(SUMIFS($O$8:$O$37,$A$8:$A$37,">="&$AI$18+7*(2-1),$A$8:$A$37,"<="&$AI$18+7*(2-1)+6)+SUMIFS('2026年05月'!$O$8:$O$38,'2026年05月'!$A$8:$A$38,">="&$AI$18+7*(2-1),'2026年05月'!$A$8:$A$38,"<="&$AI$18+7*(2-1)+6)),"")) -> 0.31656805 | AE21: =IF($AB21="","",IFERROR((SUMIFS($G$8:$G$37,$A$8:$A$37,">="&$AI$18+7*(2-1),$A$8:$A$37,"<="&$AI$18+7*(2-1)+6)+SUMIFS('2026年05月'!$G$8:$G$38,'2026年05月'!$A$8:$A$38,">="&$AI$18+7*(2-1),'2026年05月'!$A$8:$A$38,"<="&$AI$18+7*(2-1)+6))/(SUMIFS($M$8:$M$37,$A$8:$A$37,">="&$AI$18+7*(2-1),$A$8:$A$37,"<="&$AI$18+7*(2-1)+6)+SUMIFS('2026年05月'!$M$8:$M$38,'2026年05月'!$A$8:$A$38,">="&$AI$18+7*(2-1),'2026年05月'!$A$8:$A$38,"<="&$AI$18+7*(2-1)+6)),"")) -> 24256.963 | AF21: =IF($AB21="","",IFERROR((SUMIFS($N$8:$N$37,$A$8:$A$37,">="&$AI$18+7*(2-1),$A$8:$A$37,"<="&$AI$18+7*(2-1)+6)+SUMIFS('2026年05月'!$N$8:$N$38,'2026年05月'!$A$8:$A$38,">="&$AI$18+7*(2-1),'2026年05月'!$A$8:$A$38,"<="&$AI$18+7*(2-1)+6))/(SUMIFS($M$8:$M$37,$A$8:$A$37,">="&$AI$18+7*(2-1),$A$8:$A$37,"<="&$AI$18+7*(2-1)+6)+SUMIFS('2026年05月'!$M$8:$M$38,'2026年05月'!$A$8:$A$38,">="&$AI$18+7*(2-1),'2026年05月'!$A$8:$A$38,"<="&$AI$18+7*(2-1)+6)),"")) -> 1.1214953 | AG21: =IF($AB21="","",IFERROR((SUMIFS($P$8:$P$37,$A$8:$A$37,">="&$AI$18+7*(2-1),$A$8:$A$37,"<="&$AI$18+7*(2-1)+6)+SUMIFS('2026年05月'!$P$8:$P$38,'2026年05月'!$A$8:$A$38,">="&$AI$18+7*(2-1),'2026年05月'!$A$8:$A$38,"<="&$AI$18+7*(2-1)+6))/(SUMIFS($O$8:$O$37,$A$8:$A$37,">="&$AI$18+7*(2-1),$A$8:$A$37,"<="&$AI$18+7*(2-1)+6)+SUMIFS('2026年05月'!$O$8:$O$38,'2026年05月'!$A$8:$A$38,">="&$AI$18+7*(2-1),'2026年05月'!$A$8:$A$38,"<="&$AI$18+7*(2-1)+6)),"")) -> 0.48816568
A22: 46127 | B22: =MID("日月火水木金土",WEEKDAY(A22),1) -> 水 | C22: 500000 | D22: =SUM($C$8:C22) -> 8700000 | E22: 141345 | F22: 219930 | G22: =IF(COUNT(E22:F22)=0,"",SUM(E22:F22)) -> 361275 | H22: =IF(G22="","",SUM($G$8:G22)) -> 4502788 | I22: =IF(G22="","",IFERROR(G22/C22,"")) -> 0.72255 | J22: =IF(H22="","",IFERROR(H22/D22,"")) -> 0.51756184 | K22: =IF(H22="","",IF(D22=0,"",H22-D22)) -> -4197212 | L22: =IF(G22="","—",IF(D22=0,"予算未入力",IF(H22>=D22,"◎ ペース内","▲ 遅れ"))) -> ▲ 遅れ | M22: 15 | N22: 17 | O22: 27 | P22: 19 | R22: =IFERROR(M22/O22,"") -> 0.55555556 | S22: =IFERROR(G22/M22,"") -> 24085 | T22: =IFERROR(N22/M22,"") -> 1.1333333 | U22: =IFERROR(P22/O22,"") -> 0.7037037 | W22: 43078 | X22: 0 | AA22: 3 | AB22: =IF($AI$18+7*(3-1)>$A$37,"",TEXT($AI$18+7*(3-1),"m/d")&"-"&TEXT($AI$18+7*(3-1)+6,"m/d")) -> 4/21-4/27 | AC22: =IF($AB22="","",(SUMIFS($G$8:$G$37,$A$8:$A$37,">="&$AI$18+7*(3-1),$A$8:$A$37,"<="&$AI$18+7*(3-1)+6)+SUMIFS('2026年05月'!$G$8:$G$38,'2026年05月'!$A$8:$A$38,">="&$AI$18+7*(3-1),'2026年05月'!$A$8:$A$38,"<="&$AI$18+7*(3-1)+6))) -> 2390767 | AD22: =IF($AB22="","",IFERROR((SUMIFS($M$8:$M$37,$A$8:$A$37,">="&$AI$18+7*(3-1),$A$8:$A$37,"<="&$AI$18+7*(3-1)+6)+SUMIFS('2026年05月'!$M$8:$M$38,'2026年05月'!$A$8:$A$38,">="&$AI$18+7*(3-1),'2026年05月'!$A$8:$A$38,"<="&$AI$18+7*(3-1)+6))/(SUMIFS($O$8:$O$37,$A$8:$A$37,">="&$AI$18+7*(3-1),$A$8:$A$37,"<="&$AI$18+7*(3-1)+6)+SUMIFS('2026年05月'!$O$8:$O$38,'2026年05月'!$A$8:$A$38,">="&$AI$18+7*(3-1),'2026年05月'!$A$8:$A$38,"<="&$AI$18+7*(3-1)+6)),"")) -> 0.28448276 | AE22: =IF($AB22="","",IFERROR((SUMIFS($G$8:$G$37,$A$8:$A$37,">="&$AI$18+7*(3-1),$A$8:$A$37,"<="&$AI$18+7*(3-1)+6)+SUMIFS('2026年05月'!$G$8:$G$38,'2026年05月'!$A$8:$A$38,">="&$AI$18+7*(3-1),'2026年05月'!$A$8:$A$38,"<="&$AI$18+7*(3-1)+6))/(SUMIFS($M$8:$M$37,$A$8:$A$37,">="&$AI$18+7*(3-1),$A$8:$A$37,"<="&$AI$18+7*(3-1)+6)+SUMIFS('2026年05月'!$M$8:$M$38,'2026年05月'!$A$8:$A$38,">="&$AI$18+7*(3-1),'2026年05月'!$A$8:$A$38,"<="&$AI$18+7*(3-1)+6)),"")) -> 24149.162 | AF22: =IF($AB22="","",IFERROR((SUMIFS($N$8:$N$37,$A$8:$A$37,">="&$AI$18+7*(3-1),$A$8:$A$37,"<="&$AI$18+7*(3-1)+6)+SUMIFS('2026年05月'!$N$8:$N$38,'2026年05月'!$A$8:$A$38,">="&$AI$18+7*(3-1),'2026年05月'!$A$8:$A$38,"<="&$AI$18+7*(3-1)+6))/(SUMIFS($M$8:$M$37,$A$8:$A$37,">="&$AI$18+7*(3-1),$A$8:$A$37,"<="&$AI$18+7*(3-1)+6)+SUMIFS('2026年05月'!$M$8:$M$38,'2026年05月'!$A$8:$A$38,">="&$AI$18+7*(3-1),'2026年05月'!$A$8:$A$38,"<="&$AI$18+7*(3-1)+6)),"")) -> 1.1515152 | AG22: =IF($AB22="","",IFERROR((SUMIFS($P$8:$P$37,$A$8:$A$37,">="&$AI$18+7*(3-1),$A$8:$A$37,"<="&$AI$18+7*(3-1)+6)+SUMIFS('2026年05月'!$P$8:$P$38,'2026年05月'!$A$8:$A$38,">="&$AI$18+7*(3-1),'2026年05月'!$A$8:$A$38,"<="&$AI$18+7*(3-1)+6))/(SUMIFS($O$8:$O$37,$A$8:$A$37,">="&$AI$18+7*(3-1),$A$8:$A$37,"<="&$AI$18+7*(3-1)+6)+SUMIFS('2026年05月'!$O$8:$O$38,'2026年05月'!$A$8:$A$38,">="&$AI$18+7*(3-1),'2026年05月'!$A$8:$A$38,"<="&$AI$18+7*(3-1)+6)),"")) -> 0.46551724
A23: 46128 | B23: =MID("日月火水木金土",WEEKDAY(A23),1) -> 木 | C23: 500000 | D23: =SUM($C$8:C23) -> 9200000 | E23: 49710 | F23: 232000 | G23: =IF(COUNT(E23:F23)=0,"",SUM(E23:F23)) -> 281710 | H23: =IF(G23="","",SUM($G$8:G23)) -> 4784498 | I23: =IF(G23="","",IFERROR(G23/C23,"")) -> 0.56342 | J23: =IF(H23="","",IFERROR(H23/D23,"")) -> 0.52005413 | K23: =IF(H23="","",IF(D23=0,"",H23-D23)) -> -4415502 | L23: =IF(G23="","—",IF(D23=0,"予算未入力",IF(H23>=D23,"◎ ペース内","▲ 遅れ"))) -> ▲ 遅れ | M23: 12 | N23: 12 | O23: 52 | P23: 38 | R23: =IFERROR(M23/O23,"") -> 0.23076923 | S23: =IFERROR(G23/M23,"") -> 23475.833 | T23: =IFERROR(N23/M23,"") -> 1 | U23: =IFERROR(P23/O23,"") -> 0.73076923 | W23: 43159 | X23: 0 | AA23: 4 | AB23: =IF($AI$18+7*(4-1)>$A$37,"",TEXT($AI$18+7*(4-1),"m/d")&"-"&TEXT($AI$18+7*(4-1)+6,"m/d")) -> 4/28-5/4 | AC23: =IF($AB23="","",(SUMIFS($G$8:$G$37,$A$8:$A$37,">="&$AI$18+7*(4-1),$A$8:$A$37,"<="&$AI$18+7*(4-1)+6)+SUMIFS('2026年05月'!$G$8:$G$38,'2026年05月'!$A$8:$A$38,">="&$AI$18+7*(4-1),'2026年05月'!$A$8:$A$38,"<="&$AI$18+7*(4-1)+6))) -> 3137766 | AD23: =IF($AB23="","",IFERROR((SUMIFS($M$8:$M$37,$A$8:$A$37,">="&$AI$18+7*(4-1),$A$8:$A$37,"<="&$AI$18+7*(4-1)+6)+SUMIFS('2026年05月'!$M$8:$M$38,'2026年05月'!$A$8:$A$38,">="&$AI$18+7*(4-1),'2026年05月'!$A$8:$A$38,"<="&$AI$18+7*(4-1)+6))/(SUMIFS($O$8:$O$37,$A$8:$A$37,">="&$AI$18+7*(4-1),$A$8:$A$37,"<="&$AI$18+7*(4-1)+6)+SUMIFS('2026年05月'!$O$8:$O$38,'2026年05月'!$A$8:$A$38,">="&$AI$18+7*(4-1),'2026年05月'!$A$8:$A$38,"<="&$AI$18+7*(4-1)+6)),"")) -> 0.33253589 | AE23: =IF($AB23="","",IFERROR((SUMIFS($G$8:$G$37,$A$8:$A$37,">="&$AI$18+7*(4-1),$A$8:$A$37,"<="&$AI$18+7*(4-1)+6)+SUMIFS('2026年05月'!$G$8:$G$38,'2026年05月'!$A$8:$A$38,">="&$AI$18+7*(4-1),'2026年05月'!$A$8:$A$38,"<="&$AI$18+7*(4-1)+6))/(SUMIFS($M$8:$M$37,$A$8:$A$37,">="&$AI$18+7*(4-1),$A$8:$A$37,"<="&$AI$18+7*(4-1)+6)+SUMIFS('2026年05月'!$M$8:$M$38,'2026年05月'!$A$8:$A$38,">="&$AI$18+7*(4-1),'2026年05月'!$A$8:$A$38,"<="&$AI$18+7*(4-1)+6)),"")) -> 22573.856 | AF23: =IF($AB23="","",IFERROR((SUMIFS($N$8:$N$37,$A$8:$A$37,">="&$AI$18+7*(4-1),$A$8:$A$37,"<="&$AI$18+7*(4-1)+6)+SUMIFS('2026年05月'!$N$8:$N$38,'2026年05月'!$A$8:$A$38,">="&$AI$18+7*(4-1),'2026年05月'!$A$8:$A$38,"<="&$AI$18+7*(4-1)+6))/(SUMIFS($M$8:$M$37,$A$8:$A$37,">="&$AI$18+7*(4-1),$A$8:$A$37,"<="&$AI$18+7*(4-1)+6)+SUMIFS('2026年05月'!$M$8:$M$38,'2026年05月'!$A$8:$A$38,">="&$AI$18+7*(4-1),'2026年05月'!$A$8:$A$38,"<="&$AI$18+7*(4-1)+6)),"")) -> 1.1007194 | AG23: =IF($AB23="","",IFERROR((SUMIFS($P$8:$P$37,$A$8:$A$37,">="&$AI$18+7*(4-1),$A$8:$A$37,"<="&$AI$18+7*(4-1)+6)+SUMIFS('2026年05月'!$P$8:$P$38,'2026年05月'!$A$8:$A$38,">="&$AI$18+7*(4-1),'2026年05月'!$A$8:$A$38,"<="&$AI$18+7*(4-1)+6))/(SUMIFS($O$8:$O$37,$A$8:$A$37,">="&$AI$18+7*(4-1),$A$8:$A$37,"<="&$AI$18+7*(4-1)+6)+SUMIFS('2026年05月'!$O$8:$O$38,'2026年05月'!$A$8:$A$38,">="&$AI$18+7*(4-1),'2026年05月'!$A$8:$A$38,"<="&$AI$18+7*(4-1)+6)),"")) -> 0.57177033
A24: 46129 | B24: =MID("日月火水木金土",WEEKDAY(A24),1) -> 金 | C24: 500000 | D24: =SUM($C$8:C24) -> 9700000 | E24: 69730 | F24: 193360 | G24: =IF(COUNT(E24:F24)=0,"",SUM(E24:F24)) -> 263090 | H24: =IF(G24="","",SUM($G$8:G24)) -> 5047588 | I24: =IF(G24="","",IFERROR(G24/C24,"")) -> 0.52618 | J24: =IF(H24="","",IFERROR(H24/D24,"")) -> 0.5203699 | K24: =IF(H24="","",IF(D24=0,"",H24-D24)) -> -4652412 | L24: =IF(G24="","—",IF(D24=0,"予算未入力",IF(H24>=D24,"◎ ペース内","▲ 遅れ"))) -> ▲ 遅れ | M24: 11 | N24: 12 | O24: 45 | P24: 17 | Q24: 36 | R24: =IFERROR(M24/O24,"") -> 0.24444444 | S24: =IFERROR(G24/M24,"") -> 23917.273 | T24: =IFERROR(N24/M24,"") -> 1.0909091 | U24: =IFERROR(P24/O24,"") -> 0.37777778 | W24: 43305 | X24: 0 | AA24: 5 | AB24: =IF($AI$18+7*(5-1)>$A$37,"",TEXT($AI$18+7*(5-1),"m/d")&"-"&TEXT($AI$18+7*(5-1)+6,"m/d")) | AC24: =IF($AB24="","",(SUMIFS($G$8:$G$37,$A$8:$A$37,">="&$AI$18+7*(5-1),$A$8:$A$37,"<="&$AI$18+7*(5-1)+6)+SUMIFS('2026年05月'!$G$8:$G$38,'2026年05月'!$A$8:$A$38,">="&$AI$18+7*(5-1),'2026年05月'!$A$8:$A$38,"<="&$AI$18+7*(5-1)+6))) | AD24: =IF($AB24="","",IFERROR((SUMIFS($M$8:$M$37,$A$8:$A$37,">="&$AI$18+7*(5-1),$A$8:$A$37,"<="&$AI$18+7*(5-1)+6)+SUMIFS('2026年05月'!$M$8:$M$38,'2026年05月'!$A$8:$A$38,">="&$AI$18+7*(5-1),'2026年05月'!$A$8:$A$38,"<="&$AI$18+7*(5-1)+6))/(SUMIFS($O$8:$O$37,$A$8:$A$37,">="&$AI$18+7*(5-1),$A$8:$A$37,"<="&$AI$18+7*(5-1)+6)+SUMIFS('2026年05月'!$O$8:$O$38,'2026年05月'!$A$8:$A$38,">="&$AI$18+7*(5-1),'2026年05月'!$A$8:$A$38,"<="&$AI$18+7*(5-1)+6)),"")) | AE24: =IF($AB24="","",IFERROR((SUMIFS($G$8:$G$37,$A$8:$A$37,">="&$AI$18+7*(5-1),$A$8:$A$37,"<="&$AI$18+7*(5-1)+6)+SUMIFS('2026年05月'!$G$8:$G$38,'2026年05月'!$A$8:$A$38,">="&$AI$18+7*(5-1),'2026年05月'!$A$8:$A$38,"<="&$AI$18+7*(5-1)+6))/(SUMIFS($M$8:$M$37,$A$8:$A$37,">="&$AI$18+7*(5-1),$A$8:$A$37,"<="&$AI$18+7*(5-1)+6)+SUMIFS('2026年05月'!$M$8:$M$38,'2026年05月'!$A$8:$A$38,">="&$AI$18+7*(5-1),'2026年05月'!$A$8:$A$38,"<="&$AI$18+7*(5-1)+6)),"")) | AF24: =IF($AB24="","",IFERROR((SUMIFS($N$8:$N$37,$A$8:$A$37,">="&$AI$18+7*(5-1),$A$8:$A$37,"<="&$AI$18+7*(5-1)+6)+SUMIFS('2026年05月'!$N$8:$N$38,'2026年05月'!$A$8:$A$38,">="&$AI$18+7*(5-1),'2026年05月'!$A$8:$A$38,"<="&$AI$18+7*(5-1)+6))/(SUMIFS($M$8:$M$37,$A$8:$A$37,">="&$AI$18+7*(5-1),$A$8:$A$37,"<="&$AI$18+7*(5-1)+6)+SUMIFS('2026年05月'!$M$8:$M$38,'2026年05月'!$A$8:$A$38,">="&$AI$18+7*(5-1),'2026年05月'!$A$8:$A$38,"<="&$AI$18+7*(5-1)+6)),"")) | AG24: =IF($AB24="","",IFERROR((SUMIFS($P$8:$P$37,$A$8:$A$37,">="&$AI$18+7*(5-1),$A$8:$A$37,"<="&$AI$18+7*(5-1)+6)+SUMIFS('2026年05月'!$P$8:$P$38,'2026年05月'!$A$8:$A$38,">="&$AI$18+7*(5-1),'2026年05月'!$A$8:$A$38,"<="&$AI$18+7*(5-1)+6))/(SUMIFS($O$8:$O$37,$A$8:$A$37,">="&$AI$18+7*(5-1),$A$8:$A$37,"<="&$AI$18+7*(5-1)+6)+SUMIFS('2026年05月'!$O$8:$O$38,'2026年05月'!$A$8:$A$38,">="&$AI$18+7*(5-1),'2026年05月'!$A$8:$A$38,"<="&$AI$18+7*(5-1)+6)),""))
A25: 46130 | B25: =MID("日月火水木金土",WEEKDAY(A25),1) -> 土 | C25: 800000 | D25: =SUM($C$8:C25) -> 10500000 | E25: 141940 | F25: 345030 | G25: =IF(COUNT(E25:F25)=0,"",SUM(E25:F25)) -> 486970 | H25: =IF(G25="","",SUM($G$8:G25)) -> 5534558 | I25: =IF(G25="","",IFERROR(G25/C25,"")) -> 0.6087125 | J25: =IF(H25="","",IFERROR(H25/D25,"")) -> 0.52710076 | K25: =IF(H25="","",IF(D25=0,"",H25-D25)) -> -4965442 | L25: =IF(G25="","—",IF(D25=0,"予算未入力",IF(H25>=D25,"◎ ペース内","▲ 遅れ"))) -> ▲ 遅れ | M25: 21 | N25: 22 | O25: 74 | P25: 35 | Q25: 55 | R25: =IFERROR(M25/O25,"") -> 0.28378378 | S25: =IFERROR(G25/M25,"") -> 23189.048 | T25: =IFERROR(N25/M25,"") -> 1.047619 | U25: =IFERROR(P25/O25,"") -> 0.47297297 | X25: 0 | AA25: 6 | AB25: =IF($AI$18+7*(6-1)>$A$37,"",TEXT($AI$18+7*(6-1),"m/d")&"-"&TEXT($AI$18+7*(6-1)+6,"m/d")) | AC25: =IF($AB25="","",(SUMIFS($G$8:$G$37,$A$8:$A$37,">="&$AI$18+7*(6-1),$A$8:$A$37,"<="&$AI$18+7*(6-1)+6)+SUMIFS('2026年05月'!$G$8:$G$38,'2026年05月'!$A$8:$A$38,">="&$AI$18+7*(6-1),'2026年05月'!$A$8:$A$38,"<="&$AI$18+7*(6-1)+6))) | AD25: =IF($AB25="","",IFERROR((SUMIFS($M$8:$M$37,$A$8:$A$37,">="&$AI$18+7*(6-1),$A$8:$A$37,"<="&$AI$18+7*(6-1)+6)+SUMIFS('2026年05月'!$M$8:$M$38,'2026年05月'!$A$8:$A$38,">="&$AI$18+7*(6-1),'2026年05月'!$A$8:$A$38,"<="&$AI$18+7*(6-1)+6))/(SUMIFS($O$8:$O$37,$A$8:$A$37,">="&$AI$18+7*(6-1),$A$8:$A$37,"<="&$AI$18+7*(6-1)+6)+SUMIFS('2026年05月'!$O$8:$O$38,'2026年05月'!$A$8:$A$38,">="&$AI$18+7*(6-1),'2026年05月'!$A$8:$A$38,"<="&$AI$18+7*(6-1)+6)),"")) | AE25: =IF($AB25="","",IFERROR((SUMIFS($G$8:$G$37,$A$8:$A$37,">="&$AI$18+7*(6-1),$A$8:$A$37,"<="&$AI$18+7*(6-1)+6)+SUMIFS('2026年05月'!$G$8:$G$38,'2026年05月'!$A$8:$A$38,">="&$AI$18+7*(6-1),'2026年05月'!$A$8:$A$38,"<="&$AI$18+7*(6-1)+6))/(SUMIFS($M$8:$M$37,$A$8:$A$37,">="&$AI$18+7*(6-1),$A$8:$A$37,"<="&$AI$18+7*(6-1)+6)+SUMIFS('2026年05月'!$M$8:$M$38,'2026年05月'!$A$8:$A$38,">="&$AI$18+7*(6-1),'2026年05月'!$A$8:$A$38,"<="&$AI$18+7*(6-1)+6)),"")) | AF25: =IF($AB25="","",IFERROR((SUMIFS($N$8:$N$37,$A$8:$A$37,">="&$AI$18+7*(6-1),$A$8:$A$37,"<="&$AI$18+7*(6-1)+6)+SUMIFS('2026年05月'!$N$8:$N$38,'2026年05月'!$A$8:$A$38,">="&$AI$18+7*(6-1),'2026年05月'!$A$8:$A$38,"<="&$AI$18+7*(6-1)+6))/(SUMIFS($M$8:$M$37,$A$8:$A$37,">="&$AI$18+7*(6-1),$A$8:$A$37,"<="&$AI$18+7*(6-1)+6)+SUMIFS('2026年05月'!$M$8:$M$38,'2026年05月'!$A$8:$A$38,">="&$AI$18+7*(6-1),'2026年05月'!$A$8:$A$38,"<="&$AI$18+7*(6-1)+6)),"")) | AG25: =IF($AB25="","",IFERROR((SUMIFS($P$8:$P$37,$A$8:$A$37,">="&$AI$18+7*(6-1),$A$8:$A$37,"<="&$AI$18+7*(6-1)+6)+SUMIFS('2026年05月'!$P$8:$P$38,'2026年05月'!$A$8:$A$38,">="&$AI$18+7*(6-1),'2026年05月'!$A$8:$A$38,"<="&$AI$18+7*(6-1)+6))/(SUMIFS($O$8:$O$37,$A$8:$A$37,">="&$AI$18+7*(6-1),$A$8:$A$37,"<="&$AI$18+7*(6-1)+6)+SUMIFS('2026年05月'!$O$8:$O$38,'2026年05月'!$A$8:$A$38,">="&$AI$18+7*(6-1),'2026年05月'!$A$8:$A$38,"<="&$AI$18+7*(6-1)+6)),""))
A26: 46131 | B26: =MID("日月火水木金土",WEEKDAY(A26),1) -> 日 | C26: 800000 | D26: =SUM($C$8:C26) -> 11300000 | E26: 88320 | F26: 459850 | G26: =IF(COUNT(E26:F26)=0,"",SUM(E26:F26)) -> 548170 | H26: =IF(G26="","",SUM($G$8:G26)) -> 6082728 | I26: =IF(G26="","",IFERROR(G26/C26,"")) -> 0.6852125 | J26: =IF(H26="","",IFERROR(H26/D26,"")) -> 0.53829451 | K26: =IF(H26="","",IF(D26=0,"",H26-D26)) -> -5217272 | L26: =IF(G26="","—",IF(D26=0,"予算未入力",IF(H26>=D26,"◎ ペース内","▲ 遅れ"))) -> ▲ 遅れ | M26: 24 | N26: 26 | O26: 62 | P26: 27 | Q26: 60 | R26: =IFERROR(M26/O26,"") -> 0.38709677 | S26: =IFERROR(G26/M26,"") -> 22840.417 | T26: =IFERROR(N26/M26,"") -> 1.0833333 | U26: =IFERROR(P26/O26,"") -> 0.43548387 | W26: 43533 | X26: 0 | Y26: ※要確認：旧シートの売上合計と内訳が+210,350円ズレ。合計548,170円に合わせクレジットを249,500→459,850に調整 | AA26: ※期間ラベルは第1火曜から自動生成。決定率・客単価・セット率・試着率は「週合計÷週合計」
A27: 46132 | B27: =MID("日月火水木金土",WEEKDAY(A27),1) -> 月 | C27: 500000 | D27: =SUM($C$8:C27) -> 11800000 | E27: 48120 | F27: 211450 | G27: =IF(COUNT(E27:F27)=0,"",SUM(E27:F27)) -> 259570 | H27: =IF(G27="","",SUM($G$8:G27)) -> 6342298 | I27: =IF(G27="","",IFERROR(G27/C27,"")) -> 0.51914 | J27: =IF(H27="","",IFERROR(H27/D27,"")) -> 0.53748288 | K27: =IF(H27="","",IF(D27=0,"",H27-D27)) -> -5457702 | L27: =IF(G27="","—",IF(D27=0,"予算未入力",IF(H27>=D27,"◎ ペース内","▲ 遅れ"))) -> ▲ 遅れ | M27: 11 | N27: 13 | O27: 42 | P27: 17 | Q27: 36 | R27: =IFERROR(M27/O27,"") -> 0.26190476 | S27: =IFERROR(G27/M27,"") -> 23597.273 | T27: =IFERROR(N27/M27,"") -> 1.1818182 | U27: =IFERROR(P27/O27,"") -> 0.4047619 | W27: 43604 | X27: 0 | AA27: ※最終週は翌月にまたぐため、2026年05月シートの実績も自動で合算します
A28: 46133 | B28: =MID("日月火水木金土",WEEKDAY(A28),1) -> 火 | C28: 500000 | D28: =SUM($C$8:C28) -> 12300000 | E28: 48120 | F28: 212270 | G28: =IF(COUNT(E28:F28)=0,"",SUM(E28:F28)) -> 260390 | H28: =IF(G28="","",SUM($G$8:G28)) -> 6602688 | I28: =IF(G28="","",IFERROR(G28/C28,"")) -> 0.52078 | J28: =IF(H28="","",IFERROR(H28/D28,"")) -> 0.5368039 | K28: =IF(H28="","",IF(D28=0,"",H28-D28)) -> -5697312 | L28: =IF(G28="","—",IF(D28=0,"予算未入力",IF(H28>=D28,"◎ ペース内","▲ 遅れ"))) -> ▲ 遅れ | M28: 11 | N28: 12 | O28: 53 | P28: 20 | Q28: 45 | R28: =IFERROR(M28/O28,"") -> 0.20754717 | S28: =IFERROR(G28/M28,"") -> 23671.818 | T28: =IFERROR(N28/M28,"") -> 1.0909091 | U28: =IFERROR(P28/O28,"") -> 0.37735849 | W28: 43732 | X28: 0 | Y28: ※要確認：旧シートの売上合計と内訳が+30円ズレ。合計260,390円に合わせクレジットを212,240→212,270に調整 | AA28: ※月初の月曜まで（例：6/1）は前月シートの最終週に含まれます
A29: 46134 | B29: =MID("日月火水木金土",WEEKDAY(A29),1) -> 水 | C29: 600000 | D29: =SUM($C$8:C29) -> 12900000 | E29: 41520 | F29: 338380 | G29: =IF(COUNT(E29:F29)=0,"",SUM(E29:F29)) -> 379900 | H29: =IF(G29="","",SUM($G$8:G29)) -> 6982588 | I29: =IF(G29="","",IFERROR(G29/C29,"")) -> 0.63316667 | J29: =IF(H29="","",IFERROR(H29/D29,"")) -> 0.54128589 | K29: =IF(H29="","",IF(D29=0,"",H29-D29)) -> -5917412 | L29: =IF(G29="","—",IF(D29=0,"予算未入力",IF(H29>=D29,"◎ ペース内","▲ 遅れ"))) -> ▲ 遅れ | M29: 15 | N29: 20 | O29: 63 | P29: 20 | Q29: 67 | R29: =IFERROR(M29/O29,"") -> 0.23809524 | S29: =IFERROR(G29/M29,"") -> 25326.667 | T29: =IFERROR(N29/M29,"") -> 1.3333333 | U29: =IFERROR(P29/O29,"") -> 0.31746032 | W29: 43777 | X29: 0
A30: 46135 | B30: =MID("日月火水木金土",WEEKDAY(A30),1) -> 木 | C30: 600000 | D30: =SUM($C$8:C30) -> 13500000 | E30: 42730 | F30: 23810 | G30: =IF(COUNT(E30:F30)=0,"",SUM(E30:F30)) -> 66540 | H30: =IF(G30="","",SUM($G$8:G30)) -> 7049128 | I30: =IF(G30="","",IFERROR(G30/C30,"")) -> 0.1109 | J30: =IF(H30="","",IFERROR(H30/D30,"")) -> 0.52215763 | K30: =IF(H30="","",IF(D30=0,"",H30-D30)) -> -6450872 | L30: =IF(G30="","—",IF(D30=0,"予算未入力",IF(H30>=D30,"◎ ペース内","▲ 遅れ"))) -> ▲ 遅れ | M30: 3 | N30: 4 | O30: 14 | P30: 9 | Q30: 15 | R30: =IFERROR(M30/O30,"") -> 0.21428571 | S30: =IFERROR(G30/M30,"") -> 22180 | T30: =IFERROR(N30/M30,"") -> 1.3333333 | U30: =IFERROR(P30/O30,"") -> 0.64285714 | W30: 43870 | X30: 0
A31: 46136 | B31: =MID("日月火水木金土",WEEKDAY(A31),1) -> 金 | C31: 600000 | D31: =SUM($C$8:C31) -> 14100000 | E31: 83640 | F31: 388867 | G31: =IF(COUNT(E31:F31)=0,"",SUM(E31:F31)) -> 472507 | H31: =IF(G31="","",SUM($G$8:G31)) -> 7521635 | I31: =IF(G31="","",IFERROR(G31/C31,"")) -> 0.78751167 | J31: =IF(H31="","",IFERROR(H31/D31,"")) -> 0.53344929 | K31: =IF(H31="","",IF(D31=0,"",H31-D31)) -> -6578365 | L31: =IF(G31="","—",IF(D31=0,"予算未入力",IF(H31>=D31,"◎ ペース内","▲ 遅れ"))) -> ▲ 遅れ | M31: 18 | N31: 22 | O31: 56 | P31: 28 | Q31: 53 | R31: =IFERROR(M31/O31,"") -> 0.32142857 | S31: =IFERROR(G31/M31,"") -> 26250.389 | T31: =IFERROR(N31/M31,"") -> 1.2222222 | U31: =IFERROR(P31/O31,"") -> 0.5 | W31: 43953 | X31: 0
A32: 46137 | B32: =MID("日月火水木金土",WEEKDAY(A32),1) -> 土 | C32: 800000 | D32: =SUM($C$8:C32) -> 14900000 | E32: 90790 | F32: 322620 | G32: =IF(COUNT(E32:F32)=0,"",SUM(E32:F32)) -> 413410 | H32: =IF(G32="","",SUM($G$8:G32)) -> 7935045 | I32: =IF(G32="","",IFERROR(G32/C32,"")) -> 0.5167625 | J32: =IF(H32="","",IFERROR(H32/D32,"")) -> 0.53255336 | K32: =IF(H32="","",IF(D32=0,"",H32-D32)) -> -6964955 | L32: =IF(G32="","—",IF(D32=0,"予算未入力",IF(H32>=D32,"◎ ペース内","▲ 遅れ"))) -> ▲ 遅れ | M32: 18 | N32: 19 | O32: 62 | P32: 27 | Q32: 53 | R32: =IFERROR(M32/O32,"") -> 0.29032258 | S32: =IFERROR(G32/M32,"") -> 22967.222 | T32: =IFERROR(N32/M32,"") -> 1.0555556 | U32: =IFERROR(P32/O32,"") -> 0.43548387 | W32: 44008 | X32: 0
A33: 46138 | B33: =MID("日月火水木金土",WEEKDAY(A33),1) -> 日 | C33: 800000 | D33: =SUM($C$8:C33) -> 15700000 | E33: 52460 | F33: 511980 | G33: =IF(COUNT(E33:F33)=0,"",SUM(E33:F33)) -> 564440 | H33: =IF(G33="","",SUM($G$8:G33)) -> 8499485 | I33: =IF(G33="","",IFERROR(G33/C33,"")) -> 0.70555 | J33: =IF(H33="","",IFERROR(H33/D33,"")) -> 0.54136847 | K33: =IF(H33="","",IF(D33=0,"",H33-D33)) -> -7200515 | L33: =IF(G33="","—",IF(D33=0,"予算未入力",IF(H33>=D33,"◎ ペース内","▲ 遅れ"))) -> ▲ 遅れ | M33: 24 | N33: 26 | O33: 66 | P33: 45 | Q33: 53 | R33: =IFERROR(M33/O33,"") -> 0.36363636 | S33: =IFERROR(G33/M33,"") -> 23518.333 | T33: =IFERROR(N33/M33,"") -> 1.0833333 | U33: =IFERROR(P33/O33,"") -> 0.68181818 | W33: 44051 | X33: 0 | Y33: ※要確認：旧シートの売上合計と内訳が-60,000円ズレ。合計564,440円に合わせクレジットを571,980→511,980に調整
A34: 46139 | B34: =MID("日月火水木金土",WEEKDAY(A34),1) -> 月 | C34: 600000 | D34: =SUM($C$8:C34) -> 16300000 | E34: 140040 | F34: 93540 | G34: =IF(COUNT(E34:F34)=0,"",SUM(E34:F34)) -> 233580 | H34: =IF(G34="","",SUM($G$8:G34)) -> 8733065 | I34: =IF(G34="","",IFERROR(G34/C34,"")) -> 0.3893 | J34: =IF(H34="","",IFERROR(H34/D34,"")) -> 0.53577086 | K34: =IF(H34="","",IF(D34=0,"",H34-D34)) -> -7566935 | L34: =IF(G34="","—",IF(D34=0,"予算未入力",IF(H34>=D34,"◎ ペース内","▲ 遅れ"))) -> ▲ 遅れ | M34: 10 | N34: 11 | O34: 34 | P34: 13 | Q34: 23 | R34: =IFERROR(M34/O34,"") -> 0.29411765 | S34: =IFERROR(G34/M34,"") -> 23358 | T34: =IFERROR(N34/M34,"") -> 1.1 | U34: =IFERROR(P34/O34,"") -> 0.38235294 | W34: 44085 | X34: 0
A35: 46140 | B35: =MID("日月火水木金土",WEEKDAY(A35),1) -> 火 | C35: 700000 | D35: =SUM($C$8:C35) -> 17000000 | E35: 45920 | F35: 132530 | G35: =IF(COUNT(E35:F35)=0,"",SUM(E35:F35)) -> 178450 | H35: =IF(G35="","",SUM($G$8:G35)) -> 8911515 | I35: =IF(G35="","",IFERROR(G35/C35,"")) -> 0.25492857 | J35: =IF(H35="","",IFERROR(H35/D35,"")) -> 0.52420676 | K35: =IF(H35="","",IF(D35=0,"",H35-D35)) -> -8088485 | L35: =IF(G35="","—",IF(D35=0,"予算未入力",IF(H35>=D35,"◎ ペース内","▲ 遅れ"))) -> ▲ 遅れ | M35: 8 | N35: 8 | O35: 24 | P35: 10 | Q35: 24 | R35: =IFERROR(M35/O35,"") -> 0.33333333 | S35: =IFERROR(G35/M35,"") -> 22306.25 | T35: =IFERROR(N35/M35,"") -> 1 | U35: =IFERROR(P35/O35,"") -> 0.41666667 | W35: 44087 | X35: 0
A36: 46141 | B36: =MID("日月火水木金土",WEEKDAY(A36),1) -> 水 | C36: 800000 | D36: =SUM($C$8:C36) -> 17800000 | E36: 155130 | F36: 454830 | G36: =IF(COUNT(E36:F36)=0,"",SUM(E36:F36)) -> 609960 | H36: =IF(G36="","",SUM($G$8:G36)) -> 9521475 | I36: =IF(G36="","",IFERROR(G36/C36,"")) -> 0.76245 | J36: =IF(H36="","",IFERROR(H36/D36,"")) -> 0.53491433 | K36: =IF(H36="","",IF(D36=0,"",H36-D36)) -> -8278525 | L36: =IF(G36="","—",IF(D36=0,"予算未入力",IF(H36>=D36,"◎ ペース内","▲ 遅れ"))) -> ▲ 遅れ | M36: 26 | N36: 30 | O36: 82 | P36: 50 | Q36: 63 | R36: =IFERROR(M36/O36,"") -> 0.31707317 | S36: =IFERROR(G36/M36,"") -> 23460 | T36: =IFERROR(N36/M36,"") -> 1.1538462 | U36: =IFERROR(P36/O36,"") -> 0.6097561 | X36: 0
A37: 46142 | B37: =MID("日月火水木金土",WEEKDAY(A37),1) -> 木 | C37: 700000 | D37: =SUM($C$8:C37) -> 18500000 | E37: 138850 | F37: 204350 | G37: =IF(COUNT(E37:F37)=0,"",SUM(E37:F37)) -> 343200 | H37: =IF(G37="","",SUM($G$8:G37)) -> 9864675 | I37: =IF(G37="","",IFERROR(G37/C37,"")) -> 0.49028571 | J37: =IF(H37="","",IFERROR(H37/D37,"")) -> 0.53322568 | K37: =IF(H37="","",IF(D37=0,"",H37-D37)) -> -8635325 | L37: =IF(G37="","—",IF(D37=0,"予算未入力",IF(H37>=D37,"◎ ペース内","▲ 遅れ"))) -> ▲ 遅れ | M37: 15 | N37: 18 | O37: 54 | P37: 28 | Q37: 51 | R37: =IFERROR(M37/O37,"") -> 0.27777778 | S37: =IFERROR(G37/M37,"") -> 22880 | T37: =IFERROR(N37/M37,"") -> 1.2 | U37: =IFERROR(P37/O37,"") -> 0.51851852 | W37: 44065 | X37: 0
A38: 月計 | C38: =SUM(C8:C37) -> 18500000 | D38: =C38 -> 18500000 | E38: =SUM(E8:E37) -> 2338915 | F38: =SUM(F8:F37) -> 7525760 | G38: =SUM(G8:G37) -> 9864675 | H38: =G38 -> 9864675 | I38: =IFERROR(G38/C38,"") -> 0.53322568 | J38: =IFERROR(G38/C38,"") -> 0.53322568 | K38: =G38-C38 -> -8635325 | M38: =SUM(M8:M37) -> 425 | N38: =SUM(N8:N37) -> 467 | O38: =SUM(O8:O37) -> 1489 | P38: =SUM(P8:P37) -> 717 | Q38: =SUM(Q8:Q37) -> 634 | R38: =IFERROR(M38/O38,"") -> 0.28542646 | S38: =IFERROR(G38/M38,"") -> 23211 | T38: =IFERROR(N38/M38,"") -> 1.0988235 | U38: =IFERROR(P38/O38,"") -> 0.48153123 | V38: =SUM(V8:V37) -> 0 | W38: =IFERROR(LOOKUP(9.99E+307,W8:W37),"") -> 44065 | X38: =SUM(X8:X37) -> 0 | Y38: フォロワーは月末値

Sheet 2026年05月
A1: 2026年5月 原宿店 日別売上管理
A2: 青字＋薄黄色のセルが入力欄。白セルは数式なので触らないでください。単位：円
A3: 月間予算 | C3: 当月実績 | E3: 達成率 | G3: 営業日数(/31日) | I3: 残り必要額 | K3: 残り必要日商
A4: =IF('設定'!$B$9="",SUM(C8:C38),'設定'!$B$9) -> 12329470 | C4: =SUM(G8:G38) -> 12381052 | E4: =IFERROR(C4/A4,0) -> 1.0041836 | G4: =COUNTIF(G8:G38,">0") -> 31 | I4: =A4-C4 -> -51582 | K4: =IF((31-G4)>0,(A4-C4)/(31-G4),0) -> 0
A5: 日次予算合計 | C5: 着地見込 | E5: 決定率 | G5: 客単価 | I5: セット率 | K5: 試着率
A6: =SUM(C8:C38) -> 20200000 | C6: =IFERROR(C4/G4*31,0) -> 12381052 | E6: =IFERROR(M39/O39,0) -> 0.35422164 | G6: =IFERROR(G39/M39,0) -> 23055.963 | I6: =IFERROR(N39/M39,0) -> 1.1061453 | K6: =IFERROR(P39/O39,0) -> 0.61081794
A7: 日付 | B7: 曜 | C7: 日次予算 | D7: 累計予算 | E7: 現金 | F7: クレジット | G7: 実績合計 | H7: 累計実績 | I7: 日次達成 | J7: 累計達成 | K7: 累計予実差 | L7: ペース | M7: 購入人数 | N7: 販売点数 | O7: 来客数 | P7: 試着組数 | Q7: 試着個数 | R7: 決定率 | S7: 客単価 | T7: セット率 | U7: 試着率 | V7: クロス クーポン | W7: インスタ フォロワー | X7: 経費 | Y7: メモ | AA7: 曜日 | AB7: 平均日商 | AC7: 日数 | AD7: 決定率 | AE7: 客単価
A8: 46143 | B8: =MID("日月火水木金土",WEEKDAY(A8),1) -> 金 | C8: 500000 | D8: =SUM($C$8:C8) -> 500000 | E8: 82330 | F8: 358729 | G8: =IF(COUNT(E8:F8)=0,"",SUM(E8:F8)) -> 441059 | H8: =IF(G8="","",SUM($G$8:G8)) -> 441059 | I8: =IF(G8="","",IFERROR(G8/C8,"")) -> 0.882118 | J8: =IF(H8="","",IFERROR(H8/D8,"")) -> 0.882118 | K8: =IF(H8="","",IF(D8=0,"",H8-D8)) -> -58941 | L8: =IF(G8="","—",IF(D8=0,"予算未入力",IF(H8>=D8,"◎ ペース内","▲ 遅れ"))) -> ▲ 遅れ | M8: 20 | N8: 21 | O8: 40 | P8: 23 | Q8: 57 | R8: =IFERROR(M8/O8,"") -> 0.5 | S8: =IFERROR(G8/M8,"") -> 22052.95 | T8: =IFERROR(N8/M8,"") -> 1.05 | U8: =IFERROR(P8/O8,"") -> 0.575 | W8: 44051 | X8: 0 | AA8: 月 | AB8: =IFERROR(AVERAGEIFS($G$8:$G$38,$B$8:$B$38,AA8,$G$8:$G$38,">0"),0) -> 445354.25 | AC8: =COUNTIFS($B$8:$B$38,AA8,$G$8:$G$38,">0") -> 4 | AD8: =IFERROR(SUMIF($B$8:$B$38,AA8,$M$8:$M$38)/SUMIF($B$8:$B$38,AA8,$O$8:$O$38),0) -> 0.34955752 | AE8: =IFERROR(SUMIF($B$8:$B$38,AA8,$G$8:$G$38)/SUMIF($B$8:$B$38,AA8,$M$8:$M$38),0) -> 22549.582
A9: 46144 | B9: =MID("日月火水木金土",WEEKDAY(A9),1) -> 土 | C9: 1000000 | D9: =SUM($C$8:C9) -> 1500000 | E9: 112090 | F9: 429750 | G9: =IF(COUNT(E9:F9)=0,"",SUM(E9:F9)) -> 541840 | H9: =IF(G9="","",SUM($G$8:G9)) -> 982899 | I9: =IF(G9="","",IFERROR(G9/C9,"")) -> 0.54184 | J9: =IF(H9="","",IFERROR(H9/D9,"")) -> 0.655266 | K9: =IF(H9="","",IF(D9=0,"",H9-D9)) -> -517101 | L9: =IF(G9="","—",IF(D9=0,"予算未入力",IF(H9>=D9,"◎ ペース内","▲ 遅れ"))) -> ▲ 遅れ | M9: 24 | N9: 26 | O9: 88 | P9: 53 | Q9: 106 | R9: =IFERROR(M9/O9,"") -> 0.27272727 | S9: =IFERROR(G9/M9,"") -> 22576.667 | T9: =IFERROR(N9/M9,"") -> 1.0833333 | U9: =IFERROR(P9/O9,"") -> 0.60227273 | W9: 44043 | X9: 0 | AA9: 火 | AB9: =IFERROR(AVERAGEIFS($G$8:$G$38,$B$8:$B$38,AA9,$G$8:$G$38,">0"),0) -> 348647.5 | AC9: =COUNTIFS($B$8:$B$38,AA9,$G$8:$G$38,">0") -> 4 | AD9: =IFERROR(SUMIF($B$8:$B$38,AA9,$M$8:$M$38)/SUMIF($B$8:$B$38,AA9,$O$8:$O$38),0) -> 0.27777778 | AE9: =IFERROR(SUMIF($B$8:$B$38,AA9,$G$8:$G$38)/SUMIF($B$8:$B$38,AA9,$M$8:$M$38),0) -> 23243.167
A10: 46145 | B10: =MID("日月火水木金土",WEEKDAY(A10),1) -> 日 | C10: 1000000 | D10: =SUM($C$8:C10) -> 2500000 | E10: 164000 | F10: 421487 | G10: =IF(COUNT(E10:F10)=0,"",SUM(E10:F10)) -> 585487 | H10: =IF(G10="","",SUM($G$8:G10)) -> 1568386 | I10: =IF(G10="","",IFERROR(G10/C10,"")) -> 0.585487 | J10: =IF(H10="","",IFERROR(H10/D10,"")) -> 0.6273544 | K10: =IF(H10="","",IF(D10=0,"",H10-D10)) -> -931614 | L10: =IF(G10="","—",IF(D10=0,"予算未入力",IF(H10>=D10,"◎ ペース内","▲ 遅れ"))) -> ▲ 遅れ | M10: 25 | N10: 28 | O10: 74 | P10: 43 | Q10: 86 | R10: =IFERROR(M10/O10,"") -> 0.33783784 | S10: =IFERROR(G10/M10,"") -> 23419.48 | T10: =IFERROR(N10/M10,"") -> 1.12 | U10: =IFERROR(P10/O10,"") -> 0.58108108 | W10: 44038 | X10: 0 | AA10: 水 | AB10: =IFERROR(AVERAGEIFS($G$8:$G$38,$B$8:$B$38,AA10,$G$8:$G$38,">0"),0) -> 388922.5 | AC10: =COUNTIFS($B$8:$B$38,AA10,$G$8:$G$38,">0") -> 4 | AD10: =IFERROR(SUMIF($B$8:$B$38,AA10,$M$8:$M$38)/SUMIF($B$8:$B$38,AA10,$O$8:$O$38),0) -> 0.35227273 | AE10: =IFERROR(SUMIF($B$8:$B$38,AA10,$G$8:$G$38)/SUMIF($B$8:$B$38,AA10,$M$8:$M$38),0) -> 25091.774
A11: 46146 | B11: =MID("日月火水木金土",WEEKDAY(A11),1) -> 月 | C11: 1000000 | D11: =SUM($C$8:C11) -> 3500000 | E11: 105540 | F11: 332230 | G11: =IF(COUNT(E11:F11)=0,"",SUM(E11:F11)) -> 437770 | H11: =IF(G11="","",SUM($G$8:G11)) -> 2006156 | I11: =IF(G11="","",IFERROR(G11/C11,"")) -> 0.43777 | J11: =IF(H11="","",IFERROR(H11/D11,"")) -> 0.57318743 | K11: =IF(H11="","",IF(D11=0,"",H11-D11)) -> -1493844 | L11: =IF(G11="","—",IF(D11=0,"予算未入力",IF(H11>=D11,"◎ ペース内","▲ 遅れ"))) -> ▲ 遅れ | M11: 21 | N11: 22 | O11: 56 | P11: 32 | Q11: 56 | R11: =IFERROR(M11/O11,"") -> 0.375 | S11: =IFERROR(G11/M11,"") -> 20846.19 | T11: =IFERROR(N11/M11,"") -> 1.047619 | U11: =IFERROR(P11/O11,"") -> 0.57142857 | W11: 44028 | X11: 0 | AA11: 木 | AB11: =IFERROR(AVERAGEIFS($G$8:$G$38,$B$8:$B$38,AA11,$G$8:$G$38,">0"),0) -> 298960.75 | AC11: =COUNTIFS($B$8:$B$38,AA11,$G$8:$G$38,">0") -> 4 | AD11: =IFERROR(SUMIF($B$8:$B$38,AA11,$M$8:$M$38)/SUMIF($B$8:$B$38,AA11,$O$8:$O$38),0) -> 0.39416058 | AE11: =IFERROR(SUMIF($B$8:$B$38,AA11,$G$8:$G$38)/SUMIF($B$8:$B$38,AA11,$M$8:$M$38),0) -> 22145.241
A12: 46147 | B12: =MID("日月火水木金土",WEEKDAY(A12),1) -> 火 | C12: 1000000 | D12: =SUM($C$8:C12) -> 4500000 | E12: 186310 | F12: 428550 | G12: =IF(COUNT(E12:F12)=0,"",SUM(E12:F12)) -> 614860 | H12: =IF(G12="","",SUM($G$8:G12)) -> 2621016 | I12: =IF(G12="","",IFERROR(G12/C12,"")) -> 0.61486 | J12: =IF(H12="","",IFERROR(H12/D12,"")) -> 0.582448 | K12: =IF(H12="","",IF(D12=0,"",H12-D12)) -> -1878984 | L12: =IF(G12="","—",IF(D12=0,"予算未入力",IF(H12>=D12,"◎ ペース内","▲ 遅れ"))) -> ▲ 遅れ | M12: 27 | N12: 30 | O12: 78 | P12: 74 | Q12: 59 | R12: =IFERROR(M12/O12,"") -> 0.34615385 | S12: =IFERROR(G12/M12,"") -> 22772.593 | T12: =IFERROR(N12/M12,"") -> 1.1111111 | U12: =IFERROR(P12/O12,"") -> 0.94871795 | W12: 44009 | X12: 0 | AA12: 金 | AB12: =IFERROR(AVERAGEIFS($G$8:$G$38,$B$8:$B$38,AA12,$G$8:$G$38,">0"),0) -> 279935.8 | AC12: =COUNTIFS($B$8:$B$38,AA12,$G$8:$G$38,">0") -> 5 | AD12: =IFERROR(SUMIF($B$8:$B$38,AA12,$M$8:$M$38)/SUMIF($B$8:$B$38,AA12,$O$8:$O$38),0) -> 0.33333333 | AE12: =IFERROR(SUMIF($B$8:$B$38,AA12,$G$8:$G$38)/SUMIF($B$8:$B$38,AA12,$M$8:$M$38),0) -> 23327.983
A13: 46148 | B13: =MID("日月火水木金土",WEEKDAY(A13),1) -> 水 | C13: 1000000 | D13: =SUM($C$8:C13) -> 5500000 | E13: 19910 | F13: 546700 | G13: =IF(COUNT(E13:F13)=0,"",SUM(E13:F13)) -> 566610 | H13: =IF(G13="","",SUM($G$8:G13)) -> 3187626 | I13: =IF(G13="","",IFERROR(G13/C13,"")) -> 0.56661 | J13: =IF(H13="","",IFERROR(H13/D13,"")) -> 0.57956836 | K13: =IF(H13="","",IF(D13=0,"",H13-D13)) -> -2312374 | L13: =IF(G13="","—",IF(D13=0,"予算未入力",IF(H13>=D13,"◎ ペース内","▲ 遅れ"))) -> ▲ 遅れ | M13: 21 | N13: 29 | O13: 73 | P13: 36 | Q13: 85 | R13: =IFERROR(M13/O13,"") -> 0.28767123 | S13: =IFERROR(G13/M13,"") -> 26981.429 | T13: =IFERROR(N13/M13,"") -> 1.3809524 | U13: =IFERROR(P13/O13,"") -> 0.49315068 | W13: 43989 | X13: 0 | AA13: 土 | AB13: =IFERROR(AVERAGEIFS($G$8:$G$38,$B$8:$B$38,AA13,$G$8:$G$38,">0"),0) -> 547375.8 | AC13: =COUNTIFS($B$8:$B$38,AA13,$G$8:$G$38,">0") -> 5 | AD13: =IFERROR(SUMIF($B$8:$B$38,AA13,$M$8:$M$38)/SUMIF($B$8:$B$38,AA13,$O$8:$O$38),0) -> 0.40802676 | AE13: =IFERROR(SUMIF($B$8:$B$38,AA13,$G$8:$G$38)/SUMIF($B$8:$B$38,AA13,$M$8:$M$38),0) -> 22433.434
A14: 46149 | B14: =MID("日月火水木金土",WEEKDAY(A14),1) -> 木 | C14: 600000 | D14: =SUM($C$8:C14) -> 6100000 | E14: 57530 | F14: 299099 | G14: =IF(COUNT(E14:F14)=0,"",SUM(E14:F14)) -> 356629 | H14: =IF(G14="","",SUM($G$8:G14)) -> 3544255 | I14: =IF(G14="","",IFERROR(G14/C14,"")) -> 0.59438167 | J14: =IF(H14="","",IFERROR(H14/D14,"")) -> 0.58102541 | K14: =IF(H14="","",IF(D14=0,"",H14-D14)) -> -2555745 | L14: =IF(G14="","—",IF(D14=0,"予算未入力",IF(H14>=D14,"◎ ペース内","▲ 遅れ"))) -> ▲ 遅れ | M14: 17 | N14: 17 | O14: 45 | P14: 32 | Q14: 56 | R14: =IFERROR(M14/O14,"") -> 0.37777778 | S14: =IFERROR(G14/M14,"") -> 20978.176 | T14: =IFERROR(N14/M14,"") -> 1 | U14: =IFERROR(P14/O14,"") -> 0.71111111 | W14: 43971 | X14: 0 | AA14: 日 | AB14: =IFERROR(AVERAGEIFS($G$8:$G$38,$B$8:$B$38,AA14,$G$8:$G$38,">0"),0) -> 463390.8 | AC14: =COUNTIFS($B$8:$B$38,AA14,$G$8:$G$38,">0") -> 5 | AD14: =IFERROR(SUMIF($B$8:$B$38,AA14,$M$8:$M$38)/SUMIF($B$8:$B$38,AA14,$O$8:$O$38),0) -> 0.35460993 | AE14: =IFERROR(SUMIF($B$8:$B$38,AA14,$G$8:$G$38)/SUMIF($B$8:$B$38,AA14,$M$8:$M$38),0) -> 23169.54
A15: 46150 | B15: =MID("日月火水木金土",WEEKDAY(A15),1) -> 金 | C15: 600000 | D15: =SUM($C$8:C15) -> 6700000 | E15: 0 | F15: 338440 | G15: =IF(COUNT(E15:F15)=0,"",SUM(E15:F15)) -> 338440 | H15: =IF(G15="","",SUM($G$8:G15)) -> 3882695 | I15: =IF(G15="","",IFERROR(G15/C15,"")) -> 0.56406667 | J15: =IF(H15="","",IFERROR(H15/D15,"")) -> 0.57950672 | K15: =IF(H15="","",IF(D15=0,"",H15-D15)) -> -2817305 | L15: =IF(G15="","—",IF(D15=0,"予算未入力",IF(H15>=D15,"◎ ペース内","▲ 遅れ"))) -> ▲ 遅れ | M15: 13 | N15: 17 | O15: 38 | P15: 29 | Q15: 39 | R15: =IFERROR(M15/O15,"") -> 0.34210526 | S15: =IFERROR(G15/M15,"") -> 26033.846 | T15: =IFERROR(N15/M15,"") -> 1.3076923 | U15: =IFERROR(P15/O15,"") -> 0.76315789 | W15: 43954 | X15: 0
A16: 46151 | B16: =MID("日月火水木金土",WEEKDAY(A16),1) -> 土 | C16: 900000 | D16: =SUM($C$8:C16) -> 7600000 | E16: 172350 | F16: 202700 | G16: =IF(COUNT(E16:F16)=0,"",SUM(E16:F16)) -> 375050 | H16: =IF(G16="","",SUM($G$8:G16)) -> 4257745 | I16: =IF(G16="","",IFERROR(G16/C16,"")) -> 0.41672222 | J16: =IF(H16="","",IFERROR(H16/D16,"")) -> 0.56022961 | K16: =IF(H16="","",IF(D16=0,"",H16-D16)) -> -3342255 | L16: =IF(G16="","—",IF(D16=0,"予算未入力",IF(H16>=D16,"◎ ペース内","▲ 遅れ"))) -> ▲ 遅れ | M16: 18 | N16: 20 | O16: 52 | P16: 29 | Q16: 58 | R16: =IFERROR(M16/O16,"") -> 0.34615385 | S16: =IFERROR(G16/M16,"") -> 20836.111 | T16: =IFERROR(N16/M16,"") -> 1.1111111 | U16: =IFERROR(P16/O16,"") -> 0.55769231 | W16: 43954 | X16: 0 | AA16: ※実績入力後に曜日別の傾向が出ます
A17: 46152 | B17: =MID("日月火水木金土",WEEKDAY(A17),1) -> 日 | C17: 900000 | D17: =SUM($C$8:C17) -> 8500000 | E17: 83970 | F17: 284370 | G17: =IF(COUNT(E17:F17)=0,"",SUM(E17:F17)) -> 368340 | H17: =IF(G17="","",SUM($G$8:G17)) -> 4626085 | I17: =IF(G17="","",IFERROR(G17/C17,"")) -> 0.40926667 | J17: =IF(H17="","",IFERROR(H17/D17,"")) -> 0.54424529 | K17: =IF(H17="","",IF(D17=0,"",H17-D17)) -> -3873915 | L17: =IF(G17="","—",IF(D17=0,"予算未入力",IF(H17>=D17,"◎ ペース内","▲ 遅れ"))) -> ▲ 遅れ | M17: 16 | N17: 18 | O17: 48 | P17: 22 | Q17: 58 | R17: =IFERROR(M17/O17,"") -> 0.33333333 | S17: =IFERROR(G17/M17,"") -> 23021.25 | T17: =IFERROR(N17/M17,"") -> 1.125 | U17: =IFERROR(P17/O17,"") -> 0.45833333 | W17: 43945 | X17: 0
A18: 46153 | B18: =MID("日月火水木金土",WEEKDAY(A18),1) -> 月 | C18: 500000 | D18: =SUM($C$8:C18) -> 9000000 | E18: 43610 | F18: 349930 | G18: =IF(COUNT(E18:F18)=0,"",SUM(E18:F18)) -> 393540 | H18: =IF(G18="","",SUM($G$8:G18)) -> 5019625 | I18: =IF(G18="","",IFERROR(G18/C18,"")) -> 0.78708 | J18: =IF(H18="","",IFERROR(H18/D18,"")) -> 0.55773611 | K18: =IF(H18="","",IF(D18=0,"",H18-D18)) -> -3980375 | L18: =IF(G18="","—",IF(D18=0,"予算未入力",IF(H18>=D18,"◎ ペース内","▲ 遅れ"))) -> ▲ 遅れ | M18: 17 | N18: 20 | O18: 52 | P18: 27 | Q18: 53 | R18: =IFERROR(M18/O18,"") -> 0.32692308 | S18: =IFERROR(G18/M18,"") -> 23149.412 | T18: =IFERROR(N18/M18,"") -> 1.1764706 | U18: =IFERROR(P18/O18,"") -> 0.51923077 | W18: 43952 | X18: 0 | AA18: ■ 週次サマリー（火曜〜翌月曜） | AH18: 第1火曜 | AI18: =$A$8+MOD(2-WEEKDAY($A$8,2)+7,7) -> 46147
A19: 46154 | B19: =MID("日月火水木金土",WEEKDAY(A19),1) -> 火 | C19: 500000 | D19: =SUM($C$8:C19) -> 9500000 | E19: 41520 | F19: 122810 | G19: =IF(COUNT(E19:F19)=0,"",SUM(E19:F19)) -> 164330 | H19: =IF(G19="","",SUM($G$8:G19)) -> 5183955 | I19: =IF(G19="","",IFERROR(G19/C19,"")) -> 0.32866 | J19: =IF(H19="","",IFERROR(H19/D19,"")) -> 0.54567947 | K19: =IF(H19="","",IF(D19=0,"",H19-D19)) -> -4316045 | L19: =IF(G19="","—",IF(D19=0,"予算未入力",IF(H19>=D19,"◎ ペース内","▲ 遅れ"))) -> ▲ 遅れ | M19: 8 | N19: 10 | O19: 38 | P19: 14 | Q19: 19 | R19: =IFERROR(M19/O19,"") -> 0.21052632 | S19: =IFERROR(G19/M19,"") -> 20541.25 | T19: =IFERROR(N19/M19,"") -> 1.25 | U19: =IFERROR(P19/O19,"") -> 0.36842105 | W19: 43940 | X19: 0 | AA19: 週 | AB19: 期間 | AC19: 売上 | AD19: 決定率 | AE19: 客単価 | AF19: セット率 | AG19: 試着率
