Workbook

Sheet ダッシュボード
A1: OLD ORDER 名古屋店 売上管理ダッシュボード 2026年4月〜2027年3月
A2: 各月シートの入力欄を埋めると、ここに自動集計されます。単位：円
A4: 年間予算 | C4: 当期実績(YTD) | E4: 年間予算進捗 | G4: 経過月 達成率 | I4: 残り必要額
A5: =IF('設定'!$B$5=0,SUM(B8:B19),'設定'!$B$5) -> 142952527 | C5: =SUM(C8:C19) -> 34259237 | E5: =IFERROR(C5/A5,0) -> 0.23965464 | G5: =IFERROR(SUMIFS($C$8:$C$19,$C$8:$C$19,">0",$B$8:$B$19,">0")/SUMIFS($B$8:$B$19,$C$8:$C$19,">0",$B$8:$B$19,">0"),0) -> 0.43392198 | I5: =A5-C5 -> 108693290
A7: 月 | B7: 月間予算 | C7: 当月実績 | D7: 達成率 | E7: 予実差 | F7: 前年実績 | G7: 前年比 | H7: 購入人数 | I7: 来客数 | J7: 決定率 | K7: 客単価 | L7: 累計予算 | M7: 累計実績 | N7: 累計達成率
A8: 2026年4月 | B8: ='2026年04月'!$A$4 -> 6927491 | C8: ='2026年04月'!$C$4 -> 6331814 | D8: =IF(C8=0,"",IFERROR(C8/B8,"")) -> 0.91401259 | E8: =C8-B8 -> -595677 | F8: =IF('設定'!C8="","",'設定'!C8) | G8: =IF(OR(F8="",C8=0),"",IFERROR(C8/F8,"")) | H8: ='2026年04月'!$N$38 -> 306 | I8: ='2026年04月'!$P$38 -> 938 | J8: =IFERROR(H8/I8,0) -> 0.32622601 | K8: =IFERROR(C8/H8,0) -> 20692.203 | L8: =IF(C8=0,"",SUM($B$8:B8)) -> 6927491 | M8: =IF(C8=0,"",SUM($C$8:C8)) -> 6331814 | N8: =IF(M8="","",IFERROR(M8/L8,0)) -> 0.91401259
A9: 2026年5月 | B9: ='2026年05月'!$A$4 -> 6625036 | C9: ='2026年05月'!$C$4 -> 6030095 | D9: =IF(C9=0,"",IFERROR(C9/B9,"")) -> 0.91019807 | E9: =C9-B9 -> -594941 | F9: =IF('設定'!C9="","",'設定'!C9) | G9: =IF(OR(F9="",C9=0),"",IFERROR(C9/F9,"")) | H9: ='2026年05月'!$N$39 -> 285 | I9: ='2026年05月'!$P$39 -> 1055 | J9: =IFERROR(H9/I9,0) -> 0.27014218 | K9: =IFERROR(C9/H9,0) -> 21158.228 | L9: =IF(C9=0,"",SUM($B$8:B9)) -> 13552527 | M9: =IF(C9=0,"",SUM($C$8:C9)) -> 12361909 | N9: =IF(M9="","",IFERROR(M9/L9,0)) -> 0.9121479
A10: 2026年6月 | B10: ='2026年06月'!$A$4 -> 9000000 | C10: ='2026年06月'!$C$4 -> 5200406 | D10: =IF(C10=0,"",IFERROR(C10/B10,"")) -> 0.57782289 | E10: =C10-B10 -> -3799594 | F10: =IF('設定'!C10="","",'設定'!C10) | G10: =IF(OR(F10="",C10=0),"",IFERROR(C10/F10,"")) | H10: ='2026年06月'!$N$38 -> 240 | I10: ='2026年06月'!$P$38 -> 834 | J10: =IFERROR(H10/I10,0) -> 0.28776978 | K10: =IFERROR(C10/H10,0) -> 21668.358 | L10: =IF(C10=0,"",SUM($B$8:B10)) -> 22552527 | M10: =IF(C10=0,"",SUM($C$8:C10)) -> 17562315 | N10: =IF(M10="","",IFERROR(M10/L10,0)) -> 0.77872936
A11: 2026年7月 | B11: ='2026年07月'!$A$4 -> 14000000 | C11: ='2026年07月'!$C$4 -> 5575024 | D11: =IF(C11=0,"",IFERROR(C11/B11,"")) -> 0.398216 | E11: =C11-B11 -> -8424976 | F11: =IF('設定'!C11="","",'設定'!C11) | G11: =IF(OR(F11="",C11=0),"",IFERROR(C11/F11,"")) | H11: ='2026年07月'!$O$39 -> 241 | I11: ='2026年07月'!$Q$39 -> 793 | J11: =IFERROR(H11/I11,0) -> 0.30390921 | K11: =IFERROR(C11/H11,0) -> 23132.88 | L11: =IF(C11=0,"",SUM($B$8:B11)) -> 36552527 | M11: =IF(C11=0,"",SUM($C$8:C11)) -> 23137339 | N11: =IF(M11="","",IFERROR(M11/L11,0)) -> 0.63298877
A12: 2026年8月 | B12: ='2026年08月'!$A$4 -> 17400000 | C12: ='2026年08月'!$C$4 -> 4585980 | D12: =IF(C12=0,"",IFERROR(C12/B12,"")) -> 0.26356207 | E12: =C12-B12 -> -12814020 | F12: =IF('設定'!C12="","",'設定'!C12) | G12: =IF(OR(F12="",C12=0),"",IFERROR(C12/F12,"")) | H12: ='2026年08月'!$O$39 -> 208 | I12: ='2026年08月'!$Q$39 -> 790 | J12: =IFERROR(H12/I12,0) -> 0.26329114 | K12: =IFERROR(C12/H12,0) -> 22047.981 | L12: =IF(C12=0,"",SUM($B$8:B12)) -> 53952527 | M12: =IF(C12=0,"",SUM($C$8:C12)) -> 27723319 | N12: =IF(M12="","",IFERROR(M12/L12,0)) -> 0.51384653
A13: 2026年9月 | B13: ='2026年09月'!$A$4 -> 14000000 | C13: ='2026年09月'!$C$4 -> 4640983 | D13: =IF(C13=0,"",IFERROR(C13/B13,"")) -> 0.33149879 | E13: =C13-B13 -> -9359017 | F13: =IF('設定'!C13="","",'設定'!C13) | G13: =IF(OR(F13="",C13=0),"",IFERROR(C13/F13,"")) | H13: ='2026年09月'!$O$38 -> 201 | I13: ='2026年09月'!$Q$38 -> 708 | J13: =IFERROR(H13/I13,0) -> 0.28389831 | K13: =IFERROR(C13/H13,0) -> 23089.468 | L13: =IF(C13=0,"",SUM($B$8:B13)) -> 67952527 | M13: =IF(C13=0,"",SUM($C$8:C13)) -> 32364302 | N13: =IF(M13="","",IFERROR(M13/L13,0)) -> 0.47627812
A14: 2026年10月 | B14: ='2026年10月'!$A$4 -> 11000000 | C14: ='2026年10月'!$C$4 -> 1894935 | D14: =IF(C14=0,"",IFERROR(C14/B14,"")) -> 0.17226682 | E14: =C14-B14 -> -9105065 | F14: =IF('設定'!C14="","",'設定'!C14) | G14: =IF(OR(F14="",C14=0),"",IFERROR(C14/F14,"")) | H14: ='2026年10月'!$O$39 -> 83 | I14: ='2026年10月'!$Q$39 -> 379 | J14: =IFERROR(H14/I14,0) -> 0.21899736 | K14: =IFERROR(C14/H14,0) -> 22830.542 | L14: =IF(C14=0,"",SUM($B$8:B14)) -> 78952527 | M14: =IF(C14=0,"",SUM($C$8:C14)) -> 34259237 | N14: =IF(M14="","",IFERROR(M14/L14,0)) -> 0.43392198
A15: 2026年11月 | B15: ='2026年11月'!$A$4 -> 12000000 | C15: ='2026年11月'!$C$4 -> 0 | D15: =IF(C15=0,"",IFERROR(C15/B15,"")) | E15: =C15-B15 -> -12000000 | F15: =IF('設定'!C15="","",'設定'!C15) -> 3642505 | G15: =IF(OR(F15="",C15=0),"",IFERROR(C15/F15,"")) | H15: ='2026年11月'!$O$38 -> 0 | I15: ='2026年11月'!$Q$38 -> 0 | J15: =IFERROR(H15/I15,0) -> 0 | K15: =IFERROR(C15/H15,0) -> 0 | L15: =IF(C15=0,"",SUM($B$8:B15)) | M15: =IF(C15=0,"",SUM($C$8:C15)) | N15: =IF(M15="","",IFERROR(M15/L15,0))
A16: 2026年12月 | B16: ='2026年12月'!$A$4 -> 14000000 | C16: ='2026年12月'!$C$4 -> 0 | D16: =IF(C16=0,"",IFERROR(C16/B16,"")) | E16: =C16-B16 -> -14000000 | F16: =IF('設定'!C16="","",'設定'!C16) -> 9172615 | G16: =IF(OR(F16="",C16=0),"",IFERROR(C16/F16,"")) | H16: ='2026年12月'!$O$39 -> 0 | I16: ='2026年12月'!$Q$39 -> 0 | J16: =IFERROR(H16/I16,0) -> 0 | K16: =IFERROR(C16/H16,0) -> 0 | L16: =IF(C16=0,"",SUM($B$8:B16)) | M16: =IF(C16=0,"",SUM($C$8:C16)) | N16: =IF(M16="","",IFERROR(M16/L16,0))
A17: 2027年1月 | B17: ='2027年01月'!$A$4 -> 15000000 | C17: ='2027年01月'!$C$4 -> 0 | D17: =IF(C17=0,"",IFERROR(C17/B17,"")) | E17: =C17-B17 -> -15000000 | F17: =IF('設定'!C17="","",'設定'!C17) -> 6528886 | G17: =IF(OR(F17="",C17=0),"",IFERROR(C17/F17,"")) | H17: ='2027年01月'!$O$39 -> 0 | I17: ='2027年01月'!$Q$39 -> 0 | J17: =IFERROR(H17/I17,0) -> 0 | K17: =IFERROR(C17/H17,0) -> 0 | L17: =IF(C17=0,"",SUM($B$8:B17)) | M17: =IF(C17=0,"",SUM($C$8:C17)) | N17: =IF(M17="","",IFERROR(M17/L17,0))
A18: 2027年2月 | B18: ='2027年02月'!$A$4 -> 12000000 | C18: ='2027年02月'!$C$4 -> 0 | D18: =IF(C18=0,"",IFERROR(C18/B18,"")) | E18: =C18-B18 -> -12000000 | F18: =IF('設定'!C18="","",'設定'!C18) -> 4592978 | G18: =IF(OR(F18="",C18=0),"",IFERROR(C18/F18,"")) | H18: ='2027年02月'!$O$36 -> 0 | I18: ='2027年02月'!$Q$36 -> 0 | J18: =IFERROR(H18/I18,0) -> 0 | K18: =IFERROR(C18/H18,0) -> 0 | L18: =IF(C18=0,"",SUM($B$8:B18)) | M18: =IF(C18=0,"",SUM($C$8:C18)) | N18: =IF(M18="","",IFERROR(M18/L18,0))
A19: 2027年3月 | B19: ='2027年03月'!$A$4 -> 11000000 | C19: ='2027年03月'!$C$4 -> 0 | D19: =IF(C19=0,"",IFERROR(C19/B19,"")) | E19: =C19-B19 -> -11000000 | F19: =IF('設定'!C19="","",'設定'!C19) -> 5167827 | G19: =IF(OR(F19="",C19=0),"",IFERROR(C19/F19,"")) | H19: ='2027年03月'!$O$39 -> 0 | I19: ='2027年03月'!$Q$39 -> 0 | J19: =IFERROR(H19/I19,0) -> 0 | K19: =IFERROR(C19/H19,0) -> 0 | L19: =IF(C19=0,"",SUM($B$8:B19)) | M19: =IF(C19=0,"",SUM($C$8:C19)) | N19: =IF(M19="","",IFERROR(M19/L19,0))
A20: 合計 | B20: =SUM(B8:B19) -> 142952527 | C20: =SUM(C8:C19) -> 34259237 | D20: =IFERROR(C20/B20,0) -> 0.23965464 | E20: =SUM(E8:E19) -> -108693290 | F20: =SUM(F8:F19) -> 29104811 | G20: =IFERROR(C20/F20,0) -> 1.1770988 | H20: =SUM(H8:H19) -> 1564 | I20: =SUM(I8:I19) -> 5497 | J20: =IFERROR(H20/I20,0) -> 0.28451883 | K20: =IFERROR(C20/H20,0) -> 21904.883
A22: ※前年実績は「設定」シートの青字セルに入力。元データが無い月は空欄です。
A23: ※「経過月 達成率」は予算と実績の両方が入っている月だけで計算します。
A24: 【グラフ】

Sheet 2026年04月
A1: 2026年4月 名古屋店 日別売上管理
A2: 青字＋薄黄色のセルが入力欄。白セルは数式なので触らないでください。単位：円
A3: 月間予算 | C3: 当月実績 | E3: 達成率 | G3: 営業日数(/30日) | I3: 残り必要額 | K3: 残り必要日商
A4: =IF('設定'!$B$8="",SUM(C8:C37),'設定'!$B$8) -> 6927491 | C4: =SUM(H8:H37) -> 6331814 | E4: =IFERROR(C4/A4,0) -> 0.91401259 | G4: =COUNTIF(H8:H37,">0") -> 30 | I4: =A4-C4 -> 595677 | K4: =IF((30-G4)>0,(A4-C4)/(30-G4),0) -> 0
A5: 日次予算合計 | C5: 着地見込 | E5: 決定率 | G5: 客単価 | I5: セット率 | K5: 試着率
A6: =SUM(C8:C37) -> 10200000 | C6: =IFERROR(C4/G4*30,0) -> 6331814 | E6: =IFERROR(N38/P38,0) -> 0.32622601 | G6: =IFERROR(H38/N38,0) -> 20692.203 | I6: =IFERROR(O38/N38,0) -> 1.1045752 | K6: =IFERROR(Q38/P38,0) -> 0.47547974
A7: 日付 | B7: 曜 | C7: 日次予算 | D7: 累計予算 | E7: 現金 | F7: クレジット | G7: 内訳差額 (要確認) | H7: 実績合計 | I7: 累計実績 | J7: 日次達成 | K7: 累計達成 | L7: 累計予実差 | M7: ペース | N7: 購入人数 | O7: 販売点数 | P7: 来客数 | Q7: 試着組数 | R7: 試着個数 | S7: 決定率 | T7: 客単価 | U7: セット率 | V7: 試着率 | W7: クロス クーポン | X7: インスタ フォロワー | Y7: 経費 | Z7: メモ | AB7: 曜日 | AC7: 平均日商 | AD7: 日数 | AE7: 決定率 | AF7: 客単価
A8: 46113 | B8: =MID("日月火水木金土",WEEKDAY(A8),1) -> 水 | C8: 200000 | D8: =SUM($C$8:C8) -> 200000 | E8: 60638 | F8: 107470 | G8: -17706 | H8: =IF(COUNT(E8:G8)=0,"",SUM(E8:G8)) -> 150402 | I8: =IF(H8="","",SUM($H$8:H8)) -> 150402 | J8: =IF(H8="","",IFERROR(H8/C8,"")) -> 0.75201 | K8: =IF(I8="","",IFERROR(I8/D8,"")) -> 0.75201 | L8: =IF(I8="","",IF(D8=0,"",I8-D8)) -> -49598 | M8: =IF(H8="","—",IF(D8=0,"予算未入力",IF(I8>=D8,"◎ ペース内","▲ 遅れ"))) -> ▲ 遅れ | N8: 8 | O8: 8 | P8: 20 | Q8: 13 | S8: =IFERROR(N8/P8,"") -> 0.4 | T8: =IFERROR(H8/N8,"") -> 18800.25 | U8: =IFERROR(O8/N8,"") -> 1 | V8: =IFERROR(Q8/P8,"") -> 0.65 | X8: 8054 | Y8: 0 | AB8: 月 | AC8: =IFERROR(AVERAGEIFS($H$8:$H$37,$B$8:$B$37,AB8,$H$8:$H$37,">0"),0) -> 146293.25 | AD8: =COUNTIFS($B$8:$B$37,AB8,$H$8:$H$37,">0") -> 4 | AE8: =IFERROR(SUMIF($B$8:$B$37,AB8,$N$8:$N$37)/SUMIF($B$8:$B$37,AB8,$P$8:$P$37),0) -> 0.26126126 | AF8: =IFERROR(SUMIF($B$8:$B$37,AB8,$H$8:$H$37)/SUMIF($B$8:$B$37,AB8,$N$8:$N$37),0) -> 20178.379
A9: 46114 | B9: =MID("日月火水木金土",WEEKDAY(A9),1) -> 木 | C9: 200000 | D9: =SUM($C$8:C9) -> 400000 | E9: 40392 | F9: 236347 | G9: 21879 | H9: =IF(COUNT(E9:G9)=0,"",SUM(E9:G9)) -> 298618 | I9: =IF(H9="","",SUM($H$8:H9)) -> 449020 | J9: =IF(H9="","",IFERROR(H9/C9,"")) -> 1.49309 | K9: =IF(I9="","",IFERROR(I9/D9,"")) -> 1.12255 | L9: =IF(I9="","",IF(D9=0,"",I9-D9)) -> 49020 | M9: =IF(H9="","—",IF(D9=0,"予算未入力",IF(I9>=D9,"◎ ペース内","▲ 遅れ"))) -> ◎ ペース内 | N9: 13 | O9: 15 | P9: 33 | Q9: 13 | S9: =IFERROR(N9/P9,"") -> 0.39393939 | T9: =IFERROR(H9/N9,"") -> 22970.615 | U9: =IFERROR(O9/N9,"") -> 1.1538462 | V9: =IFERROR(Q9/P9,"") -> 0.39393939 | X9: 8108 | Y9: 0 | AB9: 火 | AC9: =IFERROR(AVERAGEIFS($H$8:$H$37,$B$8:$B$37,AB9,$H$8:$H$37,">0"),0) -> 107222 | AD9: =COUNTIFS($B$8:$B$37,AB9,$H$8:$H$37,">0") -> 4 | AE9: =IFERROR(SUMIF($B$8:$B$37,AB9,$N$8:$N$37)/SUMIF($B$8:$B$37,AB9,$P$8:$P$37),0) -> 0.25609756 | AF9: =IFERROR(SUMIF($B$8:$B$37,AB9,$H$8:$H$37)/SUMIF($B$8:$B$37,AB9,$N$8:$N$37),0) -> 20423.238
A10: 46115 | B10: =MID("日月火水木金土",WEEKDAY(A10),1) -> 金 | C10: 200000 | D10: =SUM($C$8:C10) -> 600000 | E10: 64598 | F10: 67348 | G10: 30860 | H10: =IF(COUNT(E10:G10)=0,"",SUM(E10:G10)) -> 162806 | I10: =IF(H10="","",SUM($H$8:H10)) -> 611826 | J10: =IF(H10="","",IFERROR(H10/C10,"")) -> 0.81403 | K10: =IF(I10="","",IFERROR(I10/D10,"")) -> 1.01971 | L10: =IF(I10="","",IF(D10=0,"",I10-D10)) -> 11826 | M10: =IF(H10="","—",IF(D10=0,"予算未入力",IF(I10>=D10,"◎ ペース内","▲ 遅れ"))) -> ◎ ペース内 | N10: 8 | O10: 8 | P10: 36 | Q10: 8 | S10: =IFERROR(N10/P10,"") -> 0.22222222 | T10: =IFERROR(H10/N10,"") -> 20350.75 | U10: =IFERROR(O10/N10,"") -> 1 | V10: =IFERROR(Q10/P10,"") -> 0.22222222 | X10: 8167 | Y10: 0 | AB10: 水 | AC10: =IFERROR(AVERAGEIFS($H$8:$H$37,$B$8:$B$37,AB10,$H$8:$H$37,">0"),0) -> 205001.8 | AD10: =COUNTIFS($B$8:$B$37,AB10,$H$8:$H$37,">0") -> 5 | AE10: =IFERROR(SUMIF($B$8:$B$37,AB10,$N$8:$N$37)/SUMIF($B$8:$B$37,AB10,$P$8:$P$37),0) -> 0.38059701 | AF10: =IFERROR(SUMIF($B$8:$B$37,AB10,$H$8:$H$37)/SUMIF($B$8:$B$37,AB10,$N$8:$N$37),0) -> 20098.216
A11: 46116 | B11: =MID("日月火水木金土",WEEKDAY(A11),1) -> 土 | C11: 500000 | D11: =SUM($C$8:C11) -> 1100000 | E11: 43430 | F11: 269270 | G11: -8261 | H11: =IF(COUNT(E11:G11)=0,"",SUM(E11:G11)) -> 304439 | I11: =IF(H11="","",SUM($H$8:H11)) -> 916265 | J11: =IF(H11="","",IFERROR(H11/C11,"")) -> 0.608878 | K11: =IF(I11="","",IFERROR(I11/D11,"")) -> 0.83296818 | L11: =IF(I11="","",IF(D11=0,"",I11-D11)) -> -183735 | M11: =IF(H11="","—",IF(D11=0,"予算未入力",IF(I11>=D11,"◎ ペース内","▲ 遅れ"))) -> ▲ 遅れ | N11: 14 | O11: 26 | P11: 43 | Q11: 38 | S11: =IFERROR(N11/P11,"") -> 0.3255814 | T11: =IFERROR(H11/N11,"") -> 21745.643 | U11: =IFERROR(O11/N11,"") -> 1.8571429 | V11: =IFERROR(Q11/P11,"") -> 0.88372093 | X11: 8220 | Y11: 0 | AB11: 木 | AC11: =IFERROR(AVERAGEIFS($H$8:$H$37,$B$8:$B$37,AB11,$H$8:$H$37,">0"),0) -> 223738.4 | AD11: =COUNTIFS($B$8:$B$37,AB11,$H$8:$H$37,">0") -> 5 | AE11: =IFERROR(SUMIF($B$8:$B$37,AB11,$N$8:$N$37)/SUMIF($B$8:$B$37,AB11,$P$8:$P$37),0) -> 0.3630137 | AF11: =IFERROR(SUMIF($B$8:$B$37,AB11,$H$8:$H$37)/SUMIF($B$8:$B$37,AB11,$N$8:$N$37),0) -> 21107.396
A12: 46117 | B12: =MID("日月火水木金土",WEEKDAY(A12),1) -> 日 | C12: 400000 | D12: =SUM($C$8:C12) -> 1500000 | E12: 72199 | F12: 144030 | G12: 101108 | H12: =IF(COUNT(E12:G12)=0,"",SUM(E12:G12)) -> 317337 | I12: =IF(H12="","",SUM($H$8:H12)) -> 1233602 | J12: =IF(H12="","",IFERROR(H12/C12,"")) -> 0.7933425 | K12: =IF(I12="","",IFERROR(I12/D12,"")) -> 0.82240133 | L12: =IF(I12="","",IF(D12=0,"",I12-D12)) -> -266398 | M12: =IF(H12="","—",IF(D12=0,"予算未入力",IF(I12>=D12,"◎ ペース内","▲ 遅れ"))) -> ▲ 遅れ | N12: 15 | O12: 15 | P12: 51 | Q12: 31 | S12: =IFERROR(N12/P12,"") -> 0.29411765 | T12: =IFERROR(H12/N12,"") -> 21155.8 | U12: =IFERROR(O12/N12,"") -> 1 | V12: =IFERROR(Q12/P12,"") -> 0.60784314 | X12: 8287 | Y12: 0 | AB12: 金 | AC12: =IFERROR(AVERAGEIFS($H$8:$H$37,$B$8:$B$37,AB12,$H$8:$H$37,">0"),0) -> 168889.75 | AD12: =COUNTIFS($B$8:$B$37,AB12,$H$8:$H$37,">0") -> 4 | AE12: =IFERROR(SUMIF($B$8:$B$37,AB12,$N$8:$N$37)/SUMIF($B$8:$B$37,AB12,$P$8:$P$37),0) -> 0.28695652 | AF12: =IFERROR(SUMIF($B$8:$B$37,AB12,$H$8:$H$37)/SUMIF($B$8:$B$37,AB12,$N$8:$N$37),0) -> 20471.485
A13: 46118 | B13: =MID("日月火水木金土",WEEKDAY(A13),1) -> 月 | C13: 300000 | D13: =SUM($C$8:C13) -> 1800000 | E13: 23810 | F13: 150520 | G13: 4780 | H13: =IF(COUNT(E13:G13)=0,"",SUM(E13:G13)) -> 179110 | I13: =IF(H13="","",SUM($H$8:H13)) -> 1412712 | J13: =IF(H13="","",IFERROR(H13/C13,"")) -> 0.59703333 | K13: =IF(I13="","",IFERROR(I13/D13,"")) -> 0.78484 | L13: =IF(I13="","",IF(D13=0,"",I13-D13)) -> -387288 | M13: =IF(H13="","—",IF(D13=0,"予算未入力",IF(I13>=D13,"◎ ペース内","▲ 遅れ"))) -> ▲ 遅れ | N13: 8 | O13: 9 | P13: 21 | Q13: 8 | S13: =IFERROR(N13/P13,"") -> 0.38095238 | T13: =IFERROR(H13/N13,"") -> 22388.75 | U13: =IFERROR(O13/N13,"") -> 1.125 | V13: =IFERROR(Q13/P13,"") -> 0.38095238 | X13: 8332 | Y13: 0 | AB13: 土 | AC13: =IFERROR(AVERAGEIFS($H$8:$H$37,$B$8:$B$37,AB13,$H$8:$H$37,">0"),0) -> 277896.75 | AD13: =COUNTIFS($B$8:$B$37,AB13,$H$8:$H$37,">0") -> 4 | AE13: =IFERROR(SUMIF($B$8:$B$37,AB13,$N$8:$N$37)/SUMIF($B$8:$B$37,AB13,$P$8:$P$37),0) -> 0.28108108 | AF13: =IFERROR(SUMIF($B$8:$B$37,AB13,$H$8:$H$37)/SUMIF($B$8:$B$37,AB13,$N$8:$N$37),0) -> 21376.673
A14: 46119 | B14: =MID("日月火水木金土",WEEKDAY(A14),1) -> 火 | C14: 300000 | D14: =SUM($C$8:C14) -> 2100000 | E14: 0 | F14: 14520 | G14: -1320 | H14: =IF(COUNT(E14:G14)=0,"",SUM(E14:G14)) -> 13200 | I14: =IF(H14="","",SUM($H$8:H14)) -> 1425912 | J14: =IF(H14="","",IFERROR(H14/C14,"")) -> 0.044 | K14: =IF(I14="","",IFERROR(I14/D14,"")) -> 0.67900571 | L14: =IF(I14="","",IF(D14=0,"",I14-D14)) -> -674088 | M14: =IF(H14="","—",IF(D14=0,"予算未入力",IF(I14>=D14,"◎ ペース内","▲ 遅れ"))) -> ▲ 遅れ | N14: 1 | O14: 1 | P14: 8 | Q14: 3 | S14: =IFERROR(N14/P14,"") -> 0.125 | T14: =IFERROR(H14/N14,"") -> 13200 | U14: =IFERROR(O14/N14,"") -> 1 | V14: =IFERROR(Q14/P14,"") -> 0.375 | X14: 8329 | Y14: 0 | AB14: 日 | AC14: =IFERROR(AVERAGEIFS($H$8:$H$37,$B$8:$B$37,AB14,$H$8:$H$37,">0"),0) -> 346726.5 | AD14: =COUNTIFS($B$8:$B$37,AB14,$H$8:$H$37,">0") -> 4 | AE14: =IFERROR(SUMIF($B$8:$B$37,AB14,$N$8:$N$37)/SUMIF($B$8:$B$37,AB14,$P$8:$P$37),0) -> 0.40606061 | AF14: =IFERROR(SUMIF($B$8:$B$37,AB14,$H$8:$H$37)/SUMIF($B$8:$B$37,AB14,$N$8:$N$37),0) -> 20700.09
A15: 46120 | B15: =MID("日月火水木金土",WEEKDAY(A15),1) -> 水 | C15: 300000 | D15: =SUM($C$8:C15) -> 2400000 | E15: 21610 | F15: 50320 | G15: 15074 | H15: =IF(COUNT(E15:G15)=0,"",SUM(E15:G15)) -> 87004 | I15: =IF(H15="","",SUM($H$8:H15)) -> 1512916 | J15: =IF(H15="","",IFERROR(H15/C15,"")) -> 0.29001333 | K15: =IF(I15="","",IFERROR(I15/D15,"")) -> 0.63038167 | L15: =IF(I15="","",IF(D15=0,"",I15-D15)) -> -887084 | M15: =IF(H15="","—",IF(D15=0,"予算未入力",IF(I15>=D15,"◎ ペース内","▲ 遅れ"))) -> ▲ 遅れ | N15: 4 | O15: 4 | P15: 18 | Q15: 10 | S15: =IFERROR(N15/P15,"") -> 0.22222222 | T15: =IFERROR(H15/N15,"") -> 21751 | U15: =IFERROR(O15/N15,"") -> 1 | V15: =IFERROR(Q15/P15,"") -> 0.55555556 | X15: 8331 | Y15: 0
A16: 46121 | B16: =MID("日月火水木金土",WEEKDAY(A16),1) -> 木 | C16: 300000 | D16: =SUM($C$8:C16) -> 2700000 | E16: 21500 | F16: 23810 | G16: 43321 | H16: =IF(COUNT(E16:G16)=0,"",SUM(E16:G16)) -> 88631 | I16: =IF(H16="","",SUM($H$8:H16)) -> 1601547 | J16: =IF(H16="","",IFERROR(H16/C16,"")) -> 0.29543667 | K16: =IF(I16="","",IFERROR(I16/D16,"")) -> 0.59316556 | L16: =IF(I16="","",IF(D16=0,"",I16-D16)) -> -1098453 | M16: =IF(H16="","—",IF(D16=0,"予算未入力",IF(I16>=D16,"◎ ペース内","▲ 遅れ"))) -> ▲ 遅れ | N16: 4 | O16: 5 | P16: 16 | Q16: 12 | S16: =IFERROR(N16/P16,"") -> 0.25 | T16: =IFERROR(H16/N16,"") -> 22157.75 | U16: =IFERROR(O16/N16,"") -> 1.25 | V16: =IFERROR(Q16/P16,"") -> 0.75 | X16: 8324 | Y16: 0 | AB16: ※実績入力後に曜日別の傾向が出ます
A17: 46122 | B17: =MID("日月火水木金土",WEEKDAY(A17),1) -> 金 | C17: 300000 | D17: =SUM($C$8:C17) -> 3000000 | E17: 23700 | F17: 97730 | G17: -12428 | H17: =IF(COUNT(E17:G17)=0,"",SUM(E17:G17)) -> 109002 | I17: =IF(H17="","",SUM($H$8:H17)) -> 1710549 | J17: =IF(H17="","",IFERROR(H17/C17,"")) -> 0.36334 | K17: =IF(I17="","",IFERROR(I17/D17,"")) -> 0.570183 | L17: =IF(I17="","",IF(D17=0,"",I17-D17)) -> -1289451 | M17: =IF(H17="","—",IF(D17=0,"予算未入力",IF(I17>=D17,"◎ ペース内","▲ 遅れ"))) -> ▲ 遅れ | N17: 5 | O17: 5 | P17: 24 | Q17: 14 | S17: =IFERROR(N17/P17,"") -> 0.20833333 | T17: =IFERROR(H17/N17,"") -> 21800.4 | U17: =IFERROR(O17/N17,"") -> 1 | V17: =IFERROR(Q17/P17,"") -> 0.58333333 | X17: 8317 | Y17: 0
A18: 46123 | B18: =MID("日月火水木金土",WEEKDAY(A18),1) -> 土 | C18: 500000 | D18: =SUM($C$8:C18) -> 3500000 | E18: 117140 | F18: 144350 | G18: -3476 | H18: =IF(COUNT(E18:G18)=0,"",SUM(E18:G18)) -> 258014 | I18: =IF(H18="","",SUM($H$8:H18)) -> 1968563 | J18: =IF(H18="","",IFERROR(H18/C18,"")) -> 0.516028 | K18: =IF(I18="","",IFERROR(I18/D18,"")) -> 0.56244657 | L18: =IF(I18="","",IF(D18=0,"",I18-D18)) -> -1531437 | M18: =IF(H18="","—",IF(D18=0,"予算未入力",IF(I18>=D18,"◎ ペース内","▲ 遅れ"))) -> ▲ 遅れ | N18: 12 | O18: 12 | P18: 43 | Q18: 30 | S18: =IFERROR(N18/P18,"") -> 0.27906977 | T18: =IFERROR(H18/N18,"") -> 21501.167 | U18: =IFERROR(O18/N18,"") -> 1 | V18: =IFERROR(Q18/P18,"") -> 0.69767442 | X18: 8315 | Y18: 0 | AB18: ■ 週次サマリー（火曜〜翌月曜） | AI18: 第1火曜 | AJ18: =$A$8+MOD(2-WEEKDAY($A$8,2)+7,7) -> 46119
A19: 46124 | B19: =MID("日月火水木金土",WEEKDAY(A19),1) -> 日 | C19: 400000 | D19: =SUM($C$8:C19) -> 3900000 | E19: 90630 | F19: 62030 | G19: -14652 | H19: =IF(COUNT(E19:G19)=0,"",SUM(E19:G19)) -> 138008 | I19: =IF(H19="","",SUM($H$8:H19)) -> 2106571 | J19: =IF(H19="","",IFERROR(H19/C19,"")) -> 0.34502 | K19: =IF(I19="","",IFERROR(I19/D19,"")) -> 0.54014641 | L19: =IF(I19="","",IF(D19=0,"",I19-D19)) -> -1793429 | M19: =IF(H19="","—",IF(D19=0,"予算未入力",IF(I19>=D19,"◎ ペース内","▲ 遅れ"))) -> ▲ 遅れ | N19: 7 | O19: 7 | P19: 33 | Q19: 20 | S19: =IFERROR(N19/P19,"") -> 0.21212121 | T19: =IFERROR(H19/N19,"") -> 19715.429 | U19: =IFERROR(O19/N19,"") -> 1 | V19: =IFERROR(Q19/P19,"") -> 0.60606061 | X19: 8308 | Y19: 0 | AB19: 週 | AC19: 期間 | AD19: 売上 | AE19: 決定率 | AF19: 客単価 | AG19: セット率 | AH19: 試着率
A20: 46125 | B20: =MID("日月火水木金土",WEEKDAY(A20),1) -> 月 | C20: 300000 | D20: =SUM($C$8:C20) -> 4200000 | E20: 35910 | F20: 64620 | G20: -9528 | H20: =IF(COUNT(E20:G20)=0,"",SUM(E20:G20)) -> 91002 | I20: =IF(H20="","",SUM($H$8:H20)) -> 2197573 | J20: =IF(H20="","",IFERROR(H20/C20,"")) -> 0.30334 | K20: =IF(I20="","",IFERROR(I20/D20,"")) -> 0.52323167 | L20: =IF(I20="","",IF(D20=0,"",I20-D20)) -> -2002427 | M20: =IF(H20="","—",IF(D20=0,"予算未入力",IF(I20>=D20,"◎ ペース内","▲ 遅れ"))) -> ▲ 遅れ | N20: 5 | O20: 5 | P20: 28 | Q20: 8 | S20: =IFERROR(N20/P20,"") -> 0.17857143 | T20: =IFERROR(H20/N20,"") -> 18200.4 | U20: =IFERROR(O20/N20,"") -> 1 | V20: =IFERROR(Q20/P20,"") -> 0.28571429 | X20: 8304 | Y20: 0 | AB20: 1 | AC20: =IF($AJ$18+7*(1-1)>$A$37,"",TEXT($AJ$18+7*(1-1),"m/d")&"-"&TEXT($AJ$18+7*(1-1)+6,"m/d")) -> 4/7-4/13 | AD20: =IF($AC20="","",(SUMIFS($H$8:$H$37,$A$8:$A$37,">="&$AJ$18+7*(1-1),$A$8:$A$37,"<="&$AJ$18+7*(1-1)+6)+SUMIFS('2026年05月'!$H$8:$H$38,'2026年05月'!$A$8:$A$38,">="&$AJ$18+7*(1-1),'2026年05月'!$A$8:$A$38,"<="&$AJ$18+7*(1-1)+6))) -> 784861 | AE20: =IF($AC20="","",IFERROR((SUMIFS($N$8:$N$37,$A$8:$A$37,">="&$AJ$18+7*(1-1),$A$8:$A$37,"<="&$AJ$18+7*(1-1)+6)+SUMIFS('2026年05月'!$N$8:$N$38,'2026年05月'!$A$8:$A$38,">="&$AJ$18+7*(1-1),'2026年05月'!$A$8:$A$38,"<="&$AJ$18+7*(1-1)+6))/(SUMIFS($P$8:$P$37,$A$8:$A$37,">="&$AJ$18+7*(1-1),$A$8:$A$37,"<="&$AJ$18+7*(1-1)+6)+SUMIFS('2026年05月'!$P$8:$P$38,'2026年05月'!$A$8:$A$38,">="&$AJ$18+7*(1-1),'2026年05月'!$A$8:$A$38,"<="&$AJ$18+7*(1-1)+6)),"")) -> 0.22352941 | AF20: =IF($AC20="","",IFERROR((SUMIFS($H$8:$H$37,$A$8:$A$37,">="&$AJ$18+7*(1-1),$A$8:$A$37,"<="&$AJ$18+7*(1-1)+6)+SUMIFS('2026年05月'!$H$8:$H$38,'2026年05月'!$A$8:$A$38,">="&$AJ$18+7*(1-1),'2026年05月'!$A$8:$A$38,"<="&$AJ$18+7*(1-1)+6))/(SUMIFS($N$8:$N$37,$A$8:$A$37,">="&$AJ$18+7*(1-1),$A$8:$A$37,"<="&$AJ$18+7*(1-1)+6)+SUMIFS('2026年05月'!$N$8:$N$38,'2026年05月'!$A$8:$A$38,">="&$AJ$18+7*(1-1),'2026年05月'!$A$8:$A$38,"<="&$AJ$18+7*(1-1)+6)),"")) -> 20654.237 | AG20: =IF($AC20="","",IFERROR((SUMIFS($O$8:$O$37,$A$8:$A$37,">="&$AJ$18+7*(1-1),$A$8:$A$37,"<="&$AJ$18+7*(1-1)+6)+SUMIFS('2026年05月'!$O$8:$O$38,'2026年05月'!$A$8:$A$38,">="&$AJ$18+7*(1-1),'2026年05月'!$A$8:$A$38,"<="&$AJ$18+7*(1-1)+6))/(SUMIFS($N$8:$N$37,$A$8:$A$37,">="&$AJ$18+7*(1-1),$A$8:$A$37,"<="&$AJ$18+7*(1-1)+6)+SUMIFS('2026年05月'!$N$8:$N$38,'2026年05月'!$A$8:$A$38,">="&$AJ$18+7*(1-1),'2026年05月'!$A$8:$A$38,"<="&$AJ$18+7*(1-1)+6)),"")) -> 1.0263158 | AH20: =IF($AC20="","",IFERROR((SUMIFS($Q$8:$Q$37,$A$8:$A$37,">="&$AJ$18+7*(1-1),$A$8:$A$37,"<="&$AJ$18+7*(1-1)+6)+SUMIFS('2026年05月'!$Q$8:$Q$38,'2026年05月'!$A$8:$A$38,">="&$AJ$18+7*(1-1),'2026年05月'!$A$8:$A$38,"<="&$AJ$18+7*(1-1)+6))/(SUMIFS($P$8:$P$37,$A$8:$A$37,">="&$AJ$18+7*(1-1),$A$8:$A$37,"<="&$AJ$18+7*(1-1)+6)+SUMIFS('2026年05月'!$P$8:$P$38,'2026年05月'!$A$8:$A$38,">="&$AJ$18+7*(1-1),'2026年05月'!$A$8:$A$38,"<="&$AJ$18+7*(1-1)+6)),"")) -> 0.57058824
A21: 46126 | B21: =MID("日月火水木金土",WEEKDAY(A21),1) -> 火 | C21: 300000 | D21: =SUM($C$8:C21) -> 4500000 | E21: 0 | F21: 44110 | G21: 39392 | H21: =IF(COUNT(E21:G21)=0,"",SUM(E21:G21)) -> 83502 | I21: =IF(H21="","",SUM($H$8:H21)) -> 2281075 | J21: =IF(H21="","",IFERROR(H21/C21,"")) -> 0.27834 | K21: =IF(I21="","",IFERROR(I21/D21,"")) -> 0.50690556 | L21: =IF(I21="","",IF(D21=0,"",I21-D21)) -> -2218925 | M21: =IF(H21="","—",IF(D21=0,"予算未入力",IF(I21>=D21,"◎ ペース内","▲ 遅れ"))) -> ▲ 遅れ | N21: 4 | O21: 4 | P21: 25 | Q21: 13 | S21: =IFERROR(N21/P21,"") -> 0.16 | T21: =IFERROR(H21/N21,"") -> 20875.5 | U21: =IFERROR(O21/N21,"") -> 1 | V21: =IFERROR(Q21/P21,"") -> 0.52 | X21: 8301 | Y21: 0 | AB21: 2 | AC21: =IF($AJ$18+7*(2-1)>$A$37,"",TEXT($AJ$18+7*(2-1),"m/d")&"-"&TEXT($AJ$18+7*(2-1)+6,"m/d")) -> 4/14-4/20 | AD21: =IF($AC21="","",(SUMIFS($H$8:$H$37,$A$8:$A$37,">="&$AJ$18+7*(2-1),$A$8:$A$37,"<="&$AJ$18+7*(2-1)+6)+SUMIFS('2026年05月'!$H$8:$H$38,'2026年05月'!$A$8:$A$38,">="&$AJ$18+7*(2-1),'2026年05月'!$A$8:$A$38,"<="&$AJ$18+7*(2-1)+6))) -> 1329465 | AE21: =IF($AC21="","",IFERROR((SUMIFS($N$8:$N$37,$A$8:$A$37,">="&$AJ$18+7*(2-1),$A$8:$A$37,"<="&$AJ$18+7*(2-1)+6)+SUMIFS('2026年05月'!$N$8:$N$38,'2026年05月'!$A$8:$A$38,">="&$AJ$18+7*(2-1),'2026年05月'!$A$8:$A$38,"<="&$AJ$18+7*(2-1)+6))/(SUMIFS($P$8:$P$37,$A$8:$A$37,">="&$AJ$18+7*(2-1),$A$8:$A$37,"<="&$AJ$18+7*(2-1)+6)+SUMIFS('2026年05月'!$P$8:$P$38,'2026年05月'!$A$8:$A$38,">="&$AJ$18+7*(2-1),'2026年05月'!$A$8:$A$38,"<="&$AJ$18+7*(2-1)+6)),"")) -> 0.33668342 | AF21: =IF($AC21="","",IFERROR((SUMIFS($H$8:$H$37,$A$8:$A$37,">="&$AJ$18+7*(2-1),$A$8:$A$37,"<="&$AJ$18+7*(2-1)+6)+SUMIFS('2026年05月'!$H$8:$H$38,'2026年05月'!$A$8:$A$38,">="&$AJ$18+7*(2-1),'2026年05月'!$A$8:$A$38,"<="&$AJ$18+7*(2-1)+6))/(SUMIFS($N$8:$N$37,$A$8:$A$37,">="&$AJ$18+7*(2-1),$A$8:$A$37,"<="&$AJ$18+7*(2-1)+6)+SUMIFS('2026年05月'!$N$8:$N$38,'2026年05月'!$A$8:$A$38,">="&$AJ$18+7*(2-1),'2026年05月'!$A$8:$A$38,"<="&$AJ$18+7*(2-1)+6)),"")) -> 19842.761 | AG21: =IF($AC21="","",IFERROR((SUMIFS($O$8:$O$37,$A$8:$A$37,">="&$AJ$18+7*(2-1),$A$8:$A$37,"<="&$AJ$18+7*(2-1)+6)+SUMIFS('2026年05月'!$O$8:$O$38,'2026年05月'!$A$8:$A$38,">="&$AJ$18+7*(2-1),'2026年05月'!$A$8:$A$38,"<="&$AJ$18+7*(2-1)+6))/(SUMIFS($N$8:$N$37,$A$8:$A$37,">="&$AJ$18+7*(2-1),$A$8:$A$37,"<="&$AJ$18+7*(2-1)+6)+SUMIFS('2026年05月'!$N$8:$N$38,'2026年05月'!$A$8:$A$38,">="&$AJ$18+7*(2-1),'2026年05月'!$A$8:$A$38,"<="&$AJ$18+7*(2-1)+6)),"")) -> 1.0298507 | AH21: =IF($AC21="","",IFERROR((SUMIFS($Q$8:$Q$37,$A$8:$A$37,">="&$AJ$18+7*(2-1),$A$8:$A$37,"<="&$AJ$18+7*(2-1)+6)+SUMIFS('2026年05月'!$Q$8:$Q$38,'2026年05月'!$A$8:$A$38,">="&$AJ$18+7*(2-1),'2026年05月'!$A$8:$A$38,"<="&$AJ$18+7*(2-1)+6))/(SUMIFS($P$8:$P$37,$A$8:$A$37,">="&$AJ$18+7*(2-1),$A$8:$A$37,"<="&$AJ$18+7*(2-1)+6)+SUMIFS('2026年05月'!$P$8:$P$38,'2026年05月'!$A$8:$A$38,">="&$AJ$18+7*(2-1),'2026年05月'!$A$8:$A$38,"<="&$AJ$18+7*(2-1)+6)),"")) -> 0.44221106
A22: 46127 | B22: =MID("日月火水木金土",WEEKDAY(A22),1) -> 水 | C22: 300000 | D22: =SUM($C$8:C22) -> 4800000 | E22: 23810 | F22: 99030 | G22: -11830 | H22: =IF(COUNT(E22:G22)=0,"",SUM(E22:G22)) -> 111010 | I22: =IF(H22="","",SUM($H$8:H22)) -> 2392085 | J22: =IF(H22="","",IFERROR(H22/C22,"")) -> 0.37003333 | K22: =IF(I22="","",IFERROR(I22/D22,"")) -> 0.49835104 | L22: =IF(I22="","",IF(D22=0,"",I22-D22)) -> -2407915 | M22: =IF(H22="","—",IF(D22=0,"予算未入力",IF(I22>=D22,"◎ ペース内","▲ 遅れ"))) -> ▲ 遅れ | N22: 6 | O22: 6 | P22: 17 | Q22: 5 | R22: 11 | S22: =IFERROR(N22/P22,"") -> 0.35294118 | T22: =IFERROR(H22/N22,"") -> 18501.667 | U22: =IFERROR(O22/N22,"") -> 1 | V22: =IFERROR(Q22/P22,"") -> 0.29411765 | X22: 8301 | Y22: 0 | AB22: 3 | AC22: =IF($AJ$18+7*(3-1)>$A$37,"",TEXT($AJ$18+7*(3-1),"m/d")&"-"&TEXT($AJ$18+7*(3-1)+6,"m/d")) -> 4/21-4/27 | AD22: =IF($AC22="","",(SUMIFS($H$8:$H$37,$A$8:$A$37,">="&$AJ$18+7*(3-1),$A$8:$A$37,"<="&$AJ$18+7*(3-1)+6)+SUMIFS('2026年05月'!$H$8:$H$38,'2026年05月'!$A$8:$A$38,">="&$AJ$18+7*(3-1),'2026年05月'!$A$8:$A$38,"<="&$AJ$18+7*(3-1)+6))) -> 1685356 | AE22: =IF($AC22="","",IFERROR((SUMIFS($N$8:$N$37,$A$8:$A$37,">="&$AJ$18+7*(3-1),$A$8:$A$37,"<="&$AJ$18+7*(3-1)+6)+SUMIFS('2026年05月'!$N$8:$N$38,'2026年05月'!$A$8:$A$38,">="&$AJ$18+7*(3-1),'2026年05月'!$A$8:$A$38,"<="&$AJ$18+7*(3-1)+6))/(SUMIFS($P$8:$P$37,$A$8:$A$37,">="&$AJ$18+7*(3-1),$A$8:$A$37,"<="&$AJ$18+7*(3-1)+6)+SUMIFS('2026年05月'!$P$8:$P$38,'2026年05月'!$A$8:$A$38,">="&$AJ$18+7*(3-1),'2026年05月'!$A$8:$A$38,"<="&$AJ$18+7*(3-1)+6)),"")) -> 0.32916667 | AF22: =IF($AC22="","",IFERROR((SUMIFS($H$8:$H$37,$A$8:$A$37,">="&$AJ$18+7*(3-1),$A$8:$A$37,"<="&$AJ$18+7*(3-1)+6)+SUMIFS('2026年05月'!$H$8:$H$38,'2026年05月'!$A$8:$A$38,">="&$AJ$18+7*(3-1),'2026年05月'!$A$8:$A$38,"<="&$AJ$18+7*(3-1)+6))/(SUMIFS($N$8:$N$37,$A$8:$A$37,">="&$AJ$18+7*(3-1),$A$8:$A$37,"<="&$AJ$18+7*(3-1)+6)+SUMIFS('2026年05月'!$N$8:$N$38,'2026年05月'!$A$8:$A$38,">="&$AJ$18+7*(3-1),'2026年05月'!$A$8:$A$38,"<="&$AJ$18+7*(3-1)+6)),"")) -> 21333.62 | AG22: =IF($AC22="","",IFERROR((SUMIFS($O$8:$O$37,$A$8:$A$37,">="&$AJ$18+7*(3-1),$A$8:$A$37,"<="&$AJ$18+7*(3-1)+6)+SUMIFS('2026年05月'!$O$8:$O$38,'2026年05月'!$A$8:$A$38,">="&$AJ$18+7*(3-1),'2026年05月'!$A$8:$A$38,"<="&$AJ$18+7*(3-1)+6))/(SUMIFS($N$8:$N$37,$A$8:$A$37,">="&$AJ$18+7*(3-1),$A$8:$A$37,"<="&$AJ$18+7*(3-1)+6)+SUMIFS('2026年05月'!$N$8:$N$38,'2026年05月'!$A$8:$A$38,">="&$AJ$18+7*(3-1),'2026年05月'!$A$8:$A$38,"<="&$AJ$18+7*(3-1)+6)),"")) -> 1.1265823 | AH22: =IF($AC22="","",IFERROR((SUMIFS($Q$8:$Q$37,$A$8:$A$37,">="&$AJ$18+7*(3-1),$A$8:$A$37,"<="&$AJ$18+7*(3-1)+6)+SUMIFS('2026年05月'!$Q$8:$Q$38,'2026年05月'!$A$8:$A$38,">="&$AJ$18+7*(3-1),'2026年05月'!$A$8:$A$38,"<="&$AJ$18+7*(3-1)+6))/(SUMIFS($P$8:$P$37,$A$8:$A$37,">="&$AJ$18+7*(3-1),$A$8:$A$37,"<="&$AJ$18+7*(3-1)+6)+SUMIFS('2026年05月'!$P$8:$P$38,'2026年05月'!$A$8:$A$38,">="&$AJ$18+7*(3-1),'2026年05月'!$A$8:$A$38,"<="&$AJ$18+7*(3-1)+6)),"")) -> 0.40416667
A23: 46128 | B23: =MID("日月火水木金土",WEEKDAY(A23),1) -> 木 | C23: 300000 | D23: =SUM($C$8:C23) -> 5100000 | E23: 23810 | F23: 104100 | G23: 6299 | H23: =IF(COUNT(E23:G23)=0,"",SUM(E23:G23)) -> 134209 | I23: =IF(H23="","",SUM($H$8:H23)) -> 2526294 | J23: =IF(H23="","",IFERROR(H23/C23,"")) -> 0.44736333 | K23: =IF(I23="","",IFERROR(I23/D23,"")) -> 0.49535176 | L23: =IF(I23="","",IF(D23=0,"",I23-D23)) -> -2573706 | M23: =IF(H23="","—",IF(D23=0,"予算未入力",IF(I23>=D23,"◎ ペース内","▲ 遅れ"))) -> ▲ 遅れ | N23: 8 | O23: 9 | P23: 24 | Q23: 11 | R23: 19 | S23: =IFERROR(N23/P23,"") -> 0.33333333 | T23: =IFERROR(H23/N23,"") -> 16776.125 | U23: =IFERROR(O23/N23,"") -> 1.125 | V23: =IFERROR(Q23/P23,"") -> 0.45833333 | X23: 8304 | Y23: 0 | AB23: 4 | AC23: =IF($AJ$18+7*(4-1)>$A$37,"",TEXT($AJ$18+7*(4-1),"m/d")&"-"&TEXT($AJ$18+7*(4-1)+6,"m/d")) -> 4/28-5/4 | AD23: =IF($AC23="","",(SUMIFS($H$8:$H$37,$A$8:$A$37,">="&$AJ$18+7*(4-1),$A$8:$A$37,"<="&$AJ$18+7*(4-1)+6)+SUMIFS('2026年05月'!$H$8:$H$38,'2026年05月'!$A$8:$A$38,">="&$AJ$18+7*(4-1),'2026年05月'!$A$8:$A$38,"<="&$AJ$18+7*(4-1)+6))) -> 2560005 | AE23: =IF($AC23="","",IFERROR((SUMIFS($N$8:$N$37,$A$8:$A$37,">="&$AJ$18+7*(4-1),$A$8:$A$37,"<="&$AJ$18+7*(4-1)+6)+SUMIFS('2026年05月'!$N$8:$N$38,'2026年05月'!$A$8:$A$38,">="&$AJ$18+7*(4-1),'2026年05月'!$A$8:$A$38,"<="&$AJ$18+7*(4-1)+6))/(SUMIFS($P$8:$P$37,$A$8:$A$37,">="&$AJ$18+7*(4-1),$A$8:$A$37,"<="&$AJ$18+7*(4-1)+6)+SUMIFS('2026年05月'!$P$8:$P$38,'2026年05月'!$A$8:$A$38,">="&$AJ$18+7*(4-1),'2026年05月'!$A$8:$A$38,"<="&$AJ$18+7*(4-1)+6)),"")) -> 0.38819876 | AF23: =IF($AC23="","",IFERROR((SUMIFS($H$8:$H$37,$A$8:$A$37,">="&$AJ$18+7*(4-1),$A$8:$A$37,"<="&$AJ$18+7*(4-1)+6)+SUMIFS('2026年05月'!$H$8:$H$38,'2026年05月'!$A$8:$A$38,">="&$AJ$18+7*(4-1),'2026年05月'!$A$8:$A$38,"<="&$AJ$18+7*(4-1)+6))/(SUMIFS($N$8:$N$37,$A$8:$A$37,">="&$AJ$18+7*(4-1),$A$8:$A$37,"<="&$AJ$18+7*(4-1)+6)+SUMIFS('2026年05月'!$N$8:$N$38,'2026年05月'!$A$8:$A$38,">="&$AJ$18+7*(4-1),'2026年05月'!$A$8:$A$38,"<="&$AJ$18+7*(4-1)+6)),"")) -> 20480.04 | AG23: =IF($AC23="","",IFERROR((SUMIFS($O$8:$O$37,$A$8:$A$37,">="&$AJ$18+7*(4-1),$A$8:$A$37,"<="&$AJ$18+7*(4-1)+6)+SUMIFS('2026年05月'!$O$8:$O$38,'2026年05月'!$A$8:$A$38,">="&$AJ$18+7*(4-1),'2026年05月'!$A$8:$A$38,"<="&$AJ$18+7*(4-1)+6))/(SUMIFS($N$8:$N$37,$A$8:$A$37,">="&$AJ$18+7*(4-1),$A$8:$A$37,"<="&$AJ$18+7*(4-1)+6)+SUMIFS('2026年05月'!$N$8:$N$38,'2026年05月'!$A$8:$A$38,">="&$AJ$18+7*(4-1),'2026年05月'!$A$8:$A$38,"<="&$AJ$18+7*(4-1)+6)),"")) -> 1.072 | AH23: =IF($AC23="","",IFERROR((SUMIFS($Q$8:$Q$37,$A$8:$A$37,">="&$AJ$18+7*(4-1),$A$8:$A$37,"<="&$AJ$18+7*(4-1)+6)+SUMIFS('2026年05月'!$Q$8:$Q$38,'2026年05月'!$A$8:$A$38,">="&$AJ$18+7*(4-1),'2026年05月'!$A$8:$A$38,"<="&$AJ$18+7*(4-1)+6))/(SUMIFS($P$8:$P$37,$A$8:$A$37,">="&$AJ$18+7*(4-1),$A$8:$A$37,"<="&$AJ$18+7*(4-1)+6)+SUMIFS('2026年05月'!$P$8:$P$38,'2026年05月'!$A$8:$A$38,">="&$AJ$18+7*(4-1),'2026年05月'!$A$8:$A$38,"<="&$AJ$18+7*(4-1)+6)),"")) -> 0.41304348
A24: 46129 | B24: =MID("日月火水木金土",WEEKDAY(A24),1) -> 金 | C24: 300000 | D24: =SUM($C$8:C24) -> 5400000 | E24: 65930 | F24: 103050 | G24: 5058 | H24: =IF(COUNT(E24:G24)=0,"",SUM(E24:G24)) -> 174038 | I24: =IF(H24="","",SUM($H$8:H24)) -> 2700332 | J24: =IF(H24="","",IFERROR(H24/C24,"")) -> 0.58012667 | K24: =IF(I24="","",IFERROR(I24/D24,"")) -> 0.50006148 | L24: =IF(I24="","",IF(D24=0,"",I24-D24)) -> -2699668 | M24: =IF(H24="","—",IF(D24=0,"予算未入力",IF(I24>=D24,"◎ ペース内","▲ 遅れ"))) -> ▲ 遅れ | N24: 9 | O24: 9 | P24: 21 | Q24: 5 | R24: 7 | S24: =IFERROR(N24/P24,"") -> 0.42857143 | T24: =IFERROR(H24/N24,"") -> 19337.556 | U24: =IFERROR(O24/N24,"") -> 1 | V24: =IFERROR(Q24/P24,"") -> 0.23809524 | X24: 8378 | Y24: 0 | AB24: 5 | AC24: =IF($AJ$18+7*(5-1)>$A$37,"",TEXT($AJ$18+7*(5-1),"m/d")&"-"&TEXT($AJ$18+7*(5-1)+6,"m/d")) | AD24: =IF($AC24="","",(SUMIFS($H$8:$H$37,$A$8:$A$37,">="&$AJ$18+7*(5-1),$A$8:$A$37,"<="&$AJ$18+7*(5-1)+6)+SUMIFS('2026年05月'!$H$8:$H$38,'2026年05月'!$A$8:$A$38,">="&$AJ$18+7*(5-1),'2026年05月'!$A$8:$A$38,"<="&$AJ$18+7*(5-1)+6))) | AE24: =IF($AC24="","",IFERROR((SUMIFS($N$8:$N$37,$A$8:$A$37,">="&$AJ$18+7*(5-1),$A$8:$A$37,"<="&$AJ$18+7*(5-1)+6)+SUMIFS('2026年05月'!$N$8:$N$38,'2026年05月'!$A$8:$A$38,">="&$AJ$18+7*(5-1),'2026年05月'!$A$8:$A$38,"<="&$AJ$18+7*(5-1)+6))/(SUMIFS($P$8:$P$37,$A$8:$A$37,">="&$AJ$18+7*(5-1),$A$8:$A$37,"<="&$AJ$18+7*(5-1)+6)+SUMIFS('2026年05月'!$P$8:$P$38,'2026年05月'!$A$8:$A$38,">="&$AJ$18+7*(5-1),'2026年05月'!$A$8:$A$38,"<="&$AJ$18+7*(5-1)+6)),"")) | AF24: =IF($AC24="","",IFERROR((SUMIFS($H$8:$H$37,$A$8:$A$37,">="&$AJ$18+7*(5-1),$A$8:$A$37,"<="&$AJ$18+7*(5-1)+6)+SUMIFS('2026年05月'!$H$8:$H$38,'2026年05月'!$A$8:$A$38,">="&$AJ$18+7*(5-1),'2026年05月'!$A$8:$A$38,"<="&$AJ$18+7*(5-1)+6))/(SUMIFS($N$8:$N$37,$A$8:$A$37,">="&$AJ$18+7*(5-1),$A$8:$A$37,"<="&$AJ$18+7*(5-1)+6)+SUMIFS('2026年05月'!$N$8:$N$38,'2026年05月'!$A$8:$A$38,">="&$AJ$18+7*(5-1),'2026年05月'!$A$8:$A$38,"<="&$AJ$18+7*(5-1)+6)),"")) | AG24: =IF($AC24="","",IFERROR((SUMIFS($O$8:$O$37,$A$8:$A$37,">="&$AJ$18+7*(5-1),$A$8:$A$37,"<="&$AJ$18+7*(5-1)+6)+SUMIFS('2026年05月'!$O$8:$O$38,'2026年05月'!$A$8:$A$38,">="&$AJ$18+7*(5-1),'2026年05月'!$A$8:$A$38,"<="&$AJ$18+7*(5-1)+6))/(SUMIFS($N$8:$N$37,$A$8:$A$37,">="&$AJ$18+7*(5-1),$A$8:$A$37,"<="&$AJ$18+7*(5-1)+6)+SUMIFS('2026年05月'!$N$8:$N$38,'2026年05月'!$A$8:$A$38,">="&$AJ$18+7*(5-1),'2026年05月'!$A$8:$A$38,"<="&$AJ$18+7*(5-1)+6)),"")) | AH24: =IF($AC24="","",IFERROR((SUMIFS($Q$8:$Q$37,$A$8:$A$37,">="&$AJ$18+7*(5-1),$A$8:$A$37,"<="&$AJ$18+7*(5-1)+6)+SUMIFS('2026年05月'!$Q$8:$Q$38,'2026年05月'!$A$8:$A$38,">="&$AJ$18+7*(5-1),'2026年05月'!$A$8:$A$38,"<="&$AJ$18+7*(5-1)+6))/(SUMIFS($P$8:$P$37,$A$8:$A$37,">="&$AJ$18+7*(5-1),$A$8:$A$37,"<="&$AJ$18+7*(5-1)+6)+SUMIFS('2026年05月'!$P$8:$P$38,'2026年05月'!$A$8:$A$38,">="&$AJ$18+7*(5-1),'2026年05月'!$A$8:$A$38,"<="&$AJ$18+7*(5-1)+6)),""))
A25: 46130 | B25: =MID("日月火水木金土",WEEKDAY(A25),1) -> 土 | C25: 500000 | D25: =SUM($C$8:C25) -> 5900000 | E25: 65330 | F25: 116640 | G25: 4041 | H25: =IF(COUNT(E25:G25)=0,"",SUM(E25:G25)) -> 186011 | I25: =IF(H25="","",SUM($H$8:H25)) -> 2886343 | J25: =IF(H25="","",IFERROR(H25/C25,"")) -> 0.372022 | K25: =IF(I25="","",IFERROR(I25/D25,"")) -> 0.48921068 | L25: =IF(I25="","",IF(D25=0,"",I25-D25)) -> -3013657 | M25: =IF(H25="","—",IF(D25=0,"予算未入力",IF(I25>=D25,"◎ ペース内","▲ 遅れ"))) -> ▲ 遅れ | N25: 9 | O25: 9 | P25: 36 | Q25: 17 | R25: 40 | S25: =IFERROR(N25/P25,"") -> 0.25 | T25: =IFERROR(H25/N25,"") -> 20667.889 | U25: =IFERROR(O25/N25,"") -> 1 | V25: =IFERROR(Q25/P25,"") -> 0.47222222 | X25: 8485 | Y25: 0 | AB25: 6 | AC25: =IF($AJ$18+7*(6-1)>$A$37,"",TEXT($AJ$18+7*(6-1),"m/d")&"-"&TEXT($AJ$18+7*(6-1)+6,"m/d")) | AD25: =IF($AC25="","",(SUMIFS($H$8:$H$37,$A$8:$A$37,">="&$AJ$18+7*(6-1),$A$8:$A$37,"<="&$AJ$18+7*(6-1)+6)+SUMIFS('2026年05月'!$H$8:$H$38,'2026年05月'!$A$8:$A$38,">="&$AJ$18+7*(6-1),'2026年05月'!$A$8:$A$38,"<="&$AJ$18+7*(6-1)+6))) | AE25: =IF($AC25="","",IFERROR((SUMIFS($N$8:$N$37,$A$8:$A$37,">="&$AJ$18+7*(6-1),$A$8:$A$37,"<="&$AJ$18+7*(6-1)+6)+SUMIFS('2026年05月'!$N$8:$N$38,'2026年05月'!$A$8:$A$38,">="&$AJ$18+7*(6-1),'2026年05月'!$A$8:$A$38,"<="&$AJ$18+7*(6-1)+6))/(SUMIFS($P$8:$P$37,$A$8:$A$37,">="&$AJ$18+7*(6-1),$A$8:$A$37,"<="&$AJ$18+7*(6-1)+6)+SUMIFS('2026年05月'!$P$8:$P$38,'2026年05月'!$A$8:$A$38,">="&$AJ$18+7*(6-1),'2026年05月'!$A$8:$A$38,"<="&$AJ$18+7*(6-1)+6)),"")) | AF25: =IF($AC25="","",IFERROR((SUMIFS($H$8:$H$37,$A$8:$A$37,">="&$AJ$18+7*(6-1),$A$8:$A$37,"<="&$AJ$18+7*(6-1)+6)+SUMIFS('2026年05月'!$H$8:$H$38,'2026年05月'!$A$8:$A$38,">="&$AJ$18+7*(6-1),'2026年05月'!$A$8:$A$38,"<="&$AJ$18+7*(6-1)+6))/(SUMIFS($N$8:$N$37,$A$8:$A$37,">="&$AJ$18+7*(6-1),$A$8:$A$37,"<="&$AJ$18+7*(6-1)+6)+SUMIFS('2026年05月'!$N$8:$N$38,'2026年05月'!$A$8:$A$38,">="&$AJ$18+7*(6-1),'2026年05月'!$A$8:$A$38,"<="&$AJ$18+7*(6-1)+6)),"")) | AG25: =IF($AC25="","",IFERROR((SUMIFS($O$8:$O$37,$A$8:$A$37,">="&$AJ$18+7*(6-1),$A$8:$A$37,"<="&$AJ$18+7*(6-1)+6)+SUMIFS('2026年05月'!$O$8:$O$38,'2026年05月'!$A$8:$A$38,">="&$AJ$18+7*(6-1),'2026年05月'!$A$8:$A$38,"<="&$AJ$18+7*(6-1)+6))/(SUMIFS($N$8:$N$37,$A$8:$A$37,">="&$AJ$18+7*(6-1),$A$8:$A$37,"<="&$AJ$18+7*(6-1)+6)+SUMIFS('2026年05月'!$N$8:$N$38,'2026年05月'!$A$8:$A$38,">="&$AJ$18+7*(6-1),'2026年05月'!$A$8:$A$38,"<="&$AJ$18+7*(6-1)+6)),"")) | AH25: =IF($AC25="","",IFERROR((SUMIFS($Q$8:$Q$37,$A$8:$A$37,">="&$AJ$18+7*(6-1),$A$8:$A$37,"<="&$AJ$18+7*(6-1)+6)+SUMIFS('2026年05月'!$Q$8:$Q$38,'2026年05月'!$A$8:$A$38,">="&$AJ$18+7*(6-1),'2026年05月'!$A$8:$A$38,"<="&$AJ$18+7*(6-1)+6))/(SUMIFS($P$8:$P$37,$A$8:$A$37,">="&$AJ$18+7*(6-1),$A$8:$A$37,"<="&$AJ$18+7*(6-1)+6)+SUMIFS('2026年05月'!$P$8:$P$38,'2026年05月'!$A$8:$A$38,">="&$AJ$18+7*(6-1),'2026年05月'!$A$8:$A$38,"<="&$AJ$18+7*(6-1)+6)),""))
A26: 46131 | B26: =MID("日月火水木金土",WEEKDAY(A26),1) -> 日 | C26: 400000 | D26: =SUM($C$8:C26) -> 6300000 | E26: 205280 | F26: 233470 | G26: -11208 | H26: =IF(COUNT(E26:G26)=0,"",SUM(E26:G26)) -> 427542 | I26: =IF(H26="","",SUM($H$8:H26)) -> 3313885 | J26: =IF(H26="","",IFERROR(H26/C26,"")) -> 1.068855 | K26: =IF(I26="","",IFERROR(I26/D26,"")) -> 0.52601349 | L26: =IF(I26="","",IF(D26=0,"",I26-D26)) -> -2986115 | M26: =IF(H26="","—",IF(D26=0,"予算未入力",IF(I26>=D26,"◎ ペース内","▲ 遅れ"))) -> ▲ 遅れ | N26: 21 | O26: 21 | P26: 42 | Q26: 26 | R26: 39 | S26: =IFERROR(N26/P26,"") -> 0.5 | T26: =IFERROR(H26/N26,"") -> 20359.143 | U26: =IFERROR(O26/N26,"") -> 1 | V26: =IFERROR(Q26/P26,"") -> 0.61904762 | X26: 8572 | Y26: 0 | AB26: ※期間ラベルは第1火曜から自動生成。決定率・客単価・セット率・試着率は「週合計÷週合計」
A27: 46132 | B27: =MID("日月火水木金土",WEEKDAY(A27),1) -> 月 | C27: 300000 | D27: =SUM($C$8:C27) -> 6600000 | E27: 120710 | F27: 92220 | G27: 223 | H27: =IF(COUNT(E27:G27)=0,"",SUM(E27:G27)) -> 213153 | I27: =IF(H27="","",SUM($H$8:H27)) -> 3527038 | J27: =IF(H27="","",IFERROR(H27/C27,"")) -> 0.71051 | K27: =IF(I27="","",IFERROR(I27/D27,"")) -> 0.5343997 | L27: =IF(I27="","",IF(D27=0,"",I27-D27)) -> -3072962 | M27: =IF(H27="","—",IF(D27=0,"予算未入力",IF(I27>=D27,"◎ ペース内","▲ 遅れ"))) -> ▲ 遅れ | N27: 10 | O27: 11 | P27: 34 | Q27: 11 | R27: 19 | S27: =IFERROR(N27/P27,"") -> 0.29411765 | T27: =IFERROR(H27/N27,"") -> 21315.3 | U27: =IFERROR(O27/N27,"") -> 1.1 | V27: =IFERROR(Q27/P27,"") -> 0.32352941 | X27: 8640 | Y27: 0 | AB27: ※最終週は翌月にまたぐため、2026年05月シートの実績も自動で合算します
A28: 46133 | B28: =MID("日月火水木金土",WEEKDAY(A28),1) -> 火 | C28: 300000 | D28: =SUM($C$8:C28) -> 6900000 | E28: 26510 | F28: 72430 | G28: 25300 | H28: =IF(COUNT(E28:G28)=0,"",SUM(E28:G28)) -> 124240 | I28: =IF(H28="","",SUM($H$8:H28)) -> 3651278 | J28: =IF(H28="","",IFERROR(H28/C28,"")) -> 0.41413333 | K28: =IF(I28="","",IFERROR(I28/D28,"")) -> 0.52917072 | L28: =IF(I28="","",IF(D28=0,"",I28-D28)) -> -3248722 | M28: =IF(H28="","—",IF(D28=0,"予算未入力",IF(I28>=D28,"◎ ペース内","▲ 遅れ"))) -> ▲ 遅れ | N28: 5 | O28: 5 | P28: 23 | Q28: 10 | R28: 13 | S28: =IFERROR(N28/P28,"") -> 0.2173913 | T28: =IFERROR(H28/N28,"") -> 24848 | U28: =IFERROR(O28/N28,"") -> 1 | V28: =IFERROR(Q28/P28,"") -> 0.43478261 | X28: 8722 | Y28: 0 | AB28: ※月初の月曜まで（例：6/1）は前月シートの最終週に含まれます
A29: 46134 | B29: =MID("日月火水木金土",WEEKDAY(A29),1) -> 水 | C29: 300000 | D29: =SUM($C$8:C29) -> 7200000 | E29: 72040 | F29: 106250 | G29: -16983 | H29: =IF(COUNT(E29:G29)=0,"",SUM(E29:G29)) -> 161307 | I29: =IF(H29="","",SUM($H$8:H29)) -> 3812585 | J29: =IF(H29="","",IFERROR(H29/C29,"")) -> 0.53769 | K29: =IF(I29="","",IFERROR(I29/D29,"")) -> 0.52952569 | L29: =IF(I29="","",IF(D29=0,"",I29-D29)) -> -3387415 | M29: =IF(H29="","—",IF(D29=0,"予算未入力",IF(I29>=D29,"◎ ペース内","▲ 遅れ"))) -> ▲ 遅れ | N29: 6 | O29: 10 | P29: 23 | Q29: 6 | R29: 11 | S29: =IFERROR(N29/P29,"") -> 0.26086957 | T29: =IFERROR(H29/N29,"") -> 26884.5 | U29: =IFERROR(O29/N29,"") -> 1.6666667 | V29: =IFERROR(Q29/P29,"") -> 0.26086957 | X29: 8794 | Y29: 0
A30: 46135 | B30: =MID("日月火水木金土",WEEKDAY(A30),1) -> 木 | C30: 300000 | D30: =SUM($C$8:C30) -> 7500000 | E30: 97440 | F30: 62420 | G30: 41186 | H30: =IF(COUNT(E30:G30)=0,"",SUM(E30:G30)) -> 201046 | I30: =IF(H30="","",SUM($H$8:H30)) -> 4013631 | J30: =IF(H30="","",IFERROR(H30/C30,"")) -> 0.67015333 | K30: =IF(I30="","",IFERROR(I30/D30,"")) -> 0.5351508 | L30: =IF(I30="","",IF(D30=0,"",I30-D30)) -> -3486369 | M30: =IF(H30="","—",IF(D30=0,"予算未入力",IF(I30>=D30,"◎ ペース内","▲ 遅れ"))) -> ▲ 遅れ | N30: 10 | O30: 11 | P30: 30 | Q30: 12 | R30: 21 | S30: =IFERROR(N30/P30,"") -> 0.33333333 | T30: =IFERROR(H30/N30,"") -> 20104.6 | U30: =IFERROR(O30/N30,"") -> 1.1 | V30: =IFERROR(Q30/P30,"") -> 0.4 | X30: 8853 | Y30: 0
A31: 46136 | B31: =MID("日月火水木金土",WEEKDAY(A31),1) -> 金 | C31: 300000 | D31: =SUM($C$8:C31) -> 7800000 | E31: 21610 | F31: 232510 | G31: -24407 | H31: =IF(COUNT(E31:G31)=0,"",SUM(E31:G31)) -> 229713 | I31: =IF(H31="","",SUM($H$8:H31)) -> 4243344 | J31: =IF(H31="","",IFERROR(H31/C31,"")) -> 0.76571 | K31: =IF(I31="","",IFERROR(I31/D31,"")) -> 0.54401846 | L31: =IF(I31="","",IF(D31=0,"",I31-D31)) -> -3556656 | M31: =IF(H31="","—",IF(D31=0,"予算未入力",IF(I31>=D31,"◎ ペース内","▲ 遅れ"))) -> ▲ 遅れ | N31: 11 | O31: 13 | P31: 34 | Q31: 14 | R31: 25 | S31: =IFERROR(N31/P31,"") -> 0.32352941 | T31: =IFERROR(H31/N31,"") -> 20883 | U31: =IFERROR(O31/N31,"") -> 1.1818182 | V31: =IFERROR(Q31/P31,"") -> 0.41176471 | X31: 8942 | Y31: 0
A32: 46137 | B32: =MID("日月火水木金土",WEEKDAY(A32),1) -> 土 | C32: 600000 | D32: =SUM($C$8:C32) -> 8400000 | E32: 121140 | F32: 158980 | G32: 83003 | H32: =IF(COUNT(E32:G32)=0,"",SUM(E32:G32)) -> 363123 | I32: =IF(H32="","",SUM($H$8:H32)) -> 4606467 | J32: =IF(H32="","",IFERROR(H32/C32,"")) -> 0.605205 | K32: =IF(I32="","",IFERROR(I32/D32,"")) -> 0.54838893 | L32: =IF(I32="","",IF(D32=0,"",I32-D32)) -> -3793533 | M32: =IF(H32="","—",IF(D32=0,"予算未入力",IF(I32>=D32,"◎ ペース内","▲ 遅れ"))) -> ▲ 遅れ | N32: 17 | O32: 18 | P32: 63 | Q32: 23 | R32: 40 | S32: =IFERROR(N32/P32,"") -> 0.26984127 | T32: =IFERROR(H32/N32,"") -> 21360.176 | U32: =IFERROR(O32/N32,"") -> 1.0588235 | V32: =IFERROR(Q32/P32,"") -> 0.36507937 | X32: 8988 | Y32: 0
A33: 46138 | B33: =MID("日月火水木金土",WEEKDAY(A33),1) -> 日 | C33: 400000 | D33: =SUM($C$8:C33) -> 8800000 | E33: 147770 | F33: 324611 | G33: 31638 | H33: =IF(COUNT(E33:G33)=0,"",SUM(E33:G33)) -> 504019 | I33: =IF(H33="","",SUM($H$8:H33)) -> 5110486 | J33: =IF(H33="","",IFERROR(H33/C33,"")) -> 1.2600475 | K33: =IF(I33="","",IFERROR(I33/D33,"")) -> 0.58073705 | L33: =IF(I33="","",IF(D33=0,"",I33-D33)) -> -3689514 | M33: =IF(H33="","—",IF(D33=0,"予算未入力",IF(I33>=D33,"◎ ペース内","▲ 遅れ"))) -> ▲ 遅れ | N33: 24 | O33: 26 | P33: 39 | Q33: 23 | R33: 49 | S33: =IFERROR(N33/P33,"") -> 0.61538462 | T33: =IFERROR(H33/N33,"") -> 21000.792 | U33: =IFERROR(O33/N33,"") -> 1.0833333 | V33: =IFERROR(Q33/P33,"") -> 0.58974359 | X33: 9035 | Y33: 0
A34: 46139 | B34: =MID("日月火水木金土",WEEKDAY(A34),1) -> 月 | C34: 300000 | D34: =SUM($C$8:C34) -> 9100000 | E34: 36900 | F34: 75830 | G34: -10822 | H34: =IF(COUNT(E34:G34)=0,"",SUM(E34:G34)) -> 101908 | I34: =IF(H34="","",SUM($H$8:H34)) -> 5212394 | J34: =IF(H34="","",IFERROR(H34/C34,"")) -> 0.33969333 | K34: =IF(I34="","",IFERROR(I34/D34,"")) -> 0.57279055 | L34: =IF(I34="","",IF(D34=0,"",I34-D34)) -> -3887606 | M34: =IF(H34="","—",IF(D34=0,"予算未入力",IF(I34>=D34,"◎ ペース内","▲ 遅れ"))) -> ▲ 遅れ | N34: 6 | O34: 6 | P34: 28 | Q34: 9 | R34: 18 | S34: =IFERROR(N34/P34,"") -> 0.21428571 | T34: =IFERROR(H34/N34,"") -> 16984.667 | U34: =IFERROR(O34/N34,"") -> 1 | V34: =IFERROR(Q34/P34,"") -> 0.32142857 | X34: 9033 | Y34: 0
A35: 46140 | B35: =MID("日月火水木金土",WEEKDAY(A35),1) -> 火 | C35: 300000 | D35: =SUM($C$8:C35) -> 9400000 | E35: 33050 | F35: 131650 | G35: 43246 | H35: =IF(COUNT(E35:G35)=0,"",SUM(E35:G35)) -> 207946 | I35: =IF(H35="","",SUM($H$8:H35)) -> 5420340 | J35: =IF(H35="","",IFERROR(H35/C35,"")) -> 0.69315333 | K35: =IF(I35="","",IFERROR(I35/D35,"")) -> 0.57663191 | L35: =IF(I35="","",IF(D35=0,"",I35-D35)) -> -3979660 | M35: =IF(H35="","—",IF(D35=0,"予算未入力",IF(I35>=D35,"◎ ペース内","▲ 遅れ"))) -> ▲ 遅れ | N35: 11 | O35: 11 | P35: 26 | Q35: 10 | R35: 16 | S35: =IFERROR(N35/P35,"") -> 0.42307692 | T35: =IFERROR(H35/N35,"") -> 18904.182 | U35: =IFERROR(O35/N35,"") -> 1 | V35: =IFERROR(Q35/P35,"") -> 0.38461538 | X35: 9029 | Y35: 0
A36: 46141 | B36: =MID("日月火水木金土",WEEKDAY(A36),1) -> 水 | C36: 500000 | D36: =SUM($C$8:C36) -> 9900000 | E36: 90900 | F36: 402270 | G36: 22116 | H36: =IF(COUNT(E36:G36)=0,"",SUM(E36:G36)) -> 515286 | I36: =IF(H36="","",SUM($H$8:H36)) -> 5935626 | J36: =IF(H36="","",IFERROR(H36/C36,"")) -> 1.030572 | K36: =IF(I36="","",IFERROR(I36/D36,"")) -> 0.59955818 | L36: =IF(I36="","",IF(D36=0,"",I36-D36)) -> -3964374 | M36: =IF(H36="","—",IF(D36=0,"予算未入力",IF(I36>=D36,"◎ ペース内","▲ 遅れ"))) -> ▲ 遅れ | N36: 27 | O36: 27 | P36: 56 | Q36: 27 | R36: 51 | S36: =IFERROR(N36/P36,"") -> 0.48214286 | T36: =IFERROR(H36/N36,"") -> 19084.667 | U36: =IFERROR(O36/N36,"") -> 1 | V36: =IFERROR(Q36/P36,"") -> 0.48214286 | X36: 9024 | Y36: 2510
A37: 46142 | B37: =MID("日月火水木金土",WEEKDAY(A37),1) -> 木 | C37: 300000 | D37: =SUM($C$8:C37) -> 10200000 | E37: 276802 | F37: 92120 | G37: 27266 | H37: =IF(COUNT(E37:G37)=0,"",SUM(E37:G37)) -> 396188 | I37: =IF(H37="","",SUM($H$8:H37)) -> 6331814 | J37: =IF(H37="","",IFERROR(H37/C37,"")) -> 1.3206267 | K37: =IF(I37="","",IFERROR(I37/D37,"")) -> 0.62076608 | L37: =IF(I37="","",IF(D37=0,"",I37-D37)) -> -3868186 | M37: =IF(H37="","—",IF(D37=0,"予算未入力",IF(I37>=D37,"◎ ペース内","▲ 遅れ"))) -> ▲ 遅れ | N37: 18 | O37: 22 | P37: 43 | Q37: 16 | R37: 28 | S37: =IFERROR(N37/P37,"") -> 0.41860465 | T37: =IFERROR(H37/N37,"") -> 22010.444 | U37: =IFERROR(O37/N37,"") -> 1.2222222 | V37: =IFERROR(Q37/P37,"") -> 0.37209302 | X37: 9024 | Y37: 0
A38: 月計 | C38: =SUM(C8:C37) -> 10200000 | D38: =C38 -> 10200000 | E38: =SUM(E8:E37) -> 2044589 | F38: =SUM(F8:F37) -> 3884056 | G38: =SUM(G8:G37) -> 403169 | H38: =SUM(H8:H37) -> 6331814 | I38: =H38 -> 6331814 | J38: =IFERROR(H38/C38,"") -> 0.62076608 | K38: =IFERROR(H38/C38,"") -> 0.62076608 | L38: =H38-C38 -> -3868186 | N38: =SUM(N8:N37) -> 306 | O38: =SUM(O8:O37) -> 338 | P38: =SUM(P8:P37) -> 938 | Q38: =SUM(Q8:Q37) -> 446 | R38: =SUM(R8:R37) -> 407 | S38: =IFERROR(N38/P38,"") -> 0.32622601 | T38: =IFERROR(H38/N38,"") -> 20692.203 | U38: =IFERROR(O38/N38,"") -> 1.1045752 | V38: =IFERROR(Q38/P38,"") -> 0.47547974 | W38: =SUM(W8:W37) -> 0 | X38: =IFERROR(LOOKUP(9.99E+307,X8:X37),"") -> 9024 | Y38: =SUM(Y8:Y37) -> 2510 | Z38: フォロワーは月末値

Sheet 2026年05月
A1: 2026年5月 名古屋店 日別売上管理
A2: 青字＋薄黄色のセルが入力欄。白セルは数式なので触らないでください。単位：円
A3: 月間予算 | C3: 当月実績 | E3: 達成率 | G3: 営業日数(/31日) | I3: 残り必要額 | K3: 残り必要日商
A4: =IF('設定'!$B$9="",SUM(C8:C38),'設定'!$B$9) -> 6625036 | C4: =SUM(H8:H38) -> 6030095 | E4: =IFERROR(C4/A4,0) -> 0.91019807 | G4: =COUNTIF(H8:H38,">0") -> 31 | I4: =A4-C4 -> 594941 | K4: =IF((31-G4)>0,(A4-C4)/(31-G4),0) -> 0
A5: 日次予算合計 | C5: 着地見込 | E5: 決定率 | G5: 客単価 | I5: セット率 | K5: 試着率
A6: =SUM(C8:C38) -> 11200000 | C6: =IFERROR(C4/G4*31,0) -> 6030095 | E6: =IFERROR(N39/P39,0) -> 0.27014218 | G6: =IFERROR(H39/N39,0) -> 21158.228 | I6: =IFERROR(O39/N39,0) -> 1.0982456 | K6: =IFERROR(Q39/P39,0) -> 0.33649289
A7: 日付 | B7: 曜 | C7: 日次予算 | D7: 累計予算 | E7: 現金 | F7: クレジット | G7: 内訳差額 (要確認) | H7: 実績合計 | I7: 累計実績 | J7: 日次達成 | K7: 累計達成 | L7: 累計予実差 | M7: ペース | N7: 購入人数 | O7: 販売点数 | P7: 来客数 | Q7: 試着組数 | R7: 試着個数 | S7: 決定率 | T7: 客単価 | U7: セット率 | V7: 試着率 | W7: クロス クーポン | X7: インスタ フォロワー | Y7: 経費 | Z7: メモ | AB7: 曜日 | AC7: 平均日商 | AD7: 日数 | AE7: 決定率 | AF7: 客単価
A8: 46143 | B8: =MID("日月火水木金土",WEEKDAY(A8),1) -> 金 | C8: 300000 | D8: =SUM($C$8:C8) -> 300000 | E8: 71430 | F8: 52020 | G8: 48010 | H8: =IF(COUNT(E8:G8)=0,"",SUM(E8:G8)) -> 171460 | I8: =IF(H8="","",SUM($H$8:H8)) -> 171460 | J8: =IF(H8="","",IFERROR(H8/C8,"")) -> 0.57153333 | K8: =IF(I8="","",IFERROR(I8/D8,"")) -> 0.57153333 | L8: =IF(I8="","",IF(D8=0,"",I8-D8)) -> -128540 | M8: =IF(H8="","—",IF(D8=0,"予算未入力",IF(I8>=D8,"◎ ペース内","▲ 遅れ"))) -> ▲ 遅れ | N8: 7 | O8: 7 | P8: 38 | Q8: 7 | R8: 12 | S8: =IFERROR(N8/P8,"") -> 0.18421053 | T8: =IFERROR(H8/N8,"") -> 24494.286 | U8: =IFERROR(O8/N8,"") -> 1 | V8: =IFERROR(Q8/P8,"") -> 0.18421053 | X8: 9026 | Y8: 0 | AB8: 月 | AC8: =IFERROR(AVERAGEIFS($H$8:$H$38,$B$8:$B$38,AB8,$H$8:$H$38,">0"),0) -> 247403.5 | AD8: =COUNTIFS($B$8:$B$38,AB8,$H$8:$H$38,">0") -> 4 | AE8: =IFERROR(SUMIF($B$8:$B$38,AB8,$N$8:$N$38)/SUMIF($B$8:$B$38,AB8,$P$8:$P$38),0) -> 0.32432432 | AF8: =IFERROR(SUMIF($B$8:$B$38,AB8,$H$8:$H$38)/SUMIF($B$8:$B$38,AB8,$N$8:$N$38),0) -> 20616.958
A9: 46144 | B9: =MID("日月火水木金土",WEEKDAY(A9),1) -> 土 | C9: 800000 | D9: =SUM($C$8:C9) -> 1100000 | E9: 69730 | F9: 174859 | G9: 2574 | H9: =IF(COUNT(E9:G9)=0,"",SUM(E9:G9)) -> 247163 | I9: =IF(H9="","",SUM($H$8:H9)) -> 418623 | J9: =IF(H9="","",IFERROR(H9/C9,"")) -> 0.30895375 | K9: =IF(I9="","",IFERROR(I9/D9,"")) -> 0.38056636 | L9: =IF(I9="","",IF(D9=0,"",I9-D9)) -> -681377 | M9: =IF(H9="","—",IF(D9=0,"予算未入力",IF(I9>=D9,"◎ ペース内","▲ 遅れ"))) -> ▲ 遅れ | N9: 12 | O9: 13 | P9: 50 | Q9: 19 | R9: 30 | S9: =IFERROR(N9/P9,"") -> 0.24 | T9: =IFERROR(H9/N9,"") -> 20596.917 | U9: =IFERROR(O9/N9,"") -> 1.0833333 | V9: =IFERROR(Q9/P9,"") -> 0.38 | X9: 9026 | Y9: 0 | AB9: 火 | AC9: =IFERROR(AVERAGEIFS($H$8:$H$38,$B$8:$B$38,AB9,$H$8:$H$38,">0"),0) -> 157339.25 | AD9: =COUNTIFS($B$8:$B$38,AB9,$H$8:$H$38,">0") -> 4 | AE9: =IFERROR(SUMIF($B$8:$B$38,AB9,$N$8:$N$38)/SUMIF($B$8:$B$38,AB9,$P$8:$P$38),0) -> 0.2265625 | AF9: =IFERROR(SUMIF($B$8:$B$38,AB9,$H$8:$H$38)/SUMIF($B$8:$B$38,AB9,$N$8:$N$38),0) -> 21701.966
A10: 46145 | B10: =MID("日月火水木金土",WEEKDAY(A10),1) -> 日 | C10: 800000 | D10: =SUM($C$8:C10) -> 1900000 | E10: 90828 | F10: 340770 | G10: 18135 | H10: =IF(COUNT(E10:G10)=0,"",SUM(E10:G10)) -> 449733 | I10: =IF(H10="","",SUM($H$8:H10)) -> 868356 | J10: =IF(H10="","",IFERROR(H10/C10,"")) -> 0.56216625 | K10: =IF(I10="","",IFERROR(I10/D10,"")) -> 0.45702947 | L10: =IF(I10="","",IF(D10=0,"",I10-D10)) -> -1031644 | M10: =IF(H10="","—",IF(D10=0,"予算未入力",IF(I10>=D10,"◎ ペース内","▲ 遅れ"))) -> ▲ 遅れ | N10: 23 | O10: 25 | P10: 43 | Q10: 24 | R10: 52 | S10: =IFERROR(N10/P10,"") -> 0.53488372 | T10: =IFERROR(H10/N10,"") -> 19553.609 | U10: =IFERROR(O10/N10,"") -> 1.0869565 | V10: =IFERROR(Q10/P10,"") -> 0.55813953 | X10: 9026 | Y10: 0 | AB10: 水 | AC10: =IFERROR(AVERAGEIFS($H$8:$H$38,$B$8:$B$38,AB10,$H$8:$H$38,">0"),0) -> 150081.25 | AD10: =COUNTIFS($B$8:$B$38,AB10,$H$8:$H$38,">0") -> 4 | AE10: =IFERROR(SUMIF($B$8:$B$38,AB10,$N$8:$N$38)/SUMIF($B$8:$B$38,AB10,$P$8:$P$38),0) -> 0.23853211 | AF10: =IFERROR(SUMIF($B$8:$B$38,AB10,$H$8:$H$38)/SUMIF($B$8:$B$38,AB10,$N$8:$N$38),0) -> 23089.423
A11: 46146 | B11: =MID("日月火水木金土",WEEKDAY(A11),1) -> 月 | C11: 800000 | D11: =SUM($C$8:C11) -> 2700000 | E11: 191540 | F11: 326020 | G11: 54669 | H11: =IF(COUNT(E11:G11)=0,"",SUM(E11:G11)) -> 572229 | I11: =IF(H11="","",SUM($H$8:H11)) -> 1440585 | J11: =IF(H11="","",IFERROR(H11/C11,"")) -> 0.71528625 | K11: =IF(I11="","",IFERROR(I11/D11,"")) -> 0.53355 | L11: =IF(I11="","",IF(D11=0,"",I11-D11)) -> -1259415 | M11: =IF(H11="","—",IF(D11=0,"予算未入力",IF(I11>=D11,"◎ ペース内","▲ 遅れ"))) -> ▲ 遅れ | N11: 27 | O11: 29 | P11: 66 | Q11: 30 | R11: 44 | S11: =IFERROR(N11/P11,"") -> 0.40909091 | T11: =IFERROR(H11/N11,"") -> 21193.667 | U11: =IFERROR(O11/N11,"") -> 1.0740741 | V11: =IFERROR(Q11/P11,"") -> 0.45454545 | X11: 9029 | Y11: 0 | AB11: 木 | AC11: =IFERROR(AVERAGEIFS($H$8:$H$38,$B$8:$B$38,AB11,$H$8:$H$38,">0"),0) -> 93831.25 | AD11: =COUNTIFS($B$8:$B$38,AB11,$H$8:$H$38,">0") -> 4 | AE11: =IFERROR(SUMIF($B$8:$B$38,AB11,$N$8:$N$38)/SUMIF($B$8:$B$38,AB11,$P$8:$P$38),0) -> 0.27941176 | AF11: =IFERROR(SUMIF($B$8:$B$38,AB11,$H$8:$H$38)/SUMIF($B$8:$B$38,AB11,$N$8:$N$38),0) -> 19753.947
A12: 46147 | B12: =MID("日月火水木金土",WEEKDAY(A12),1) -> 火 | C12: 800000 | D12: =SUM($C$8:C12) -> 3500000 | E12: 24310 | F12: 170369 | G12: 26553 | H12: =IF(COUNT(E12:G12)=0,"",SUM(E12:G12)) -> 221232 | I12: =IF(H12="","",SUM($H$8:H12)) -> 1661817 | J12: =IF(H12="","",IFERROR(H12/C12,"")) -> 0.27654 | K12: =IF(I12="","",IFERROR(I12/D12,"")) -> 0.47480486 | L12: =IF(I12="","",IF(D12=0,"",I12-D12)) -> -1838183 | M12: =IF(H12="","—",IF(D12=0,"予算未入力",IF(I12>=D12,"◎ ペース内","▲ 遅れ"))) -> ▲ 遅れ | N12: 10 | O12: 12 | P12: 65 | Q12: 14 | R12: 27 | S12: =IFERROR(N12/P12,"") -> 0.15384615 | T12: =IFERROR(H12/N12,"") -> 22123.2 | U12: =IFERROR(O12/N12,"") -> 1.2 | V12: =IFERROR(Q12/P12,"") -> 0.21538462 | X12: 9024 | Y12: 0 | AB12: 金 | AC12: =IFERROR(AVERAGEIFS($H$8:$H$38,$B$8:$B$38,AB12,$H$8:$H$38,">0"),0) -> 114059.4 | AD12: =COUNTIFS($B$8:$B$38,AB12,$H$8:$H$38,">0") -> 5 | AE12: =IFERROR(SUMIF($B$8:$B$38,AB12,$N$8:$N$38)/SUMIF($B$8:$B$38,AB12,$P$8:$P$38),0) -> 0.19852941 | AF12: =IFERROR(SUMIF($B$8:$B$38,AB12,$H$8:$H$38)/SUMIF($B$8:$B$38,AB12,$N$8:$N$38),0) -> 21122.111
A13: 46148 | B13: =MID("日月火水木金土",WEEKDAY(A13),1) -> 水 | C13: 700000 | D13: =SUM($C$8:C13) -> 4200000 | E13: 143150 | F13: 145510 | G13: -7852 | H13: =IF(COUNT(E13:G13)=0,"",SUM(E13:G13)) -> 280808 | I13: =IF(H13="","",SUM($H$8:H13)) -> 1942625 | J13: =IF(H13="","",IFERROR(H13/C13,"")) -> 0.40115429 | K13: =IF(I13="","",IFERROR(I13/D13,"")) -> 0.46252976 | L13: =IF(I13="","",IF(D13=0,"",I13-D13)) -> -2257375 | M13: =IF(H13="","—",IF(D13=0,"予算未入力",IF(I13>=D13,"◎ ペース内","▲ 遅れ"))) -> ▲ 遅れ | N13: 12 | O13: 14 | P13: 47 | Q13: 14 | R13: 17 | S13: =IFERROR(N13/P13,"") -> 0.25531915 | T13: =IFERROR(H13/N13,"") -> 23400.667 | U13: =IFERROR(O13/N13,"") -> 1.1666667 | V13: =IFERROR(Q13/P13,"") -> 0.29787234 | X13: 9023 | Y13: 0 | AB13: 土 | AC13: =IFERROR(AVERAGEIFS($H$8:$H$38,$B$8:$B$38,AB13,$H$8:$H$38,">0"),0) -> 266354 | AD13: =COUNTIFS($B$8:$B$38,AB13,$H$8:$H$38,">0") -> 5 | AE13: =IFERROR(SUMIF($B$8:$B$38,AB13,$N$8:$N$38)/SUMIF($B$8:$B$38,AB13,$P$8:$P$38),0) -> 0.24313725 | AF13: =IFERROR(SUMIF($B$8:$B$38,AB13,$H$8:$H$38)/SUMIF($B$8:$B$38,AB13,$N$8:$N$38),0) -> 21480.161
A14: 46149 | B14: =MID("日月火水木金土",WEEKDAY(A14),1) -> 木 | C14: 200000 | D14: =SUM($C$8:C14) -> 4400000 | E14: 23920 | F14: 102779 | G14: -11994 | H14: =IF(COUNT(E14:G14)=0,"",SUM(E14:G14)) -> 114705 | I14: =IF(H14="","",SUM($H$8:H14)) -> 2057330 | J14: =IF(H14="","",IFERROR(H14/C14,"")) -> 0.573525 | K14: =IF(I14="","",IFERROR(I14/D14,"")) -> 0.467575 | L14: =IF(I14="","",IF(D14=0,"",I14-D14)) -> -2342670 | M14: =IF(H14="","—",IF(D14=0,"予算未入力",IF(I14>=D14,"◎ ペース内","▲ 遅れ"))) -> ▲ 遅れ | N14: 6 | O14: 7 | P14: 18 | Q14: 5 | R14: 10 | S14: =IFERROR(N14/P14,"") -> 0.33333333 | T14: =IFERROR(H14/N14,"") -> 19117.5 | U14: =IFERROR(O14/N14,"") -> 1.1666667 | V14: =IFERROR(Q14/P14,"") -> 0.27777778 | X14: 9013 | Y14: 0 | AB14: 日 | AC14: =IFERROR(AVERAGEIFS($H$8:$H$38,$B$8:$B$38,AB14,$H$8:$H$38,">0"),0) -> 306681.4 | AD14: =COUNTIFS($B$8:$B$38,AB14,$H$8:$H$38,">0") -> 5 | AE14: =IFERROR(SUMIF($B$8:$B$38,AB14,$N$8:$N$38)/SUMIF($B$8:$B$38,AB14,$P$8:$P$38),0) -> 0.3507109 | AF14: =IFERROR(SUMIF($B$8:$B$38,AB14,$H$8:$H$38)/SUMIF($B$8:$B$38,AB14,$N$8:$N$38),0) -> 20721.716
A15: 46150 | B15: =MID("日月火水木金土",WEEKDAY(A15),1) -> 金 | C15: 200000 | D15: =SUM($C$8:C15) -> 4600000 | E15: 63620 | F15: 0 | G15: -6116 | H15: =IF(COUNT(E15:G15)=0,"",SUM(E15:G15)) -> 57504 | I15: =IF(H15="","",SUM($H$8:H15)) -> 2114834 | J15: =IF(H15="","",IFERROR(H15/C15,"")) -> 0.28752 | K15: =IF(I15="","",IFERROR(I15/D15,"")) -> 0.45974652 | L15: =IF(I15="","",IF(D15=0,"",I15-D15)) -> -2485166 | M15: =IF(H15="","—",IF(D15=0,"予算未入力",IF(I15>=D15,"◎ ペース内","▲ 遅れ"))) -> ▲ 遅れ | N15: 3 | O15: 3 | P15: 26 | Q15: 3 | R15: 5 | S15: =IFERROR(N15/P15,"") -> 0.11538462 | T15: =IFERROR(H15/N15,"") -> 19168 | U15: =IFERROR(O15/N15,"") -> 1 | V15: =IFERROR(Q15/P15,"") -> 0.11538462 | X15: 9013 | Y15: 0
A16: 46151 | B16: =MID("日月火水木金土",WEEKDAY(A16),1) -> 土 | C16: 500000 | D16: =SUM($C$8:C16) -> 5100000 | E16: 43610 | F16: 83370 | G16: 9624 | H16: =IF(COUNT(E16:G16)=0,"",SUM(E16:G16)) -> 136604 | I16: =IF(H16="","",SUM($H$8:H16)) -> 2251438 | J16: =IF(H16="","",IFERROR(H16/C16,"")) -> 0.273208 | K16: =IF(I16="","",IFERROR(I16/D16,"")) -> 0.44145843 | L16: =IF(I16="","",IF(D16=0,"",I16-D16)) -> -2848562 | M16: =IF(H16="","—",IF(D16=0,"予算未入力",IF(I16>=D16,"◎ ペース内","▲ 遅れ"))) -> ▲ 遅れ | N16: 6 | O16: 7 | P16: 41 | Q16: 11 | R16: 15 | S16: =IFERROR(N16/P16,"") -> 0.14634146 | T16: =IFERROR(H16/N16,"") -> 22767.333 | U16: =IFERROR(O16/N16,"") -> 1.1666667 | V16: =IFERROR(Q16/P16,"") -> 0.26829268 | X16: 9010 | Y16: 0 | AB16: ※実績入力後に曜日別の傾向が出ます
A17: 46152 | B17: =MID("日月火水木金土",WEEKDAY(A17),1) -> 日 | C17: 400000 | D17: =SUM($C$8:C17) -> 5500000 | E17: 22000 | F17: 206599 | G17: -21789 | H17: =IF(COUNT(E17:G17)=0,"",SUM(E17:G17)) -> 206810 | I17: =IF(H17="","",SUM($H$8:H17)) -> 2458248 | J17: =IF(H17="","",IFERROR(H17/C17,"")) -> 0.517025 | K17: =IF(I17="","",IFERROR(I17/D17,"")) -> 0.44695418 | L17: =IF(I17="","",IF(D17=0,"",I17-D17)) -> -3041752 | M17: =IF(H17="","—",IF(D17=0,"予算未入力",IF(I17>=D17,"◎ ペース内","▲ 遅れ"))) -> ▲ 遅れ | N17: 9 | O17: 10 | P17: 41 | Q17: 10 | R17: 16 | S17: =IFERROR(N17/P17,"") -> 0.2195122 | T17: =IFERROR(H17/N17,"") -> 22978.889 | U17: =IFERROR(O17/N17,"") -> 1.1111111 | V17: =IFERROR(Q17/P17,"") -> 0.24390244 | X17: 9004 | Y17: 0
A18: 46153 | B18: =MID("日月火水木金土",WEEKDAY(A18),1) -> 月 | C18: 200000 | D18: =SUM($C$8:C18) -> 5700000 | E18: 29470 | F18: 85597 | G18: -11200 | H18: =IF(COUNT(E18:G18)=0,"",SUM(E18:G18)) -> 103867 | I18: =IF(H18="","",SUM($H$8:H18)) -> 2562115 | J18: =IF(H18="","",IFERROR(H18/C18,"")) -> 0.519335 | K18: =IF(I18="","",IFERROR(I18/D18,"")) -> 0.44949386 | L18: =IF(I18="","",IF(D18=0,"",I18-D18)) -> -3137885 | M18: =IF(H18="","—",IF(D18=0,"予算未入力",IF(I18>=D18,"◎ ペース内","▲ 遅れ"))) -> ▲ 遅れ | N18: 6 | O18: 6 | P18: 28 | Q18: 15 | R18: 26 | S18: =IFERROR(N18/P18,"") -> 0.21428571 | T18: =IFERROR(H18/N18,"") -> 17311.167 | U18: =IFERROR(O18/N18,"") -> 1 | V18: =IFERROR(Q18/P18,"") -> 0.53571429 | X18: 9002 | Y18: 0 | AB18: ■ 週次サマリー（火曜〜翌月曜） | AI18: 第1火曜 | AJ18: =$A$8+MOD(2-WEEKDAY($A$8,2)+7,7) -> 46147
A19: 46154 | B19: =MID("日月火水木金土",WEEKDAY(A19),1) -> 火 | C19: 200000 | D19: =SUM($C$8:C19) -> 5900000 | E19: 41410 | F19: 85140 | G19: 1456 | H19: =IF(COUNT(E19:G19)=0,"",SUM(E19:G19)) -> 128006 | I19: =IF(H19="","",SUM($H$8:H19)) -> 2690121 | J19: =IF(H19="","",IFERROR(H19/C19,"")) -> 0.64003 | K19: =IF(I19="","",IFERROR(I19/D19,"")) -> 0.45595271 | L19: =IF(I19="","",IF(D19=0,"",I19-D19)) -> -3209879 | M19: =IF(H19="","—",IF(D19=0,"予算未入力",IF(I19>=D19,"◎ ペース内","▲ 遅れ"))) -> ▲ 遅れ | N19: 6 | O19: 6 | P19: 20 | Q19: 6 | R19: 13 | S19: =IFERROR(N19/P19,"") -> 0.3 | T19: =IFERROR(H19/N19,"") -> 21334.333 | U19: =IFERROR(O19/N19,"") -> 1 | V19: =IFERROR(Q19/P19,"") -> 0.3 | X19: 9007 | Y19: 0 | AB19: 週 | AC19: 期間 | AD19: 売上 | AE19: 決定率 | AF19: 客単価 | AG19: セット率 | AH19: 試着率
